<?xml version="1.0" ?>
<!-- =================================================================================== -->
<!-- |    This document was autogenerated by xacro from ardak/ardak.urdf               | -->
<!-- |    EDITING THIS FILE BY HAND IS NOT RECOMMENDED                                 | -->
<!-- =================================================================================== -->
<robot name="ardak">
  <link name="base_link">
    <visual>
      <geometry>
        <box size="0.7112 0.35 0.302244"/>
      </geometry>
      <material name="Cyan">
        <color rgba="0 1.0 1.0 1.0"/>
      </material>
    </visual>
    <collision>
      <origin rpy="0 0 0" xyz="0 0 0"/>
      <geometry>
        <box size="0.7112 0.35 0.302244"/>
      </geometry>
    </collision>
    <inertial>
      <mass value="1"/>
      <inertia ixx="0.1" ixy="0.0" ixz="0.0" iyy="1" iyz="0.0" izz="0.1"/>
    </inertial>
  </link>
  <gazebo reference="base_link">
    <material>Gazebo/White</material>
  </gazebo>
  <link name="base_footprint"/>
  <joint name="base_joint" type="fixed">
    <parent link="base_link"/>
    <child link="base_footprint"/>
    <origin rpy="0 0 0" xyz="0.0 0.0 -0.20793"/>
  </joint>
  <link name="camera_link">
    <parent link="base_to_camera_joint"/>
  </link>
  <link name="drive_wheel_rear_left_link">
    <visual>
      <origin rpy="1.5707963267948966 0 0" xyz="0 0 0"/>
      <geometry>
        <cylinder length="0.10795" radius="0.1016"/>
      </geometry>
      <material name="Gray">
        <color rgba="0.5 0.5 0.5 1.0"/>
      </material>
    </visual>
    <collision>
      <origin rpy="1.5707963267948966 0 0" xyz="0 0 0"/>
      2
        
      <geometry>
        <cylinder length="0.10795" radius="0.1016"/>
      </geometry>
    </collision>
    <inertial>
      <mass value="1"/>
      <inertia ixx="0.1" ixy="0.0" ixz="0.0" iyy="1" iyz="0.0" izz="0.1"/>
    </inertial>
    <axis>
      <xyz> 0 1 0 </xyz>
    </axis>
  </link>
  <joint name="drive_wheel_rear_left_joint" type="continuous">
    <parent link="base_link"/>
    <child link="drive_wheel_rear_left_link"/>
    <origin rpy="0 0 0" xyz="-0.26397000000000004 0.258475 -0.10633000000000001"/>
    <axis xyz="0 1 0"/>
  </joint>
  <link name="drive_wheel_rear_right_link">
    <visual>
      <origin rpy="1.5707963267948966 0 0" xyz="0 0 0"/>
      <geometry>
        <cylinder length="0.10795" radius="0.1016"/>
      </geometry>
      <material name="Gray">
        <color rgba="0.5 0.5 0.5 1.0"/>
      </material>
    </visual>
    <collision>
      <origin rpy="1.5707963267948966 0 0" xyz="0 0 0"/>
      2
        
      <geometry>
        <cylinder length="0.10795" radius="0.1016"/>
      </geometry>
    </collision>
    <inertial>
      <mass value="1"/>
      <inertia ixx="0.1" ixy="0.0" ixz="0.0" iyy="1" iyz="0.0" izz="0.1"/>
    </inertial>
    <axis>
      <xyz> 0 1 0 </xyz>
    </axis>
  </link>
  <joint name="drive_wheel_rear_right_joint" type="continuous">
    <parent link="base_link"/>
    <child link="drive_wheel_rear_right_link"/>
    <origin rpy="0 0 0" xyz="-0.26397000000000004 -0.258475 -0.10633000000000001"/>
    <axis xyz="0 1 0"/>
  </joint>
  <link name="drive_wheel_front_left_link">
    <visual>
      <origin rpy="1.5707963267948966 0 0" xyz="0 0 0"/>
      <geometry>
        <cylinder length="0.10795" radius="0.1016"/>
      </geometry>
      <material name="Gray">
        <color rgba="0.5 0.5 0.5 1.0"/>
      </material>
    </visual>
    <collision>
      <origin rpy="1.5707963267948966 0 0" xyz="0 0 0"/>
      2
        
      <geometry>
        <cylinder length="0.10795" radius="0.1016"/>
      </geometry>
    </collision>
    <inertial>
      <mass value="1"/>
      <inertia ixx="0.1" ixy="0.0" ixz="0.0" iyy="1" iyz="0.0" izz="0.1"/>
    </inertial>
    <axis>
      <xyz> 0 1 0 </xyz>
    </axis>
  </link>
  <joint name="drive_wheel_front_left_joint" type="continuous">
    <parent link="base_link"/>
    <child link="drive_wheel_front_left_link"/>
    <origin rpy="0 0 0" xyz="0.26397000000000004 0.258475 -0.10633000000000001"/>
    <axis xyz="0 1 0"/>
  </joint>
  <link name="drive_wheel_front_right_link">
    <visual>
      <origin rpy="1.5707963267948966 0 0" xyz="0 0 0"/>
      <geometry>
        <cylinder length="0.10795" radius="0.1016"/>
      </geometry>
      <material name="Gray">
        <color rgba="0.5 0.5 0.5 1.0"/>
      </material>
    </visual>
    <collision>
      <origin rpy="1.5707963267948966 0 0" xyz="0 0 0"/>
      2
        
      <geometry>
        <cylinder length="0.10795" radius="0.1016"/>
      </geometry>
    </collision>
    <inertial>
      <mass value="1"/>
      <inertia ixx="0.1" ixy="0.0" ixz="0.0" iyy="1" iyz="0.0" izz="0.1"/>
    </inertial>
    <axis>
      <xyz> 0 1 0 </xyz>
    </axis>
  </link>
  <joint name="drive_wheel_front_right_joint" type="continuous">
    <parent link="base_link"/>
    <child link="drive_wheel_front_right_link"/>
    <origin rpy="0 0 0" xyz="0.26397000000000004 -0.258475 -0.10633000000000001"/>
    <axis xyz="0 1 0"/>
  </joint>
  <joint name="base_to_camera_joint" type="fixed">
    <parent link="base_link"/>
    <child link="camera_link"/>
    <origin xyz="0.321769 0.0 0.022078000000000014"/>
  </joint>
</robot>
