<?xml version="1.0" ?>
<!-- =================================================================================== -->
<!-- |    This document was autogenerated by xacro from ../description/ardak/ardak.urdf | -->
<!-- |    EDITING THIS FILE BY HAND IS NOT RECOMMENDED                                 | -->
<!-- =================================================================================== -->
<robot name="ardak">
  <link name="center_link">
    <visual>
      <geometry>
        <box size="0.55 0.35 0.302244"/>
      </geometry>
      <material name="Cyan">
        <color rgba="0 1.0 1.0 1.0"/>
      </material>
    </visual>
    <collision>
      <origin rpy="0 0 0" xyz="0 0 0"/>
      <geometry>
        <box size="0.55 0.35 0.302244"/>
      </geometry>
    </collision>
    <!-- Need to check these values -->
    <!-- Origin needed for inertial? -->
    <inertial>
      <mass value="18.14"/>
      <inertia ixx="2.664688434" ixy="0.0" ixz="0.0" iyy="1.758437644" iyz="0.0" izz="3.341575268"/>
    </inertial>
  </link>
  <link name="base_link">
    <visual>
      <geometry>
        <box size="0.001 0.001 0.001"/>
      </geometry>
      <material name="Cyan">
        <color rgba="0 1.0 1.0 1.0"/>
      </material>
    </visual>
    <collision>
      <origin rpy="0 0 0" xyz="0 0 0"/>
      <geometry>
        <box size="0.001 0.001 0.001"/>
      </geometry>
    </collision>
    <inertial>
      <mass value="0.12266"/>
      <inertia ixx="0.0177645" ixy="0.0" ixz="0.0" iyy="0.011722917" iyz="0.0" izz="0.022277168"/>
    </inertial>
  </link>
  <joint name="base_footprint_joint" type="fixed">
    <parent link="base_link"/>
    <child link="center_link"/>
    <origin rpy="0 0 0" xyz="0.0 0.0 0.20793"/>
  </joint>
  <gazebo reference="base_footprint_joint">
    <disableFixedJointLumping>true</disableFixedJointLumping>
    <preserveFixedJoint>true</preserveFixedJoint>
  </gazebo>
  <link name="drive_wheel_rear_left_link">
    <visual>
      <origin rpy="1.5707963267948966 0 0" xyz="0 0 0"/>
      <geometry>
        <cylinder length="0.10795" radius="0.1016"/>
      </geometry>
      <material name="Gray">
        <color rgba="0.5 0.5 0.5 1.0"/>
      </material>
    </visual>
    <collision>
      <origin rpy="1.5707963267948966 0 0" xyz="0 0 0"/>
      <geometry>
        <cylinder length="0.10795" radius="0.1016"/>
      </geometry>
    </collision>
    <inertial>
      <mass value="1"/>
      <inertia ixx="0.0062805625" ixy="0" ixz="0" iyy="0.0062805625" iyz="0" izz="0.0062805625"/>
    </inertial>
  </link>
  <joint name="drive_wheel_rear_left_joint" type="continuous">
    <!-- This should really be based off the center of the robot, but that breaks the Gazebo plugin for some reason. -->
    <parent link="base_link"/>
    <child link="drive_wheel_rear_left_link"/>
    <origin rpy="0 0 0" xyz="-0.18337000000000003 0.258475 0.1016"/>
    <axis xyz="0 1 0"/>
    <!--<dynamics friction="100.0" damping="100.0" />-->
  </joint>
  <gazebo reference="drive_wheel_rear_left_link">
    <kp>1000000.0</kp>
    <kd>100.0</kd>
    <mu1>1</mu1>
    <mu2>1</mu2>
    <slip1>0.5</slip1>
    <slip2>0</slip2>
    <minDepth>0.01</minDepth>
    <maxVel>1.0</maxVel>
  </gazebo>
  <link name="drive_wheel_rear_right_link">
    <visual>
      <origin rpy="1.5707963267948966 0 0" xyz="0 0 0"/>
      <geometry>
        <cylinder length="0.10795" radius="0.1016"/>
      </geometry>
      <material name="Gray">
        <color rgba="0.5 0.5 0.5 1.0"/>
      </material>
    </visual>
    <collision>
      <origin rpy="1.5707963267948966 0 0" xyz="0 0 0"/>
      <geometry>
        <cylinder length="0.10795" radius="0.1016"/>
      </geometry>
    </collision>
    <inertial>
      <mass value="1"/>
      <inertia ixx="0.0062805625" ixy="0" ixz="0" iyy="0.0062805625" iyz="0" izz="0.0062805625"/>
    </inertial>
  </link>
  <joint name="drive_wheel_rear_right_joint" type="continuous">
    <!-- This should really be based off the center of the robot, but that breaks the Gazebo plugin for some reason. -->
    <parent link="base_link"/>
    <child link="drive_wheel_rear_right_link"/>
    <origin rpy="0 0 0" xyz="-0.18337000000000003 -0.258475 0.1016"/>
    <axis xyz="0 1 0"/>
    <!--<dynamics friction="100.0" damping="100.0" />-->
  </joint>
  <gazebo reference="drive_wheel_rear_right_link">
    <kp>1000000.0</kp>
    <kd>100.0</kd>
    <mu1>1</mu1>
    <mu2>1</mu2>
    <slip1>0.5</slip1>
    <slip2>0</slip2>
    <minDepth>0.01</minDepth>
    <maxVel>1.0</maxVel>
  </gazebo>
  <link name="drive_wheel_front_left_link">
    <visual>
      <origin rpy="1.5707963267948966 0 0" xyz="0 0 0"/>
      <geometry>
        <cylinder length="0.10795" radius="0.1016"/>
      </geometry>
      <material name="Gray">
        <color rgba="0.5 0.5 0.5 1.0"/>
      </material>
    </visual>
    <collision>
      <origin rpy="1.5707963267948966 0 0" xyz="0 0 0"/>
      <geometry>
        <cylinder length="0.10795" radius="0.1016"/>
      </geometry>
    </collision>
    <inertial>
      <mass value="1"/>
      <inertia ixx="0.0062805625" ixy="0" ixz="0" iyy="0.0062805625" iyz="0" izz="0.0062805625"/>
    </inertial>
  </link>
  <joint name="drive_wheel_front_left_joint" type="continuous">
    <!-- This should really be based off the center of the robot, but that breaks the Gazebo plugin for some reason. -->
    <parent link="base_link"/>
    <child link="drive_wheel_front_left_link"/>
    <origin rpy="0 0 0" xyz="0.18337000000000003 0.258475 0.1016"/>
    <axis xyz="0 1 0"/>
    <!--<dynamics friction="100.0" damping="100.0" />-->
  </joint>
  <gazebo reference="drive_wheel_front_left_link">
    <kp>1000000.0</kp>
    <kd>100.0</kd>
    <mu1>1</mu1>
    <mu2>1</mu2>
    <slip1>0.5</slip1>
    <slip2>0</slip2>
    <minDepth>0.01</minDepth>
    <maxVel>1.0</maxVel>
  </gazebo>
  <link name="drive_wheel_front_right_link">
    <visual>
      <origin rpy="1.5707963267948966 0 0" xyz="0 0 0"/>
      <geometry>
        <cylinder length="0.10795" radius="0.1016"/>
      </geometry>
      <material name="Gray">
        <color rgba="0.5 0.5 0.5 1.0"/>
      </material>
    </visual>
    <collision>
      <origin rpy="1.5707963267948966 0 0" xyz="0 0 0"/>
      <geometry>
        <cylinder length="0.10795" radius="0.1016"/>
      </geometry>
    </collision>
    <inertial>
      <mass value="1"/>
      <inertia ixx="0.0062805625" ixy="0" ixz="0" iyy="0.0062805625" iyz="0" izz="0.0062805625"/>
    </inertial>
  </link>
  <joint name="drive_wheel_front_right_joint" type="continuous">
    <!-- This should really be based off the center of the robot, but that breaks the Gazebo plugin for some reason. -->
    <parent link="base_link"/>
    <child link="drive_wheel_front_right_link"/>
    <origin rpy="0 0 0" xyz="0.18337000000000003 -0.258475 0.1016"/>
    <axis xyz="0 1 0"/>
    <!--<dynamics friction="100.0" damping="100.0" />-->
  </joint>
  <gazebo reference="drive_wheel_front_right_link">
    <kp>1000000.0</kp>
    <kd>100.0</kd>
    <mu1>1</mu1>
    <mu2>1</mu2>
    <slip1>0.5</slip1>
    <slip2>0</slip2>
    <minDepth>0.01</minDepth>
    <maxVel>1.0</maxVel>
  </gazebo>
  <!-- Vision/Positioning Systems (Realsense D435 and T265) -->
  <!-- For simulation, a script places all of the realsense camera sdf information here. -->
  <link name="gps_sensor_link">
    <visual>
      <geometry>
        <box size="0.001 0.001 0.001"/>
      </geometry>
      <material name="Cyan">
        <color rgba="0 1.0 1.0 1.0"/>
      </material>
    </visual>
    <collision>
      <origin rpy="0 0 0" xyz="0 0 0"/>
      <geometry>
        <box size="0.001 0.001 0.001"/>
      </geometry>
    </collision>
    <inertial>
      <mass value="0.12266"/>
      <inertia ixx="0.0177645" ixy="0.0" ixz="0.0" iyy="0.011722917" iyz="0.0" izz="0.022277168"/>
    </inertial>
  </link>
  <joint name="gps_sensor_link_joint" type="fixed">
    <parent link="center_link"/>
    <child link="gps_sensor_link"/>
    <origin rpy="0 0 0" xyz="0 0 0.302244"/>
  </joint>
  <gazebo reference="gps_sensor_link_joint">
    <disableFixedJointLumping>true</disableFixedJointLumping>
    <preserveFixedJoint>true</preserveFixedJoint>
  </gazebo>
  <link name="imu_sensor_link">
    <visual>
      <geometry>
        <box size="0.001 0.001 0.001"/>
      </geometry>
      <material name="Cyan">
        <color rgba="0 1.0 1.0 1.0"/>
      </material>
    </visual>
    <collision>
      <origin rpy="0 0 0" xyz="0 0 0"/>
      <geometry>
        <box size="0.001 0.001 0.001"/>
      </geometry>
    </collision>
    <inertial>
      <mass value="0.12266"/>
      <inertia ixx="0.0177645" ixy="0.0" ixz="0.0" iyy="0.011722917" iyz="0.0" izz="0.022277168"/>
    </inertial>
  </link>
  <joint name="imu_sensor_link_joint" type="fixed">
    <parent link="center_link"/>
    <child link="imu_sensor_link"/>
    <origin rpy="0 0 0" xyz="0 0 0.302244"/>
  </joint>
  <gazebo reference="imu_sensor_link_joint">
    <disableFixedJointLumping>true</disableFixedJointLumping>
    <preserveFixedJoint>true</preserveFixedJoint>
  </gazebo>
  <link name="camera_link">
    <visual>
      <geometry>
        <box size="0.001 0.001 0.001"/>
      </geometry>
      <material name="Cyan">
        <color rgba="0 1.0 1.0 1.0"/>
      </material>
    </visual>
    <collision>
      <origin rpy="0 0 0" xyz="0 0 0"/>
      <geometry>
        <box size="0.001 0.001 0.001"/>
      </geometry>
    </collision>
    <inertial>
      <mass value="0.12266"/>
      <inertia ixx="0.0177645" ixy="0.0" ixz="0.0" iyy="0.011722917" iyz="0.0" izz="0.022277168"/>
    </inertial>
  </link>
  <joint name="camera_link_joint" type="fixed">
    <parent link="center_link"/>
    <child link="camera_link"/>
    <origin rpy="0 0 0" xyz="0.24300000000000002 0 0.022122000000000003"/>
  </joint>
  <gazebo reference="camera_link_joint">
    <disableFixedJointLumping>true</disableFixedJointLumping>
    <preserveFixedJoint>true</preserveFixedJoint>
  </gazebo>
  <link name="camera_depth_frame">
    <visual>
      <geometry>
        <box size="0.001 0.001 0.001"/>
      </geometry>
      <material name="Cyan">
        <color rgba="0 1.0 1.0 1.0"/>
      </material>
    </visual>
    <collision>
      <origin rpy="0 0 0" xyz="0 0 0"/>
      <geometry>
        <box size="0.001 0.001 0.001"/>
      </geometry>
    </collision>
    <inertial>
      <mass value="0.12266"/>
      <inertia ixx="0.0177645" ixy="0.0" ixz="0.0" iyy="0.011722917" iyz="0.0" izz="0.022277168"/>
    </inertial>
  </link>
  <joint name="camera_depth_joint" type="fixed">
    <parent link="camera_link"/>
    <child link="camera_depth_frame"/>
    <origin rpy="0 0 0" xyz="0 0 0.01"/>
  </joint>
  <gazebo reference="camera_depth_joint">
    <disableFixedJointLumping>true</disableFixedJointLumping>
    <preserveFixedJoint>true</preserveFixedJoint>
  </gazebo>
  <link name="camera_depth_optical_frame">
    <visual>
      <geometry>
        <box size="0.001 0.001 0.001"/>
      </geometry>
      <material name="Cyan">
        <color rgba="0 1.0 1.0 1.0"/>
      </material>
    </visual>
    <collision>
      <origin rpy="0 0 0" xyz="0 0 0"/>
      <geometry>
        <box size="0.001 0.001 0.001"/>
      </geometry>
    </collision>
    <inertial>
      <mass value="0.12266"/>
      <inertia ixx="0.0177645" ixy="0.0" ixz="0.0" iyy="0.011722917" iyz="0.0" izz="0.022277168"/>
    </inertial>
  </link>
  <joint name="camera_depth_optical_joint" type="fixed">
    <parent link="camera_depth_frame"/>
    <child link="camera_depth_optical_frame"/>
    <origin rpy="-1.57 0 -1.57" xyz="0 0 0 "/>
  </joint>
  <gazebo reference="camera_depth_optical_joint">
    <disableFixedJointLumping>true</disableFixedJointLumping>
    <preserveFixedJoint>true</preserveFixedJoint>
  </gazebo>
  <link name="camera_color_frame">
    <visual>
      <geometry>
        <box size="0.001 0.001 0.001"/>
      </geometry>
      <material name="Cyan">
        <color rgba="0 1.0 1.0 1.0"/>
      </material>
    </visual>
    <collision>
      <origin rpy="0 0 0" xyz="0 0 0"/>
      <geometry>
        <box size="0.001 0.001 0.001"/>
      </geometry>
    </collision>
    <inertial>
      <mass value="0.12266"/>
      <inertia ixx="0.0177645" ixy="0.0" ixz="0.0" iyy="0.011722917" iyz="0.0" izz="0.022277168"/>
    </inertial>
  </link>
  <joint name="camera_color_joint" type="fixed">
    <parent link="camera_link"/>
    <child link="camera_color_frame"/>
    <origin rpy="0 0 0" xyz="0 0 0.01"/>
  </joint>
  <gazebo reference="camera_color_joint">
    <disableFixedJointLumping>true</disableFixedJointLumping>
    <preserveFixedJoint>true</preserveFixedJoint>
  </gazebo>
  <link name="camera_color_optical_frame">
    <visual>
      <geometry>
        <box size="0.001 0.001 0.001"/>
      </geometry>
      <material name="Cyan">
        <color rgba="0 1.0 1.0 1.0"/>
      </material>
    </visual>
    <collision>
      <origin rpy="0 0 0" xyz="0 0 0"/>
      <geometry>
        <box size="0.001 0.001 0.001"/>
      </geometry>
    </collision>
    <inertial>
      <mass value="0.12266"/>
      <inertia ixx="0.0177645" ixy="0.0" ixz="0.0" iyy="0.011722917" iyz="0.0" izz="0.022277168"/>
    </inertial>
  </link>
  <joint name="camera_color_optical_joint" type="fixed">
    <parent link="camera_color_frame"/>
    <child link="camera_color_optical_frame"/>
    <origin rpy="-1.57 0 -1.57" xyz="0 0 0 "/>
  </joint>
  <gazebo reference="camera_color_optical_joint">
    <disableFixedJointLumping>true</disableFixedJointLumping>
    <preserveFixedJoint>true</preserveFixedJoint>
  </gazebo>
  <link name="camera_left_ir_frame">
    <visual>
      <geometry>
        <box size="0.001 0.001 0.001"/>
      </geometry>
      <material name="Cyan">
        <color rgba="0 1.0 1.0 1.0"/>
      </material>
    </visual>
    <collision>
      <origin rpy="0 0 0" xyz="0 0 0"/>
      <geometry>
        <box size="0.001 0.001 0.001"/>
      </geometry>
    </collision>
    <inertial>
      <mass value="0.12266"/>
      <inertia ixx="0.0177645" ixy="0.0" ixz="0.0" iyy="0.011722917" iyz="0.0" izz="0.022277168"/>
    </inertial>
  </link>
  <joint name="camera_left_ir_joint" type="fixed">
    <parent link="camera_depth_frame"/>
    <child link="camera_left_ir_frame"/>
    <origin rpy="0 0 0 " xyz="0 0 0 "/>
  </joint>
  <gazebo reference="camera_left_ir_joint">
    <disableFixedJointLumping>true</disableFixedJointLumping>
    <preserveFixedJoint>true</preserveFixedJoint>
  </gazebo>
  <link name="camera_left_ir_optical_frame">
    <visual>
      <geometry>
        <box size="0.001 0.001 0.001"/>
      </geometry>
      <material name="Cyan">
        <color rgba="0 1.0 1.0 1.0"/>
      </material>
    </visual>
    <collision>
      <origin rpy="0 0 0" xyz="0 0 0"/>
      <geometry>
        <box size="0.001 0.001 0.001"/>
      </geometry>
    </collision>
    <inertial>
      <mass value="0.12266"/>
      <inertia ixx="0.0177645" ixy="0.0" ixz="0.0" iyy="0.011722917" iyz="0.0" izz="0.022277168"/>
    </inertial>
  </link>
  <joint name="camera_left_ir_optical_joint" type="fixed">
    <parent link="camera_left_ir_frame"/>
    <child link="camera_left_ir_optical_frame"/>
    <origin rpy="-1.57 0 -1.57" xyz="0 0 0 "/>
  </joint>
  <gazebo reference="camera_left_ir_optical_joint">
    <disableFixedJointLumping>true</disableFixedJointLumping>
    <preserveFixedJoint>true</preserveFixedJoint>
  </gazebo>
  <link name="camera_right_ir_frame">
    <visual>
      <geometry>
        <box size="0.001 0.001 0.001"/>
      </geometry>
      <material name="Cyan">
        <color rgba="0 1.0 1.0 1.0"/>
      </material>
    </visual>
    <collision>
      <origin rpy="0 0 0" xyz="0 0 0"/>
      <geometry>
        <box size="0.001 0.001 0.001"/>
      </geometry>
    </collision>
    <inertial>
      <mass value="0.12266"/>
      <inertia ixx="0.0177645" ixy="0.0" ixz="0.0" iyy="0.011722917" iyz="0.0" izz="0.022277168"/>
    </inertial>
  </link>
  <joint name="camera_right_ir_joint" type="fixed">
    <parent link="camera_depth_frame"/>
    <child link="camera_right_ir_frame"/>
    <origin rpy="0 0 0" xyz="0 -0.050 0 "/>
  </joint>
  <gazebo reference="camera_right_ir_joint">
    <disableFixedJointLumping>true</disableFixedJointLumping>
    <preserveFixedJoint>true</preserveFixedJoint>
  </gazebo>
  <link name="camera_right_ir_optical_frame">
    <visual>
      <geometry>
        <box size="0.001 0.001 0.001"/>
      </geometry>
      <material name="Cyan">
        <color rgba="0 1.0 1.0 1.0"/>
      </material>
    </visual>
    <collision>
      <origin rpy="0 0 0" xyz="0 0 0"/>
      <geometry>
        <box size="0.001 0.001 0.001"/>
      </geometry>
    </collision>
    <inertial>
      <mass value="0.12266"/>
      <inertia ixx="0.0177645" ixy="0.0" ixz="0.0" iyy="0.011722917" iyz="0.0" izz="0.022277168"/>
    </inertial>
  </link>
  <joint name="camera_right_ir_optical_joint" type="fixed">
    <parent link="camera_right_ir_frame"/>
    <child link="camera_right_ir_optical_frame"/>
    <origin rpy="-1.57 0 -1.57" xyz="0 0 0 "/>
  </joint>
  <gazebo reference="camera_right_ir_optical_joint">
    <disableFixedJointLumping>true</disableFixedJointLumping>
    <preserveFixedJoint>true</preserveFixedJoint>
  </gazebo>
  <!-- T265 TF Links
    <xacro:unless value="$(arg use_simulation)">
        <xacro:framelink prefix="base_link" />
        <joint name="base_to_center_joint" type="fixed">
            <parent link="base_link" />
            <child link="center_link" />
            <origin xyz="-${(base_length / 2) - 0.032} 0 -${(base_height / 2) - 0.129}" rpy="0 0 0" />
        </joint>
        <xacro:fixedlink joint_name="base_to_center_joint" />
    </xacro:unless>-->
  <!-- Include Gazebo plugins and simulation definitions -->
  <!--<xacro:if value="$(arg use_simulation)">
        <xacro:include filename="$(find ardak)/description/ardak/ardak.gazebo" />
    </xacro:if>-->
</robot>
