<sdf version='1.7'>
  <model name='ardak'>
    <link name='base_link'>
      <inertial>
        <pose>0 0 0 0 -0 0</pose>
        <mass>18.14</mass>
        <inertia>
          <ixx>2.66469</ixx>
          <ixy>0</ixy>
          <ixz>0</ixz>
          <iyy>1.75844</iyy>
          <iyz>0</iyz>
          <izz>3.34158</izz>
        </inertia>
      </inertial>
      <collision name='base_link_collision'>
        <pose>0 0 0 0 -0 0</pose>
        <geometry>
          <box>
            <size>0.7112 0.35 0.302244</size>
          </box>
        </geometry>
        <surface>
          <contact>
            <ode/>
          </contact>
          <friction>
            <ode/>
          </friction>
        </surface>
      </collision>
      <visual name='base_link_visual'>
        <pose>0 0 0 0 -0 0</pose>
        <geometry>
          <box>
            <size>0.7112 0.35 0.302244</size>
          </box>
        </geometry>
        <material>
          <script>
            <name>Gazebo/White</name>
            <uri>file://media/materials/scripts/gazebo.material</uri>
          </script>
        </material>
      </visual>
    </link>
    <joint name='drive_wheel_front_left_joint' type='revolute'>
      <pose relative_to='base_link'>0.26397 0.258475 -0.10633 0 -0 0</pose>
      <parent>base_link</parent>
      <child>drive_wheel_front_left_link</child>
      <axis>
        <xyz>0 1 0</xyz>
        <limit>
          <lower>-1e+16</lower>
          <upper>1e+16</upper>
        </limit>
        <dynamics>
          <spring_reference>0</spring_reference>
          <spring_stiffness>0</spring_stiffness>
        </dynamics>
      </axis>
    </joint>
    <link name='drive_wheel_front_left_link'>
      <pose relative_to='drive_wheel_front_left_joint'>0 0 0 0 -0 0</pose>
      <inertial>
        <pose>0 0 0 0 -0 0</pose>
        <mass>1</mass>
        <inertia>
          <ixx>0.00354045</ixx>
          <ixy>0</ixy>
          <ixz>0</ixz>
          <iyy>0.00628056</iyy>
          <iyz>0</iyz>
          <izz>0.00628056</izz>
        </inertia>
      </inertial>
      <collision name='drive_wheel_front_left_link_collision'>
        <pose>0 0 0 1.5708 -0 0</pose>
        <geometry>
          <cylinder>
            <length>0.10795</length>
            <radius>0.1016</radius>
          </cylinder>
        </geometry>
        <surface>
          <contact>
            <ode>
              <kp>1e+06</kp>
              <kd>100</kd>
              <min_depth>0.01</min_depth>
            </ode>
          </contact>
          <friction>
            <ode>
              <mu2>0.8</mu2>
              <fdir1>1 0 0</fdir1>
            </ode>
          </friction>
        </surface>
        <max_contacts>3</max_contacts>
      </collision>
      <visual name='drive_wheel_front_left_link_visual'>
        <pose>0 0 0 1.5708 -0 0</pose>
        <geometry>
          <cylinder>
            <length>0.10795</length>
            <radius>0.1016</radius>
          </cylinder>
        </geometry>
      </visual>
      <mu>0.8</mu>
      <slip1>0.5</slip1>
      <slip2>0</slip2>
    </link>
    <joint name='drive_wheel_front_right_joint' type='revolute'>
      <pose relative_to='base_link'>0.26397 -0.258475 -0.10633 0 -0 0</pose>
      <parent>base_link</parent>
      <child>drive_wheel_front_right_link</child>
      <axis>
        <xyz>0 1 0</xyz>
        <limit>
          <lower>-1e+16</lower>
          <upper>1e+16</upper>
        </limit>
        <dynamics>
          <spring_reference>0</spring_reference>
          <spring_stiffness>0</spring_stiffness>
        </dynamics>
      </axis>
    </joint>
    <link name='drive_wheel_front_right_link'>
      <pose relative_to='drive_wheel_front_right_joint'>0 0 0 0 -0 0</pose>
      <inertial>
        <pose>0 0 0 0 -0 0</pose>
        <mass>1</mass>
        <inertia>
          <ixx>0.00354045</ixx>
          <ixy>0</ixy>
          <ixz>0</ixz>
          <iyy>0.00628056</iyy>
          <iyz>0</iyz>
          <izz>0.00628056</izz>
        </inertia>
      </inertial>
      <collision name='drive_wheel_front_right_link_collision'>
        <pose>0 0 0 1.5708 -0 0</pose>
        <geometry>
          <cylinder>
            <length>0.10795</length>
            <radius>0.1016</radius>
          </cylinder>
        </geometry>
        <surface>
          <contact>
            <ode>
              <kp>1e+06</kp>
              <kd>100</kd>
              <min_depth>0.01</min_depth>
            </ode>
          </contact>
          <friction>
            <ode>
              <mu2>0.8</mu2>
              <fdir1>1 0 0</fdir1>
            </ode>
          </friction>
        </surface>
        <max_contacts>3</max_contacts>
      </collision>
      <visual name='drive_wheel_front_right_link_visual'>
        <pose>0 0 0 1.5708 -0 0</pose>
        <geometry>
          <cylinder>
            <length>0.10795</length>
            <radius>0.1016</radius>
          </cylinder>
        </geometry>
      </visual>
      <mu>0.8</mu>
      <slip1>0.5</slip1>
      <slip2>0</slip2>
    </link>
    <joint name='drive_wheel_rear_left_joint' type='revolute'>
      <pose relative_to='base_link'>-0.26397 0.258475 -0.10633 0 -0 0</pose>
      <parent>base_link</parent>
      <child>drive_wheel_rear_left_link</child>
      <axis>
        <xyz>0 1 0</xyz>
        <limit>
          <lower>-1e+16</lower>
          <upper>1e+16</upper>
        </limit>
        <dynamics>
          <spring_reference>0</spring_reference>
          <spring_stiffness>0</spring_stiffness>
        </dynamics>
      </axis>
    </joint>
    <link name='drive_wheel_rear_left_link'>
      <pose relative_to='drive_wheel_rear_left_joint'>0 0 0 0 -0 0</pose>
      <inertial>
        <pose>0 0 0 0 -0 0</pose>
        <mass>1</mass>
        <inertia>
          <ixx>0.00354045</ixx>
          <ixy>0</ixy>
          <ixz>0</ixz>
          <iyy>0.00628056</iyy>
          <iyz>0</iyz>
          <izz>0.00628056</izz>
        </inertia>
      </inertial>
      <collision name='drive_wheel_rear_left_link_collision'>
        <pose>0 0 0 1.5708 -0 0</pose>
        <geometry>
          <cylinder>
            <length>0.10795</length>
            <radius>0.1016</radius>
          </cylinder>
        </geometry>
        <surface>
          <contact>
            <ode>
              <kp>1e+06</kp>
              <kd>100</kd>
              <min_depth>0.01</min_depth>
            </ode>
          </contact>
          <friction>
            <ode>
              <mu2>0.8</mu2>
              <fdir1>1 0 0</fdir1>
            </ode>
          </friction>
        </surface>
        <max_contacts>3</max_contacts>
      </collision>
      <visual name='drive_wheel_rear_left_link_visual'>
        <pose>0 0 0 1.5708 -0 0</pose>
        <geometry>
          <cylinder>
            <length>0.10795</length>
            <radius>0.1016</radius>
          </cylinder>
        </geometry>
      </visual>
      <mu>0.8</mu>
      <slip1>0.5</slip1>
      <slip2>0</slip2>
    </link>
    <joint name='drive_wheel_rear_right_joint' type='revolute'>
      <pose relative_to='base_link'>-0.26397 -0.258475 -0.10633 0 -0 0</pose>
      <parent>base_link</parent>
      <child>drive_wheel_rear_right_link</child>
      <axis>
        <xyz>0 1 0</xyz>
        <limit>
          <lower>-1e+16</lower>
          <upper>1e+16</upper>
        </limit>
        <dynamics>
          <spring_reference>0</spring_reference>
          <spring_stiffness>0</spring_stiffness>
        </dynamics>
      </axis>
    </joint>
    <link name='drive_wheel_rear_right_link'>
      <pose relative_to='drive_wheel_rear_right_joint'>0 0 0 0 -0 0</pose>
      <inertial>
        <pose>0 0 0 0 -0 0</pose>
        <mass>1</mass>
        <inertia>
          <ixx>0.00354045</ixx>
          <ixy>0</ixy>
          <ixz>0</ixz>
          <iyy>0.00628056</iyy>
          <iyz>0</iyz>
          <izz>0.00628056</izz>
        </inertia>
      </inertial>
      <collision name='drive_wheel_rear_right_link_collision'>
        <pose>0 0 0 1.5708 -0 0</pose>
        <geometry>
          <cylinder>
            <length>0.10795</length>
            <radius>0.1016</radius>
          </cylinder>
        </geometry>
        <surface>
          <contact>
            <ode>
              <kp>1e+06</kp>
              <kd>100</kd>
              <min_depth>0.01</min_depth>
            </ode>
          </contact>
          <friction>
            <ode>
              <mu2>0.8</mu2>
              <fdir1>1 0 0</fdir1>
            </ode>
          </friction>
        </surface>
        <max_contacts>3</max_contacts>
      </collision>
      <visual name='drive_wheel_rear_right_link_visual'>
        <pose>0 0 0 1.5708 -0 0</pose>
        <geometry>
          <cylinder>
            <length>0.10795</length>
            <radius>0.1016</radius>
          </cylinder>
        </geometry>
      </visual>
      <mu>0.8</mu>
      <slip1>0.5</slip1>
      <slip2>0</slip2>
    </link>
    <static>0</static>
    <plugin name='skid_steer_drive' filename='libgazebo_ros_diff_drive.so'>
      <update_rate>100.0</update_rate>
      <num_wheel_pairs>2</num_wheel_pairs>
      <left_joint>drive_wheel_front_left_joint</left_joint>
      <right_joint>drive_wheel_front_right_joint</right_joint>
      <left_joint>drive_wheel_rear_left_joint</left_joint>
      <right_joint>drive_wheel_rear_right_joint</right_joint>
      <wheel_separation>0.43347499999999994</wheel_separation>
      <wheel_separation>0.43347499999999994</wheel_separation>
      <wheel_diameter>0.2032</wheel_diameter>
      <wheel_diameter>0.2032</wheel_diameter>
      <max_wheel_torque>10</max_wheel_torque>
      <max_wheel_acceleration>1.0</max_wheel_acceleration>
      <torque>40</torque>
      <ros>
        <namespace>/</namespace>
        <remapping>cmd_vel:=wheel_cmd</remapping>
      </ros>
      <publish_odom>1</publish_odom>
      <publish_odom_tf>1</publish_odom_tf>
      <publish_wheel_tf>0</publish_wheel_tf>
      <robot_base_frame>base_link</robot_base_frame>
    </plugin>
  </model>
</sdf>
