<?xml version="1.0" ?>
<!-- =================================================================================== -->
<!-- |    This document was autogenerated by xacro from ../description/ardak/ardak.urdf | -->
<!-- |    EDITING THIS FILE BY HAND IS NOT RECOMMENDED                                 | -->
<!-- =================================================================================== -->
<robot name="ardak">
  <link name="base_link">
    <visual>
      <geometry>
        <box size="0.7112 0.35 0.302244"/>
      </geometry>
      <material name="Cyan">
        <color rgba="0 1.0 1.0 1.0"/>
      </material>
    </visual>
    <collision>
      <origin rpy="0 0 0" xyz="0 0 0"/>
      <geometry>
        <box size="0.7112 0.35 0.302244"/>
      </geometry>
    </collision>
    <!-- Need to check these values -->
    <!-- Origin needed for inertial? -->
    <inertial>
      <mass value="18.14"/>
      <inertia ixx="2.664688434" ixy="0.0" ixz="0.0" iyy="1.758437644" iyz="0.0" izz="3.341575268"/>
    </inertial>
  </link>
  <link name="base_footprint">
    <visual>
      <geometry>
        <box size="0.0 0.0 0.1"/>
      </geometry>
      <material name="Cyan">
        <color rgba="0 1.0 1.0 1.0"/>
      </material>
    </visual>
    <collision>
      <origin rpy="0 0 0" xyz="0 0 0"/>
      <geometry>
        <box size="0.0 0.0 0.0"/>
      </geometry>
    </collision>
    <inertial>
      <mass value="0.1"/>
      <inertia ixx="0.0" ixy="0.0" ixz="0.0" iyy="0.0" iyz="0.0" izz="0.001"/>
    </inertial>
  </link>
  <joint name="base_footprint_joint" type="fixed">
    <parent link="base_link"/>
    <child link="base_footprint"/>
    <origin rpy="0 0 0" xyz="0.0 0.0 -0.20793"/>
  </joint>
  <gazebo reference="base_footprint_joint">
    <disableFixedJointLumping>true</disableFixedJointLumping>
    <preserveFixedJoint>true</preserveFixedJoint>
  </gazebo>
  <link name="drive_wheel_rear_left_link">
    <visual>
      <origin rpy="1.5707963267948966 0 0" xyz="0 0 0"/>
      <geometry>
        <cylinder length="0.10795" radius="0.1016"/>
      </geometry>
      <material name="Gray">
        <color rgba="0.5 0.5 0.5 1.0"/>
      </material>
    </visual>
    <collision>
      <origin rpy="1.5707963267948966 0 0" xyz="0 0 0"/>
      <geometry>
        <cylinder length="0.10795" radius="0.1016"/>
      </geometry>
    </collision>
    <inertial>
      <mass value="1"/>
      <inertia ixx="0.0062805625" ixy="0" ixz="0" iyy="0.0062805625" iyz="0" izz="0.0062805625"/>
    </inertial>
  </link>
  <joint name="drive_wheel_rear_left_joint" type="continuous">
    <parent link="base_link"/>
    <child link="drive_wheel_rear_left_link"/>
    <origin rpy="0 0 0" xyz="-0.26397000000000004 0.258475 -0.10633000000000001"/>
    <axis xyz="0 1 0"/>
    <!--<dynamics friction="100.0" damping="100.0" />-->
  </joint>
  <gazebo reference="drive_wheel_rear_left_link">
    <kp>1000000.0</kp>
    <kd>100.0</kd>
    <mu1>1</mu1>
    <mu2>1</mu2>
    <slip1>0.5</slip1>
    <slip2>0</slip2>
    <minDepth>0.01</minDepth>
    <maxVel>1.0</maxVel>
  </gazebo>
  <link name="drive_wheel_rear_right_link">
    <visual>
      <origin rpy="1.5707963267948966 0 0" xyz="0 0 0"/>
      <geometry>
        <cylinder length="0.10795" radius="0.1016"/>
      </geometry>
      <material name="Gray">
        <color rgba="0.5 0.5 0.5 1.0"/>
      </material>
    </visual>
    <collision>
      <origin rpy="1.5707963267948966 0 0" xyz="0 0 0"/>
      <geometry>
        <cylinder length="0.10795" radius="0.1016"/>
      </geometry>
    </collision>
    <inertial>
      <mass value="1"/>
      <inertia ixx="0.0062805625" ixy="0" ixz="0" iyy="0.0062805625" iyz="0" izz="0.0062805625"/>
    </inertial>
  </link>
  <joint name="drive_wheel_rear_right_joint" type="continuous">
    <parent link="base_link"/>
    <child link="drive_wheel_rear_right_link"/>
    <origin rpy="0 0 0" xyz="-0.26397000000000004 -0.258475 -0.10633000000000001"/>
    <axis xyz="0 1 0"/>
    <!--<dynamics friction="100.0" damping="100.0" />-->
  </joint>
  <gazebo reference="drive_wheel_rear_right_link">
    <kp>1000000.0</kp>
    <kd>100.0</kd>
    <mu1>1</mu1>
    <mu2>1</mu2>
    <slip1>0.5</slip1>
    <slip2>0</slip2>
    <minDepth>0.01</minDepth>
    <maxVel>1.0</maxVel>
  </gazebo>
  <link name="drive_wheel_front_left_link">
    <visual>
      <origin rpy="1.5707963267948966 0 0" xyz="0 0 0"/>
      <geometry>
        <cylinder length="0.10795" radius="0.1016"/>
      </geometry>
      <material name="Gray">
        <color rgba="0.5 0.5 0.5 1.0"/>
      </material>
    </visual>
    <collision>
      <origin rpy="1.5707963267948966 0 0" xyz="0 0 0"/>
      <geometry>
        <cylinder length="0.10795" radius="0.1016"/>
      </geometry>
    </collision>
    <inertial>
      <mass value="1"/>
      <inertia ixx="0.0062805625" ixy="0" ixz="0" iyy="0.0062805625" iyz="0" izz="0.0062805625"/>
    </inertial>
  </link>
  <joint name="drive_wheel_front_left_joint" type="continuous">
    <parent link="base_link"/>
    <child link="drive_wheel_front_left_link"/>
    <origin rpy="0 0 0" xyz="0.26397000000000004 0.258475 -0.10633000000000001"/>
    <axis xyz="0 1 0"/>
    <!--<dynamics friction="100.0" damping="100.0" />-->
  </joint>
  <gazebo reference="drive_wheel_front_left_link">
    <kp>1000000.0</kp>
    <kd>100.0</kd>
    <mu1>1</mu1>
    <mu2>1</mu2>
    <slip1>0.5</slip1>
    <slip2>0</slip2>
    <minDepth>0.01</minDepth>
    <maxVel>1.0</maxVel>
  </gazebo>
  <link name="drive_wheel_front_right_link">
    <visual>
      <origin rpy="1.5707963267948966 0 0" xyz="0 0 0"/>
      <geometry>
        <cylinder length="0.10795" radius="0.1016"/>
      </geometry>
      <material name="Gray">
        <color rgba="0.5 0.5 0.5 1.0"/>
      </material>
    </visual>
    <collision>
      <origin rpy="1.5707963267948966 0 0" xyz="0 0 0"/>
      <geometry>
        <cylinder length="0.10795" radius="0.1016"/>
      </geometry>
    </collision>
    <inertial>
      <mass value="1"/>
      <inertia ixx="0.0062805625" ixy="0" ixz="0" iyy="0.0062805625" iyz="0" izz="0.0062805625"/>
    </inertial>
  </link>
  <joint name="drive_wheel_front_right_joint" type="continuous">
    <parent link="base_link"/>
    <child link="drive_wheel_front_right_link"/>
    <origin rpy="0 0 0" xyz="0.26397000000000004 -0.258475 -0.10633000000000001"/>
    <axis xyz="0 1 0"/>
    <!--<dynamics friction="100.0" damping="100.0" />-->
  </joint>
  <gazebo reference="drive_wheel_front_right_link">
    <kp>1000000.0</kp>
    <kd>100.0</kd>
    <mu1>1</mu1>
    <mu2>1</mu2>
    <slip1>0.5</slip1>
    <slip2>0</slip2>
    <minDepth>0.01</minDepth>
    <maxVel>1.0</maxVel>
  </gazebo>
  <!-- Vision/Positioning Systems (Realsense D435 and T265) -->
  <!-- For simulation, a script places all of the realsense camera sdf information here. -->
  <!-- GPS TF links -->
  <link name="gps_link">
    <visual>
      <geometry>
        <box size="0.0 0.0 0.1"/>
      </geometry>
      <material name="Cyan">
        <color rgba="0 1.0 1.0 1.0"/>
      </material>
    </visual>
    <collision>
      <origin rpy="0 0 0" xyz="0 0 0"/>
      <geometry>
        <box size="0.0 0.0 0.0"/>
      </geometry>
    </collision>
    <inertial>
      <mass value="0.1"/>
      <inertia ixx="0.0" ixy="0.0" ixz="0.0" iyy="0.0" iyz="0.0" izz="0.001"/>
    </inertial>
  </link>
  <joint name="gps_link_joint" type="fixed">
    <parent link="base_link"/>
    <child link="gps_link"/>
    <origin rpy="0 0 0" xyz="0 0 0.302244"/>
  </joint>
  <gazebo reference="gps_link_joint">
    <disableFixedJointLumping>true</disableFixedJointLumping>
    <preserveFixedJoint>true</preserveFixedJoint>
  </gazebo>
  <!-- IMU TF links -->
  <link name="imu_sensor_link">
    <visual>
      <geometry>
        <box size="0.0 0.0 0.1"/>
      </geometry>
      <material name="Cyan">
        <color rgba="0 1.0 1.0 1.0"/>
      </material>
    </visual>
    <collision>
      <origin rpy="0 0 0" xyz="0 0 0"/>
      <geometry>
        <box size="0.0 0.0 0.0"/>
      </geometry>
    </collision>
    <inertial>
      <mass value="0.1"/>
      <inertia ixx="0.0" ixy="0.0" ixz="0.0" iyy="0.0" iyz="0.0" izz="0.001"/>
    </inertial>
  </link>
  <joint name="imu_link_joint" type="fixed">
    <parent link="base_link"/>
    <child link="imu_sensor_link"/>
    <origin rpy="0 0 0" xyz="0 0 0.302244"/>
  </joint>
  <gazebo reference="imu_sensor_link_joint">
    <disableFixedJointLumping>true</disableFixedJointLumping>
    <preserveFixedJoint>true</preserveFixedJoint>
  </gazebo>
  <link name="camera_link">
    <visual>
      <geometry>
        <box size="0.0 0.0 0.1"/>
      </geometry>
      <material name="Cyan">
        <color rgba="0 1.0 1.0 1.0"/>
      </material>
    </visual>
    <collision>
      <origin rpy="0 0 0" xyz="0 0 0"/>
      <geometry>
        <box size="0.0 0.0 0.0"/>
      </geometry>
    </collision>
    <inertial>
      <mass value="0.1"/>
      <inertia ixx="0.0" ixy="0.0" ixz="0.0" iyy="0.0" iyz="0.0" izz="0.001"/>
    </inertial>
  </link>
  <joint name="camera_link_joint" type="fixed">
    <parent link="base_link"/>
    <child link="camera_link"/>
    <origin rpy="0 0 0" xyz="0.3236 0 0.022122000000000003"/>
  </joint>
  <gazebo reference="camera_link_joint">
    <disableFixedJointLumping>true</disableFixedJointLumping>
    <preserveFixedJoint>true</preserveFixedJoint>
  </gazebo>
  <link name="camera_depth_frame">
    <visual>
      <geometry>
        <box size="0.0 0.0 0.1"/>
      </geometry>
      <material name="Cyan">
        <color rgba="0 1.0 1.0 1.0"/>
      </material>
    </visual>
    <collision>
      <origin rpy="0 0 0" xyz="0 0 0"/>
      <geometry>
        <box size="0.0 0.0 0.0"/>
      </geometry>
    </collision>
    <inertial>
      <mass value="0.1"/>
      <inertia ixx="0.0" ixy="0.0" ixz="0.0" iyy="0.0" iyz="0.0" izz="0.001"/>
    </inertial>
  </link>
  <joint name="camera_depth_joint" type="fixed">
    <parent link="camera_link"/>
    <child link="camera_depth_frame"/>
    <origin rpy="0 0 0" xyz="0 0 0.01"/>
  </joint>
  <gazebo reference="camera_depth_joint">
    <disableFixedJointLumping>true</disableFixedJointLumping>
    <preserveFixedJoint>true</preserveFixedJoint>
  </gazebo>
  <link name="camera_depth_optical_frame">
    <visual>
      <geometry>
        <box size="0.0 0.0 0.1"/>
      </geometry>
      <material name="Cyan">
        <color rgba="0 1.0 1.0 1.0"/>
      </material>
    </visual>
    <collision>
      <origin rpy="0 0 0" xyz="0 0 0"/>
      <geometry>
        <box size="0.0 0.0 0.0"/>
      </geometry>
    </collision>
    <inertial>
      <mass value="0.1"/>
      <inertia ixx="0.0" ixy="0.0" ixz="0.0" iyy="0.0" iyz="0.0" izz="0.001"/>
    </inertial>
  </link>
  <joint name="camera_depth_optical_joint" type="fixed">
    <parent link="camera_depth_frame"/>
    <child link="camera_depth_optical_frame"/>
    <origin rpy="-1.57 0 -1.57" xyz="0 0 0 "/>
  </joint>
  <gazebo reference="camera_depth_optical_joint">
    <disableFixedJointLumping>true</disableFixedJointLumping>
    <preserveFixedJoint>true</preserveFixedJoint>
  </gazebo>
  <link name="camera_color_frame">
    <visual>
      <geometry>
        <box size="0.0 0.0 0.1"/>
      </geometry>
      <material name="Cyan">
        <color rgba="0 1.0 1.0 1.0"/>
      </material>
    </visual>
    <collision>
      <origin rpy="0 0 0" xyz="0 0 0"/>
      <geometry>
        <box size="0.0 0.0 0.0"/>
      </geometry>
    </collision>
    <inertial>
      <mass value="0.1"/>
      <inertia ixx="0.0" ixy="0.0" ixz="0.0" iyy="0.0" iyz="0.0" izz="0.001"/>
    </inertial>
  </link>
  <joint name="camera_color_joint" type="fixed">
    <parent link="camera_link"/>
    <child link="camera_color_frame"/>
    <origin rpy="0 0 0" xyz="0 0 0.01"/>
  </joint>
  <gazebo reference="camera_color_joint">
    <disableFixedJointLumping>true</disableFixedJointLumping>
    <preserveFixedJoint>true</preserveFixedJoint>
  </gazebo>
  <link name="camera_color_optical_frame">
    <visual>
      <geometry>
        <box size="0.0 0.0 0.1"/>
      </geometry>
      <material name="Cyan">
        <color rgba="0 1.0 1.0 1.0"/>
      </material>
    </visual>
    <collision>
      <origin rpy="0 0 0" xyz="0 0 0"/>
      <geometry>
        <box size="0.0 0.0 0.0"/>
      </geometry>
    </collision>
    <inertial>
      <mass value="0.1"/>
      <inertia ixx="0.0" ixy="0.0" ixz="0.0" iyy="0.0" iyz="0.0" izz="0.001"/>
    </inertial>
  </link>
  <joint name="camera_color_optical_joint" type="fixed">
    <parent link="camera_color_frame"/>
    <child link="camera_color_optical_frame"/>
    <origin rpy="-1.57 0 -1.57" xyz="0 0 0 "/>
  </joint>
  <gazebo reference="camera_color_optical_joint">
    <disableFixedJointLumping>true</disableFixedJointLumping>
    <preserveFixedJoint>true</preserveFixedJoint>
  </gazebo>
  <link name="camera_left_ir_frame">
    <visual>
      <geometry>
        <box size="0.0 0.0 0.1"/>
      </geometry>
      <material name="Cyan">
        <color rgba="0 1.0 1.0 1.0"/>
      </material>
    </visual>
    <collision>
      <origin rpy="0 0 0" xyz="0 0 0"/>
      <geometry>
        <box size="0.0 0.0 0.0"/>
      </geometry>
    </collision>
    <inertial>
      <mass value="0.1"/>
      <inertia ixx="0.0" ixy="0.0" ixz="0.0" iyy="0.0" iyz="0.0" izz="0.001"/>
    </inertial>
  </link>
  <joint name="camera_left_ir_joint" type="fixed">
    <parent link="camera_depth_frame"/>
    <child link="camera_left_ir_frame"/>
    <origin rpy="0 0 0 " xyz="0 0 0 "/>
  </joint>
  <gazebo reference="camera_left_ir_joint">
    <disableFixedJointLumping>true</disableFixedJointLumping>
    <preserveFixedJoint>true</preserveFixedJoint>
  </gazebo>
  <link name="camera_left_ir_optical_frame">
    <visual>
      <geometry>
        <box size="0.0 0.0 0.1"/>
      </geometry>
      <material name="Cyan">
        <color rgba="0 1.0 1.0 1.0"/>
      </material>
    </visual>
    <collision>
      <origin rpy="0 0 0" xyz="0 0 0"/>
      <geometry>
        <box size="0.0 0.0 0.0"/>
      </geometry>
    </collision>
    <inertial>
      <mass value="0.1"/>
      <inertia ixx="0.0" ixy="0.0" ixz="0.0" iyy="0.0" iyz="0.0" izz="0.001"/>
    </inertial>
  </link>
  <joint name="camera_left_ir_optical_joint" type="fixed">
    <parent link="camera_left_ir_frame"/>
    <child link="camera_left_ir_optical_frame"/>
    <origin rpy="-1.57 0 -1.57" xyz="0 0 0 "/>
  </joint>
  <gazebo reference="camera_left_ir_optical_joint">
    <disableFixedJointLumping>true</disableFixedJointLumping>
    <preserveFixedJoint>true</preserveFixedJoint>
  </gazebo>
  <link name="camera_right_ir_frame">
    <visual>
      <geometry>
        <box size="0.0 0.0 0.1"/>
      </geometry>
      <material name="Cyan">
        <color rgba="0 1.0 1.0 1.0"/>
      </material>
    </visual>
    <collision>
      <origin rpy="0 0 0" xyz="0 0 0"/>
      <geometry>
        <box size="0.0 0.0 0.0"/>
      </geometry>
    </collision>
    <inertial>
      <mass value="0.1"/>
      <inertia ixx="0.0" ixy="0.0" ixz="0.0" iyy="0.0" iyz="0.0" izz="0.001"/>
    </inertial>
  </link>
  <joint name="camera_right_ir_joint" type="fixed">
    <parent link="camera_depth_frame"/>
    <child link="camera_right_ir_frame"/>
    <origin rpy="0 0 0" xyz="0 -0.050 0 "/>
  </joint>
  <gazebo reference="camera_right_ir_joint">
    <disableFixedJointLumping>true</disableFixedJointLumping>
    <preserveFixedJoint>true</preserveFixedJoint>
  </gazebo>
  <link name="camera_right_ir_optical_frame">
    <visual>
      <geometry>
        <box size="0.0 0.0 0.1"/>
      </geometry>
      <material name="Cyan">
        <color rgba="0 1.0 1.0 1.0"/>
      </material>
    </visual>
    <collision>
      <origin rpy="0 0 0" xyz="0 0 0"/>
      <geometry>
        <box size="0.0 0.0 0.0"/>
      </geometry>
    </collision>
    <inertial>
      <mass value="0.1"/>
      <inertia ixx="0.0" ixy="0.0" ixz="0.0" iyy="0.0" iyz="0.0" izz="0.001"/>
    </inertial>
  </link>
  <joint name="camera_right_ir_optical_joint" type="fixed">
    <parent link="camera_right_ir_frame"/>
    <child link="camera_right_ir_optical_frame"/>
    <origin rpy="-1.57 0 -1.57" xyz="0 0 0 "/>
  </joint>
  <gazebo reference="camera_right_ir_optical_joint">
    <disableFixedJointLumping>true</disableFixedJointLumping>
    <preserveFixedJoint>true</preserveFixedJoint>
  </gazebo>
  <gazebo>
    <plugin filename="libgazebo_ros_diff_drive.so" name="diff_drive">
      <update_rate>1000.0</update_rate>
      <num_wheel_pairs>2</num_wheel_pairs>
      <left_joint>drive_wheel_front_left_joint</left_joint>
      <right_joint>drive_wheel_front_right_joint</right_joint>
      <left_joint>drive_wheel_rear_left_joint</left_joint>
      <right_joint>drive_wheel_rear_right_joint</right_joint>
      <wheel_separation>0.43347499999999994</wheel_separation>
      <wheel_separation>0.43347499999999994</wheel_separation>
      <wheel_diameter>0.2032</wheel_diameter>
      <wheel_diameter>0.2032</wheel_diameter>
      <!-- limits -->
      <max_wheel_torque>40</max_wheel_torque>
      <max_wheel_acceleration>1.0</max_wheel_acceleration>
      <torque>40</torque>
      <ros>
        <namespace>/</namespace>
        <remapping>cmd_vel:=wheel_cmd</remapping>
      </ros>
      <publish_odom>true</publish_odom>
      <publish_odom_tf>true</publish_odom_tf>
      <publish_wheel_tf>true</publish_wheel_tf>
      <robot_base_frame>base_link</robot_base_frame>
      <covariance_x>0.001</covariance_x>
      <!-- 0.0001 -->
      <covariance_y>0.001</covariance_y>
      <!-- 0.0001 -->
      <covariance_yaw>0.01</covariance_yaw>
      <!-- 0.01 -->
    </plugin>
  </gazebo>
  <gazebo reference="base_link">
    <material>Gazebo/White</material>
  </gazebo>
  <gazebo>
    <plugin filename="librealsense_gazebo_plugin.so" name="camera">
      <prefix>camera</prefix>
      <depthUpdateRate>30.0</depthUpdateRate>
      <colorUpdateRate>30.0</colorUpdateRate>
      <infraredUpdateRate>1.0</infraredUpdateRate>
      <depthTopicName>aligned_depth_to_color/image_raw</depthTopicName>
      <depthCameraInfoTopicName>depth/camera_info</depthCameraInfoTopicName>
      <colorTopicName>color/image_raw</colorTopicName>
      <colorCameraInfoTopicName>color/camera_info</colorCameraInfoTopicName>
      <infrared1TopicName>infra1/image_raw</infrared1TopicName>
      <infrared1CameraInfoTopicName>infra1/camera_info</infrared1CameraInfoTopicName>
      <infrared2TopicName>infra2/image_raw</infrared2TopicName>
      <infrared2CameraInfoTopicName>infra2/camera_info</infrared2CameraInfoTopicName>
      <colorOpticalframeName>camera_color_optical_frame</colorOpticalframeName>
      <depthOpticalframeName>camera_depth_optical_frame</depthOpticalframeName>
      <infrared1OpticalframeName>camera_left_ir_optical_frame</infrared1OpticalframeName>
      <infrared2OpticalframeName>camera_right_ir_optical_frame</infrared2OpticalframeName>
      <rangeMinDepth>0.3</rangeMinDepth>
      <rangeMaxDepth>3.0</rangeMaxDepth>
      <pointCloud>true</pointCloud>
      <pointCloudTopicName>depth/color/points</pointCloudTopicName>
      <pointCloudCutoff>0.3</pointCloudCutoff>
    </plugin>
  </gazebo>
</robot>
