<sdf version='1.9'>
  <model name='ardak'>
<link name="realsense_link">
  <pose relative_to='camera_link'>0 0 0 0 -0 0</pose>
  <visual name="realsense_link_visual">
    <pose>0 0 0 -1.57 0 -1.57</pose>
    <geometry>
      <box>
        <size>0.02505 0.090 0.025</size>
      </box>
      <!--<mesh>
        <uri>model://ardak/meshes/d435.dae</uri>
      </mesh>-->
    </geometry>
  </visual>
  <collision name="realsense_link_collision">
    <pose>0 0 0 -1.57 0 -1.57</pose>
    <geometry>
      <box>
        <size>0.02505 0.090 0.025</size>
      </box>
    </geometry>
  </collision>
  <inertial>
    <pose>0 0 0 0 0 0</pose>
    <inertia>
      <ixx>0.001</ixx>
      <ixy>0.000</ixy>
      <ixz>0.000</ixz>
      <iyy>0.001</iyy>
      <iyz>0.000</iyz>
      <izz>0.001</izz>
    </inertia>
    <mass>0.564</mass>
  </inertial>

  <sensor name="cameradepth" type="depth">
    <camera name="camera">
      <horizontal_fov>1.57</horizontal_fov>
      <image>
        <width>1280</width>
        <height>720</height>
      </image>
      <clip>
        <near>0.1</near>
        <far>100</far>
      </clip>
      <noise>
        <type>gaussian</type>
        <mean>0.0</mean>
        <stddev>0.100</stddev>
      </noise>
    </camera>
    <always_on>1</always_on>
    <update_rate>30</update_rate>
    <visualize>0</visualize>
  </sensor>
  <sensor name="cameracolor" type="camera">
    <camera name="camera">
      <horizontal_fov>1.57</horizontal_fov>
      <image>
        <width>1280</width>
        <height>720</height>
        <format>RGB_INT8</format>
      </image>
      <clip>
        <near>0.1</near>
        <far>100</far>
      </clip>
      <noise>
        <type>gaussian</type>
        <mean>0.0</mean>
        <stddev>0.007</stddev>
      </noise>
    </camera>
    <always_on>1</always_on>
    <update_rate>30</update_rate>
    <visualize>1</visualize>
  </sensor>
  <sensor name="cameraired1" type="camera">
    <camera name="camera">
      <horizontal_fov>1.57</horizontal_fov>
      <image>
        <width>1280</width>
        <height>720</height>
        <format>L_INT8</format>
      </image>
      <clip>
        <near>0.1</near>
        <far>100</far>
      </clip>
      <noise>
        <type>gaussian</type>
        <mean>0.0</mean>
        <stddev>0.05</stddev>
      </noise>
    </camera>
    <always_on>1</always_on>
    <update_rate>1</update_rate>
    <visualize>0</visualize>
  </sensor>
  <sensor name="cameraired2" type="camera">
    <camera name="camera">
      <horizontal_fov>1.57</horizontal_fov>
      <image>
        <width>1280</width>
        <height>720</height>
        <format>L_INT8</format>
      </image>
      <clip>
        <near>0.1</near>
        <far>100</far>
      </clip>
      <noise>
        <type>gaussian</type>
        <mean>0.0</mean>
        <stddev>0.05</stddev>
      </noise>
    </camera>
    <always_on>1</always_on>
    <update_rate>1</update_rate>
    <visualize>0</visualize>
  </sensor>
</link>

<joint name="realsense_joint" type="fixed">
  <parent>base_link</parent>
  <child>realsense_link</child>
  <pose>0.4 0 0.4 0 0 0</pose>
</joint>    <link name='base_link'>
      <inertial>
        <pose>0 0 0 0 0 0</pose>
        <mass>0.12266000000000001</mass>
        <inertia>
          <ixx>0.017764499999999999</ixx>
          <ixy>0</ixy>
          <ixz>0</ixz>
          <iyy>0.011722916999999999</iyy>
          <iyz>0</iyz>
          <izz>0.022277168</izz>
        </inertia>
      </inertial>
      <collision name='base_link_collision'>
        <pose>0 0 0 0 0 0</pose>
        <geometry>
          <box>
            <size>0.001 0.001 0.001</size>
          </box>
        </geometry>
      </collision>
      <visual name='base_link_visual'>
        <pose>0 0 0 0 0 0</pose>
        <geometry>
          <box>
            <size>0.001 0.001 0.001</size>
          </box>
        </geometry>
        <material>
          <diffuse>0 1 1 1</diffuse>
          <ambient>0 1 1 1</ambient>
        </material>
      </visual>
    </link>
    <joint name='base_footprint_joint' type='fixed'>
      <pose relative_to='base_link'>0 0 0.20793 0 0 0</pose>
      <parent>base_link</parent>
      <child>center_link</child>
      <axis>
        <dynamics>
          <spring_reference>0</spring_reference>
          <spring_stiffness>0</spring_stiffness>
        </dynamics>
        <xyz>0 0 1</xyz>
        <limit>
          <lower>-10000000000000000</lower>
          <upper>10000000000000000</upper>
        </limit>
      </axis>
      <physics>
        <ode>
          <limit>
            <cfm>0</cfm>
            <erp>0.20000000000000001</erp>
          </limit>
        </ode>
      </physics>
    </joint>
    <link name='center_link'>
      <pose relative_to='base_footprint_joint'>0 0 0 0 0 0</pose>
      <inertial>
        <pose>0 0 0 0 0 0</pose>
        <mass>18.140000000000001</mass>
        <inertia>
          <ixx>2.6646884339999999</ixx>
          <ixy>0</ixy>
          <ixz>0</ixz>
          <iyy>1.758437644</iyy>
          <iyz>0</iyz>
          <izz>3.3415752680000002</izz>
        </inertia>
      </inertial>
      <collision name='center_link_collision'>
        <pose>0 0 0 0 0 0</pose>
        <geometry>
          <box>
            <size>0.55 0.35 0.302244</size>
          </box>
        </geometry>
      </collision>
      <visual name='center_link_visual'>
        <pose>0 0 0 0 0 0</pose>
        <geometry>
          <box>
            <size>0.55 0.35 0.302244</size>
          </box>
        </geometry>
        <material>
          <diffuse>0 1 1 1</diffuse>
          <ambient>0 1 1 1</ambient>
        </material>
      </visual>
    </link>
    <joint name='camera_link_joint' type='fixed'>
      <pose relative_to='center_link'>0.243 0 0.022122 0 0 0</pose>
      <parent>center_link</parent>
      <child>camera_link</child>
      <axis>
        <dynamics>
          <spring_reference>0</spring_reference>
          <spring_stiffness>0</spring_stiffness>
        </dynamics>
        <xyz>0 0 1</xyz>
        <limit>
          <lower>-10000000000000000</lower>
          <upper>10000000000000000</upper>
        </limit>
      </axis>
      <physics>
        <ode>
          <limit>
            <cfm>0</cfm>
            <erp>0.20000000000000001</erp>
          </limit>
        </ode>
      </physics>
    </joint>
    <link name='camera_link'>
      <pose relative_to='camera_link_joint'>0 0 0 0 0 0</pose>
      <inertial>
        <pose>0 0 0 0 0 0</pose>
        <mass>0.12266000000000001</mass>
        <inertia>
          <ixx>0.017764499999999999</ixx>
          <ixy>0</ixy>
          <ixz>0</ixz>
          <iyy>0.011722916999999999</iyy>
          <iyz>0</iyz>
          <izz>0.022277168</izz>
        </inertia>
      </inertial>
      <collision name='camera_link_collision'>
        <pose>0 0 0 0 0 0</pose>
        <geometry>
          <box>
            <size>0.001 0.001 0.001</size>
          </box>
        </geometry>
      </collision>
      <visual name='camera_link_visual'>
        <pose>0 0 0 0 0 0</pose>
        <geometry>
          <box>
            <size>0.001 0.001 0.001</size>
          </box>
        </geometry>
        <material>
          <diffuse>0 1 1 1</diffuse>
          <ambient>0 1 1 1</ambient>
        </material>
      </visual>
    </link>
    <joint name='camera_color_joint' type='fixed'>
      <pose relative_to='camera_link'>0 0 0.01 0 0 0</pose>
      <parent>camera_link</parent>
      <child>camera_color_frame</child>
      <axis>
        <dynamics>
          <spring_reference>0</spring_reference>
          <spring_stiffness>0</spring_stiffness>
        </dynamics>
        <xyz>0 0 1</xyz>
        <limit>
          <lower>-10000000000000000</lower>
          <upper>10000000000000000</upper>
        </limit>
      </axis>
      <physics>
        <ode>
          <limit>
            <cfm>0</cfm>
            <erp>0.20000000000000001</erp>
          </limit>
        </ode>
      </physics>
    </joint>
    <link name='camera_color_frame'>
      <pose relative_to='camera_color_joint'>0 0 0 0 0 0</pose>
      <inertial>
        <pose>0 0 0 0 0 0</pose>
        <mass>0.12266000000000001</mass>
        <inertia>
          <ixx>0.017764499999999999</ixx>
          <ixy>0</ixy>
          <ixz>0</ixz>
          <iyy>0.011722916999999999</iyy>
          <iyz>0</iyz>
          <izz>0.022277168</izz>
        </inertia>
      </inertial>
      <collision name='camera_color_frame_collision'>
        <pose>0 0 0 0 0 0</pose>
        <geometry>
          <box>
            <size>0.001 0.001 0.001</size>
          </box>
        </geometry>
      </collision>
      <visual name='camera_color_frame_visual'>
        <pose>0 0 0 0 0 0</pose>
        <geometry>
          <box>
            <size>0.001 0.001 0.001</size>
          </box>
        </geometry>
        <material>
          <diffuse>0 1 1 1</diffuse>
          <ambient>0 1 1 1</ambient>
        </material>
      </visual>
    </link>
    <joint name='camera_color_optical_joint' type='fixed'>
      <pose relative_to='camera_color_frame'>0 0 0 -1.57 -5.551115123125783e-17 -1.57</pose>
      <parent>camera_color_frame</parent>
      <child>camera_color_optical_frame</child>
      <axis>
        <dynamics>
          <spring_reference>0</spring_reference>
          <spring_stiffness>0</spring_stiffness>
        </dynamics>
        <xyz>0 0 1</xyz>
        <limit>
          <lower>-10000000000000000</lower>
          <upper>10000000000000000</upper>
        </limit>
      </axis>
      <physics>
        <ode>
          <limit>
            <cfm>0</cfm>
            <erp>0.20000000000000001</erp>
          </limit>
        </ode>
      </physics>
    </joint>
    <link name='camera_color_optical_frame'>
      <pose relative_to='camera_color_optical_joint'>0 0 0 0 0 0</pose>
      <inertial>
        <pose>0 0 0 0 0 0</pose>
        <mass>0.12266000000000001</mass>
        <inertia>
          <ixx>0.017764499999999999</ixx>
          <ixy>0</ixy>
          <ixz>0</ixz>
          <iyy>0.011722916999999999</iyy>
          <iyz>0</iyz>
          <izz>0.022277168</izz>
        </inertia>
      </inertial>
      <collision name='camera_color_optical_frame_collision'>
        <pose>0 0 0 0 0 0</pose>
        <geometry>
          <box>
            <size>0.001 0.001 0.001</size>
          </box>
        </geometry>
      </collision>
      <visual name='camera_color_optical_frame_visual'>
        <pose>0 0 0 0 0 0</pose>
        <geometry>
          <box>
            <size>0.001 0.001 0.001</size>
          </box>
        </geometry>
        <material>
          <diffuse>0 1 1 1</diffuse>
          <ambient>0 1 1 1</ambient>
        </material>
      </visual>
    </link>
    <joint name='camera_depth_joint' type='fixed'>
      <pose relative_to='camera_link'>0 0 0.01 0 0 0</pose>
      <parent>camera_link</parent>
      <child>camera_depth_frame</child>
      <axis>
        <dynamics>
          <spring_reference>0</spring_reference>
          <spring_stiffness>0</spring_stiffness>
        </dynamics>
        <xyz>0 0 1</xyz>
        <limit>
          <lower>-10000000000000000</lower>
          <upper>10000000000000000</upper>
        </limit>
      </axis>
      <physics>
        <ode>
          <limit>
            <cfm>0</cfm>
            <erp>0.20000000000000001</erp>
          </limit>
        </ode>
      </physics>
    </joint>
    <link name='camera_depth_frame'>
      <pose relative_to='camera_depth_joint'>0 0 0 0 0 0</pose>
      <inertial>
        <pose>0 0 0 0 0 0</pose>
        <mass>0.12266000000000001</mass>
        <inertia>
          <ixx>0.017764499999999999</ixx>
          <ixy>0</ixy>
          <ixz>0</ixz>
          <iyy>0.011722916999999999</iyy>
          <iyz>0</iyz>
          <izz>0.022277168</izz>
        </inertia>
      </inertial>
      <collision name='camera_depth_frame_collision'>
        <pose>0 0 0 0 0 0</pose>
        <geometry>
          <box>
            <size>0.001 0.001 0.001</size>
          </box>
        </geometry>
      </collision>
      <visual name='camera_depth_frame_visual'>
        <pose>0 0 0 0 0 0</pose>
        <geometry>
          <box>
            <size>0.001 0.001 0.001</size>
          </box>
        </geometry>
        <material>
          <diffuse>0 1 1 1</diffuse>
          <ambient>0 1 1 1</ambient>
        </material>
      </visual>
    </link>
    <joint name='camera_depth_optical_joint' type='fixed'>
      <pose relative_to='camera_depth_frame'>0 0 0 -1.57 -5.551115123125783e-17 -1.57</pose>
      <parent>camera_depth_frame</parent>
      <child>camera_depth_optical_frame</child>
      <axis>
        <dynamics>
          <spring_reference>0</spring_reference>
          <spring_stiffness>0</spring_stiffness>
        </dynamics>
        <xyz>0 0 1</xyz>
        <limit>
          <lower>-10000000000000000</lower>
          <upper>10000000000000000</upper>
        </limit>
      </axis>
      <physics>
        <ode>
          <limit>
            <cfm>0</cfm>
            <erp>0.20000000000000001</erp>
          </limit>
        </ode>
      </physics>
    </joint>
    <link name='camera_depth_optical_frame'>
      <pose relative_to='camera_depth_optical_joint'>0 0 0 0 0 0</pose>
      <inertial>
        <pose>0 0 0 0 0 0</pose>
        <mass>0.12266000000000001</mass>
        <inertia>
          <ixx>0.017764499999999999</ixx>
          <ixy>0</ixy>
          <ixz>0</ixz>
          <iyy>0.011722916999999999</iyy>
          <iyz>0</iyz>
          <izz>0.022277168</izz>
        </inertia>
      </inertial>
      <collision name='camera_depth_optical_frame_collision'>
        <pose>0 0 0 0 0 0</pose>
        <geometry>
          <box>
            <size>0.001 0.001 0.001</size>
          </box>
        </geometry>
      </collision>
      <visual name='camera_depth_optical_frame_visual'>
        <pose>0 0 0 0 0 0</pose>
        <geometry>
          <box>
            <size>0.001 0.001 0.001</size>
          </box>
        </geometry>
        <material>
          <diffuse>0 1 1 1</diffuse>
          <ambient>0 1 1 1</ambient>
        </material>
      </visual>
    </link>
    <joint name='camera_left_ir_joint' type='fixed'>
      <pose relative_to='camera_depth_frame'>0 0 0 0 0 0</pose>
      <parent>camera_depth_frame</parent>
      <child>camera_left_ir_frame</child>
      <axis>
        <dynamics>
          <spring_reference>0</spring_reference>
          <spring_stiffness>0</spring_stiffness>
        </dynamics>
        <xyz>0 0 1</xyz>
        <limit>
          <lower>-10000000000000000</lower>
          <upper>10000000000000000</upper>
        </limit>
      </axis>
      <physics>
        <ode>
          <limit>
            <cfm>0</cfm>
            <erp>0.20000000000000001</erp>
          </limit>
        </ode>
      </physics>
    </joint>
    <link name='camera_left_ir_frame'>
      <pose relative_to='camera_left_ir_joint'>0 0 0 0 0 0</pose>
      <inertial>
        <pose>0 0 0 0 0 0</pose>
        <mass>0.12266000000000001</mass>
        <inertia>
          <ixx>0.017764499999999999</ixx>
          <ixy>0</ixy>
          <ixz>0</ixz>
          <iyy>0.011722916999999999</iyy>
          <iyz>0</iyz>
          <izz>0.022277168</izz>
        </inertia>
      </inertial>
      <collision name='camera_left_ir_frame_collision'>
        <pose>0 0 0 0 0 0</pose>
        <geometry>
          <box>
            <size>0.001 0.001 0.001</size>
          </box>
        </geometry>
      </collision>
      <visual name='camera_left_ir_frame_visual'>
        <pose>0 0 0 0 0 0</pose>
        <geometry>
          <box>
            <size>0.001 0.001 0.001</size>
          </box>
        </geometry>
        <material>
          <diffuse>0 1 1 1</diffuse>
          <ambient>0 1 1 1</ambient>
        </material>
      </visual>
    </link>
    <joint name='camera_left_ir_optical_joint' type='fixed'>
      <pose relative_to='camera_left_ir_frame'>0 0 0 -1.57 -5.551115123125783e-17 -1.57</pose>
      <parent>camera_left_ir_frame</parent>
      <child>camera_left_ir_optical_frame</child>
      <axis>
        <dynamics>
          <spring_reference>0</spring_reference>
          <spring_stiffness>0</spring_stiffness>
        </dynamics>
        <xyz>0 0 1</xyz>
        <limit>
          <lower>-10000000000000000</lower>
          <upper>10000000000000000</upper>
        </limit>
      </axis>
      <physics>
        <ode>
          <limit>
            <cfm>0</cfm>
            <erp>0.20000000000000001</erp>
          </limit>
        </ode>
      </physics>
    </joint>
    <link name='camera_left_ir_optical_frame'>
      <pose relative_to='camera_left_ir_optical_joint'>0 0 0 0 0 0</pose>
      <inertial>
        <pose>0 0 0 0 0 0</pose>
        <mass>0.12266000000000001</mass>
        <inertia>
          <ixx>0.017764499999999999</ixx>
          <ixy>0</ixy>
          <ixz>0</ixz>
          <iyy>0.011722916999999999</iyy>
          <iyz>0</iyz>
          <izz>0.022277168</izz>
        </inertia>
      </inertial>
      <collision name='camera_left_ir_optical_frame_collision'>
        <pose>0 0 0 0 0 0</pose>
        <geometry>
          <box>
            <size>0.001 0.001 0.001</size>
          </box>
        </geometry>
      </collision>
      <visual name='camera_left_ir_optical_frame_visual'>
        <pose>0 0 0 0 0 0</pose>
        <geometry>
          <box>
            <size>0.001 0.001 0.001</size>
          </box>
        </geometry>
        <material>
          <diffuse>0 1 1 1</diffuse>
          <ambient>0 1 1 1</ambient>
        </material>
      </visual>
    </link>
    <joint name='camera_right_ir_joint' type='fixed'>
      <pose relative_to='camera_depth_frame'>0 -0.05 0 0 0 0</pose>
      <parent>camera_depth_frame</parent>
      <child>camera_right_ir_frame</child>
      <axis>
        <dynamics>
          <spring_reference>0</spring_reference>
          <spring_stiffness>0</spring_stiffness>
        </dynamics>
        <xyz>0 0 1</xyz>
        <limit>
          <lower>-10000000000000000</lower>
          <upper>10000000000000000</upper>
        </limit>
      </axis>
      <physics>
        <ode>
          <limit>
            <cfm>0</cfm>
            <erp>0.20000000000000001</erp>
          </limit>
        </ode>
      </physics>
    </joint>
    <link name='camera_right_ir_frame'>
      <pose relative_to='camera_right_ir_joint'>0 0 0 0 0 0</pose>
      <inertial>
        <pose>0 0 0 0 0 0</pose>
        <mass>0.12266000000000001</mass>
        <inertia>
          <ixx>0.017764499999999999</ixx>
          <ixy>0</ixy>
          <ixz>0</ixz>
          <iyy>0.011722916999999999</iyy>
          <iyz>0</iyz>
          <izz>0.022277168</izz>
        </inertia>
      </inertial>
      <collision name='camera_right_ir_frame_collision'>
        <pose>0 0 0 0 0 0</pose>
        <geometry>
          <box>
            <size>0.001 0.001 0.001</size>
          </box>
        </geometry>
      </collision>
      <visual name='camera_right_ir_frame_visual'>
        <pose>0 0 0 0 0 0</pose>
        <geometry>
          <box>
            <size>0.001 0.001 0.001</size>
          </box>
        </geometry>
        <material>
          <diffuse>0 1 1 1</diffuse>
          <ambient>0 1 1 1</ambient>
        </material>
      </visual>
    </link>
    <joint name='camera_right_ir_optical_joint' type='fixed'>
      <pose relative_to='camera_right_ir_frame'>0 0 0 -1.57 -5.551115123125783e-17 -1.57</pose>
      <parent>camera_right_ir_frame</parent>
      <child>camera_right_ir_optical_frame</child>
      <axis>
        <dynamics>
          <spring_reference>0</spring_reference>
          <spring_stiffness>0</spring_stiffness>
        </dynamics>
        <xyz>0 0 1</xyz>
        <limit>
          <lower>-10000000000000000</lower>
          <upper>10000000000000000</upper>
        </limit>
      </axis>
      <physics>
        <ode>
          <limit>
            <cfm>0</cfm>
            <erp>0.20000000000000001</erp>
          </limit>
        </ode>
      </physics>
    </joint>
    <link name='camera_right_ir_optical_frame'>
      <pose relative_to='camera_right_ir_optical_joint'>0 0 0 0 0 0</pose>
      <inertial>
        <pose>0 0 0 0 0 0</pose>
        <mass>0.12266000000000001</mass>
        <inertia>
          <ixx>0.017764499999999999</ixx>
          <ixy>0</ixy>
          <ixz>0</ixz>
          <iyy>0.011722916999999999</iyy>
          <iyz>0</iyz>
          <izz>0.022277168</izz>
        </inertia>
      </inertial>
      <collision name='camera_right_ir_optical_frame_collision'>
        <pose>0 0 0 0 0 0</pose>
        <geometry>
          <box>
            <size>0.001 0.001 0.001</size>
          </box>
        </geometry>
      </collision>
      <visual name='camera_right_ir_optical_frame_visual'>
        <pose>0 0 0 0 0 0</pose>
        <geometry>
          <box>
            <size>0.001 0.001 0.001</size>
          </box>
        </geometry>
        <material>
          <diffuse>0 1 1 1</diffuse>
          <ambient>0 1 1 1</ambient>
        </material>
      </visual>
    </link>
    <joint name='gps_sensor_link_joint' type='fixed'>
      <pose relative_to='center_link'>0 0 0.302244 0 0 0</pose>
      <parent>center_link</parent>
      <child>gps_sensor_link</child>
      <axis>
        <dynamics>
          <spring_reference>0</spring_reference>
          <spring_stiffness>0</spring_stiffness>
        </dynamics>
        <xyz>0 0 1</xyz>
        <limit>
          <lower>-10000000000000000</lower>
          <upper>10000000000000000</upper>
        </limit>
      </axis>
      <physics>
        <ode>
          <limit>
            <cfm>0</cfm>
            <erp>0.20000000000000001</erp>
          </limit>
        </ode>
      </physics>
    </joint>
    <link name='gps_sensor_link'>
      <pose relative_to='gps_sensor_link_joint'>0 0 0 0 0 0</pose>
      <inertial>
        <pose>0 0 0 0 0 0</pose>
        <mass>0.12266000000000001</mass>
        <inertia>
          <ixx>0.017764499999999999</ixx>
          <ixy>0</ixy>
          <ixz>0</ixz>
          <iyy>0.011722916999999999</iyy>
          <iyz>0</iyz>
          <izz>0.022277168</izz>
        </inertia>
      </inertial>
      <collision name='gps_sensor_link_collision'>
        <pose>0 0 0 0 0 0</pose>
        <geometry>
          <box>
            <size>0.001 0.001 0.001</size>
          </box>
        </geometry>
      </collision>
      <visual name='gps_sensor_link_visual'>
        <pose>0 0 0 0 0 0</pose>
        <geometry>
          <box>
            <size>0.001 0.001 0.001</size>
          </box>
        </geometry>
        <material>
          <diffuse>0 1 1 1</diffuse>
          <ambient>0 1 1 1</ambient>
        </material>
      </visual>
    </link>
    <joint name='imu_sensor_link_joint' type='fixed'>
      <pose relative_to='center_link'>0 0 0.302244 0 0 0</pose>
      <parent>center_link</parent>
      <child>imu_sensor_link</child>
      <axis>
        <dynamics>
          <spring_reference>0</spring_reference>
          <spring_stiffness>0</spring_stiffness>
        </dynamics>
        <xyz>0 0 1</xyz>
        <limit>
          <lower>-10000000000000000</lower>
          <upper>10000000000000000</upper>
        </limit>
      </axis>
      <physics>
        <ode>
          <limit>
            <cfm>0</cfm>
            <erp>0.20000000000000001</erp>
          </limit>
        </ode>
      </physics>
    </joint>
    <link name='imu_sensor_link'>
      <pose relative_to='imu_sensor_link_joint'>0 0 0 0 0 0</pose>
      <inertial>
        <pose>0 0 0 0 0 0</pose>
        <mass>0.12266000000000001</mass>
        <inertia>
          <ixx>0.017764499999999999</ixx>
          <ixy>0</ixy>
          <ixz>0</ixz>
          <iyy>0.011722916999999999</iyy>
          <iyz>0</iyz>
          <izz>0.022277168</izz>
        </inertia>
      </inertial>
      <collision name='imu_sensor_link_collision'>
        <pose>0 0 0 0 0 0</pose>
        <geometry>
          <box>
            <size>0.001 0.001 0.001</size>
          </box>
        </geometry>
      </collision>
      <visual name='imu_sensor_link_visual'>
        <pose>0 0 0 0 0 0</pose>
        <geometry>
          <box>
            <size>0.001 0.001 0.001</size>
          </box>
        </geometry>
        <material>
          <diffuse>0 1 1 1</diffuse>
          <ambient>0 1 1 1</ambient>
        </material>
      </visual>
    </link>
    <joint name='drive_wheel_front_left_joint' type='revolute'>
      <pose relative_to='base_link'>0.18337 0.258475 0.1016 0 0 0</pose>
      <parent>base_link</parent>
      <child>drive_wheel_front_left_link</child>
      <axis>
        <xyz>0 1 0</xyz>
        <limit>
          <lower>-10000000000000000</lower>
          <upper>10000000000000000</upper>
        </limit>
        <dynamics>
          <spring_reference>0</spring_reference>
          <spring_stiffness>0</spring_stiffness>
        </dynamics>
      </axis>
    </joint>
    <link name='drive_wheel_front_left_link'>
      <pose relative_to='drive_wheel_front_left_joint'>0 0 0 0 0 0</pose>
      <inertial>
        <pose>0 0 0 0 0 0</pose>
        <mass>1</mass>
        <inertia>
          <ixx>0.0062805624999999997</ixx>
          <ixy>0</ixy>
          <ixz>0</ixz>
          <iyy>0.0062805624999999997</iyy>
          <iyz>0</iyz>
          <izz>0.0062805624999999997</izz>
        </inertia>
      </inertial>
      <collision name='drive_wheel_front_left_link_collision'>
        <pose>0 0 0 1.570796326794896 0 0</pose>
        <geometry>
          <cylinder>
            <length>0.10795</length>
            <radius>0.1016</radius>
          </cylinder>
        </geometry>
        <surface>
          <contact>
            <ode>
              <kp>1000000</kp>
              <kd>100</kd>
              <max_vel>1</max_vel>
              <min_depth>0.01</min_depth>
            </ode>
          </contact>
          <friction>
            <ode>
              <mu>1</mu>
              <mu2>1</mu2>
            </ode>
          </friction>
        </surface>
      </collision>
      <visual name='drive_wheel_front_left_link_visual'>
        <pose>0 0 0 1.570796326794896 0 0</pose>
        <geometry>
          <cylinder>
            <length>0.10795</length>
            <radius>0.1016</radius>
          </cylinder>
        </geometry>
        <material>
          <diffuse>0.625 0.625 0.625 1</diffuse>
          <ambient>0.625 0.625 0.625 1</ambient>
        </material>
      </visual>
      <slip1>0.5</slip1>
      <slip2>0</slip2>
    </link>
    <joint name='drive_wheel_front_right_joint' type='revolute'>
      <pose relative_to='base_link'>0.18337 -0.258475 0.1016 0 0 0</pose>
      <parent>base_link</parent>
      <child>drive_wheel_front_right_link</child>
      <axis>
        <xyz>0 1 0</xyz>
        <limit>
          <lower>-10000000000000000</lower>
          <upper>10000000000000000</upper>
        </limit>
        <dynamics>
          <spring_reference>0</spring_reference>
          <spring_stiffness>0</spring_stiffness>
        </dynamics>
      </axis>
    </joint>
    <link name='drive_wheel_front_right_link'>
      <pose relative_to='drive_wheel_front_right_joint'>0 0 0 0 0 0</pose>
      <inertial>
        <pose>0 0 0 0 0 0</pose>
        <mass>1</mass>
        <inertia>
          <ixx>0.0062805624999999997</ixx>
          <ixy>0</ixy>
          <ixz>0</ixz>
          <iyy>0.0062805624999999997</iyy>
          <iyz>0</iyz>
          <izz>0.0062805624999999997</izz>
        </inertia>
      </inertial>
      <collision name='drive_wheel_front_right_link_collision'>
        <pose>0 0 0 1.570796326794896 0 0</pose>
        <geometry>
          <cylinder>
            <length>0.10795</length>
            <radius>0.1016</radius>
          </cylinder>
        </geometry>
        <surface>
          <contact>
            <ode>
              <kp>1000000</kp>
              <kd>100</kd>
              <max_vel>1</max_vel>
              <min_depth>0.01</min_depth>
            </ode>
          </contact>
          <friction>
            <ode>
              <mu>1</mu>
              <mu2>1</mu2>
            </ode>
          </friction>
        </surface>
      </collision>
      <visual name='drive_wheel_front_right_link_visual'>
        <pose>0 0 0 1.570796326794896 0 0</pose>
        <geometry>
          <cylinder>
            <length>0.10795</length>
            <radius>0.1016</radius>
          </cylinder>
        </geometry>
        <material>
          <diffuse>0.625 0.625 0.625 1</diffuse>
          <ambient>0.625 0.625 0.625 1</ambient>
        </material>
      </visual>
      <slip1>0.5</slip1>
      <slip2>0</slip2>
    </link>
    <joint name='drive_wheel_rear_left_joint' type='revolute'>
      <pose relative_to='base_link'>-0.18337 0.258475 0.1016 0 0 0</pose>
      <parent>base_link</parent>
      <child>drive_wheel_rear_left_link</child>
      <axis>
        <xyz>0 1 0</xyz>
        <limit>
          <lower>-10000000000000000</lower>
          <upper>10000000000000000</upper>
        </limit>
        <dynamics>
          <spring_reference>0</spring_reference>
          <spring_stiffness>0</spring_stiffness>
        </dynamics>
      </axis>
    </joint>
    <link name='drive_wheel_rear_left_link'>
      <pose relative_to='drive_wheel_rear_left_joint'>0 0 0 0 0 0</pose>
      <inertial>
        <pose>0 0 0 0 0 0</pose>
        <mass>1</mass>
        <inertia>
          <ixx>0.0062805624999999997</ixx>
          <ixy>0</ixy>
          <ixz>0</ixz>
          <iyy>0.0062805624999999997</iyy>
          <iyz>0</iyz>
          <izz>0.0062805624999999997</izz>
        </inertia>
      </inertial>
      <collision name='drive_wheel_rear_left_link_collision'>
        <pose>0 0 0 1.570796326794896 0 0</pose>
        <geometry>
          <cylinder>
            <length>0.10795</length>
            <radius>0.1016</radius>
          </cylinder>
        </geometry>
        <surface>
          <contact>
            <ode>
              <kp>1000000</kp>
              <kd>100</kd>
              <max_vel>1</max_vel>
              <min_depth>0.01</min_depth>
            </ode>
          </contact>
          <friction>
            <ode>
              <mu>1</mu>
              <mu2>1</mu2>
            </ode>
          </friction>
        </surface>
      </collision>
      <visual name='drive_wheel_rear_left_link_visual'>
        <pose>0 0 0 1.570796326794896 0 0</pose>
        <geometry>
          <cylinder>
            <length>0.10795</length>
            <radius>0.1016</radius>
          </cylinder>
        </geometry>
        <material>
          <diffuse>0.625 0.625 0.625 1</diffuse>
          <ambient>0.625 0.625 0.625 1</ambient>
        </material>
      </visual>
      <slip1>0.5</slip1>
      <slip2>0</slip2>
    </link>
    <joint name='drive_wheel_rear_right_joint' type='revolute'>
      <pose relative_to='base_link'>-0.18337 -0.258475 0.1016 0 0 0</pose>
      <parent>base_link</parent>
      <child>drive_wheel_rear_right_link</child>
      <axis>
        <xyz>0 1 0</xyz>
        <limit>
          <lower>-10000000000000000</lower>
          <upper>10000000000000000</upper>
        </limit>
        <dynamics>
          <spring_reference>0</spring_reference>
          <spring_stiffness>0</spring_stiffness>
        </dynamics>
      </axis>
    </joint>
    <link name='drive_wheel_rear_right_link'>
      <pose relative_to='drive_wheel_rear_right_joint'>0 0 0 0 0 0</pose>
      <inertial>
        <pose>0 0 0 0 0 0</pose>
        <mass>1</mass>
        <inertia>
          <ixx>0.0062805624999999997</ixx>
          <ixy>0</ixy>
          <ixz>0</ixz>
          <iyy>0.0062805624999999997</iyy>
          <iyz>0</iyz>
          <izz>0.0062805624999999997</izz>
        </inertia>
      </inertial>
      <collision name='drive_wheel_rear_right_link_collision'>
        <pose>0 0 0 1.570796326794896 0 0</pose>
        <geometry>
          <cylinder>
            <length>0.10795</length>
            <radius>0.1016</radius>
          </cylinder>
        </geometry>
        <surface>
          <contact>
            <ode>
              <kp>1000000</kp>
              <kd>100</kd>
              <max_vel>1</max_vel>
              <min_depth>0.01</min_depth>
            </ode>
          </contact>
          <friction>
            <ode>
              <mu>1</mu>
              <mu2>1</mu2>
            </ode>
          </friction>
        </surface>
      </collision>
      <visual name='drive_wheel_rear_right_link_visual'>
        <pose>0 0 0 1.570796326794896 0 0</pose>
        <geometry>
          <cylinder>
            <length>0.10795</length>
            <radius>0.1016</radius>
          </cylinder>
        </geometry>
        <material>
          <diffuse>0.625 0.625 0.625 1</diffuse>
          <ambient>0.625 0.625 0.625 1</ambient>
        </material>
      </visual>
      <slip1>0.5</slip1>
      <slip2>0</slip2>
    </link>
  </model>
</sdf>
