<sdf version='1.7'>
  <model name='ardak'>
    <link name='base_link'>
      <inertial>
        <pose>0 0 0 0 -0 0</pose>
        <mass>1</mass>
        <inertia>
          <ixx>0.1</ixx>
          <ixy>0</ixy>
          <ixz>0</ixz>
          <iyy>1</iyy>
          <iyz>0</iyz>
          <izz>0.1</izz>
        </inertia>
      </inertial>
      <collision name='base_link_collision'>
        <pose>0 0 0 0 -0 0</pose>
        <geometry>
          <box>
            <size>0.7112 0.35 0.302244</size>
          </box>
        </geometry>
        <surface>
          <contact>
            <ode/>
          </contact>
          <friction>
            <ode/>
          </friction>
        </surface>
      </collision>
      <visual name='base_link_visual'>
        <pose>0 0 0 0 -0 0</pose>
        <geometry>
          <box>
            <size>0.7112 0.35 0.302244</size>
          </box>
        </geometry>
        <material>
          <script>
            <name>Gazebo/White</name>
            <uri>file://media/materials/scripts/gazebo.material</uri>
          </script>
        </material>
      </visual>
    </link>
    <joint name='drive_wheel_front_left_joint' type='revolute'>
      <pose relative_to='base_link'>0.26397 0.258475 -0.10633 0 -0 0</pose>
      <parent>base_link</parent>
      <child>drive_wheel_front_left_link</child>
      <axis>
        <xyz>0 1 0</xyz>
        <limit>
          <lower>-1e+16</lower>
          <upper>1e+16</upper>
        </limit>
        <dynamics>
          <spring_reference>0</spring_reference>
          <spring_stiffness>0</spring_stiffness>
        </dynamics>
      </axis>
    </joint>
    <link name='drive_wheel_front_left_link'>
      <pose relative_to='drive_wheel_front_left_joint'>0 0 0 0 -0 0</pose>
      <inertial>
        <pose>0 0 0 0 -0 0</pose>
        <mass>1</mass>
        <inertia>
          <ixx>0.1</ixx>
          <ixy>0</ixy>
          <ixz>0</ixz>
          <iyy>1</iyy>
          <iyz>0</iyz>
          <izz>0.1</izz>
        </inertia>
      </inertial>
      <collision name='drive_wheel_front_left_link_collision'>
        <pose>0 0 0 1.5708 -0 0</pose>
        <geometry>
          <cylinder>
            <length>0.10795</length>
            <radius>0.1016</radius>
          </cylinder>
        </geometry>
      </collision>
      <visual name='drive_wheel_front_left_link_visual'>
        <pose>0 0 0 1.5708 -0 0</pose>
        <geometry>
          <cylinder>
            <length>0.10795</length>
            <radius>0.1016</radius>
          </cylinder>
        </geometry>
      </visual>
    </link>
    <joint name='drive_wheel_front_right_joint' type='revolute'>
      <pose relative_to='base_link'>0.26397 -0.258475 -0.10633 0 -0 0</pose>
      <parent>base_link</parent>
      <child>drive_wheel_front_right_link</child>
      <axis>
        <xyz>0 1 0</xyz>
        <limit>
          <lower>-1e+16</lower>
          <upper>1e+16</upper>
        </limit>
        <dynamics>
          <spring_reference>0</spring_reference>
          <spring_stiffness>0</spring_stiffness>
        </dynamics>
      </axis>
    </joint>
    <link name='drive_wheel_front_right_link'>
      <pose relative_to='drive_wheel_front_right_joint'>0 0 0 0 -0 0</pose>
      <inertial>
        <pose>0 0 0 0 -0 0</pose>
        <mass>1</mass>
        <inertia>
          <ixx>0.1</ixx>
          <ixy>0</ixy>
          <ixz>0</ixz>
          <iyy>1</iyy>
          <iyz>0</iyz>
          <izz>0.1</izz>
        </inertia>
      </inertial>
      <collision name='drive_wheel_front_right_link_collision'>
        <pose>0 0 0 1.5708 -0 0</pose>
        <geometry>
          <cylinder>
            <length>0.10795</length>
            <radius>0.1016</radius>
          </cylinder>
        </geometry>
      </collision>
      <visual name='drive_wheel_front_right_link_visual'>
        <pose>0 0 0 1.5708 -0 0</pose>
        <geometry>
          <cylinder>
            <length>0.10795</length>
            <radius>0.1016</radius>
          </cylinder>
        </geometry>
      </visual>
    </link>
    <joint name='drive_wheel_rear_left_joint' type='revolute'>
      <pose relative_to='base_link'>-0.26397 0.258475 -0.10633 0 -0 0</pose>
      <parent>base_link</parent>
      <child>drive_wheel_rear_left_link</child>
      <axis>
        <xyz>0 1 0</xyz>
        <limit>
          <lower>-1e+16</lower>
          <upper>1e+16</upper>
        </limit>
        <dynamics>
          <spring_reference>0</spring_reference>
          <spring_stiffness>0</spring_stiffness>
        </dynamics>
      </axis>
    </joint>
    <link name='drive_wheel_rear_left_link'>
      <pose relative_to='drive_wheel_rear_left_joint'>0 0 0 0 -0 0</pose>
      <inertial>
        <pose>0 0 0 0 -0 0</pose>
        <mass>1</mass>
        <inertia>
          <ixx>0.1</ixx>
          <ixy>0</ixy>
          <ixz>0</ixz>
          <iyy>1</iyy>
          <iyz>0</iyz>
          <izz>0.1</izz>
        </inertia>
      </inertial>
      <collision name='drive_wheel_rear_left_link_collision'>
        <pose>0 0 0 1.5708 -0 0</pose>
        <geometry>
          <cylinder>
            <length>0.10795</length>
            <radius>0.1016</radius>
          </cylinder>
        </geometry>
      </collision>
      <visual name='drive_wheel_rear_left_link_visual'>
        <pose>0 0 0 1.5708 -0 0</pose>
        <geometry>
          <cylinder>
            <length>0.10795</length>
            <radius>0.1016</radius>
          </cylinder>
        </geometry>
      </visual>
    </link>
    <joint name='drive_wheel_rear_right_joint' type='revolute'>
      <pose relative_to='base_link'>-0.26397 -0.258475 -0.10633 0 -0 0</pose>
      <parent>base_link</parent>
      <child>drive_wheel_rear_right_link</child>
      <axis>
        <xyz>0 1 0</xyz>
        <limit>
          <lower>-1e+16</lower>
          <upper>1e+16</upper>
        </limit>
        <dynamics>
          <spring_reference>0</spring_reference>
          <spring_stiffness>0</spring_stiffness>
        </dynamics>
      </axis>
    </joint>
    <link name='drive_wheel_rear_right_link'>
      <pose relative_to='drive_wheel_rear_right_joint'>0 0 0 0 -0 0</pose>
      <inertial>
        <pose>0 0 0 0 -0 0</pose>
        <mass>1</mass>
        <inertia>
          <ixx>0.1</ixx>
          <ixy>0</ixy>
          <ixz>0</ixz>
          <iyy>1</iyy>
          <iyz>0</iyz>
          <izz>0.1</izz>
        </inertia>
      </inertial>
      <collision name='drive_wheel_rear_right_link_collision'>
        <pose>0 0 0 1.5708 -0 0</pose>
        <geometry>
          <cylinder>
            <length>0.10795</length>
            <radius>0.1016</radius>
          </cylinder>
        </geometry>
      </collision>
      <visual name='drive_wheel_rear_right_link_visual'>
        <pose>0 0 0 1.5708 -0 0</pose>
        <geometry>
          <cylinder>
            <length>0.10795</length>
            <radius>0.1016</radius>
          </cylinder>
        </geometry>
      </visual>
    </link>
    <frame name='base_joint' attached_to='base_link'>
      <pose>0 0 -0.20793 0 -0 0</pose>
    </frame>
    <frame name='base_footprint' attached_to='base_joint'/>
    <frame name='base_to_camera_joint' attached_to='base_link'>
      <pose>0.321769 0 0.022078 0 -0 0</pose>
    </frame>
    <frame name='camera_link' attached_to='base_to_camera_joint'/>
  </model>
</sdf>
