<?xml version="1.0" ?>
<!-- =================================================================================== -->
<!-- |    This document was autogenerated by xacro from src/ardak/description/ardak/ardak.urdf | -->
<!-- |    EDITING THIS FILE BY HAND IS NOT RECOMMENDED                                 | -->
<!-- =================================================================================== -->
<robot name="ardak">
  <link name="base_link">
    <visual>
      <geometry>
        <box size="0.7112 0.35 0.302244"/>
      </geometry>
      <material name="Cyan">
        <color rgba="0 1.0 1.0 1.0"/>
      </material>
    </visual>
    <collision>
      <origin rpy="0 0 0" xyz="0 0 0"/>
      <geometry>
        <box size="0.7112 0.35 0.302244"/>
      </geometry>
    </collision>
    <inertial>
      <mass value="18.14"/>
      <inertia ixx="2.664688434" ixy="0.0" ixz="0.0" iyy="1.758437644" iyz="0.0" izz="3.341575268"/>
    </inertial>
  </link>
  <gazebo reference="base_link">
    <material>Gazebo/White</material>
  </gazebo>
  <gazebo>
    <plugin filename="libgazebo_ros_diff_drive.so" name="skid_steer_drive">
      <update_rate>100.0</update_rate>
      <num_wheel_pairs>2</num_wheel_pairs>
      <left_joint>drive_wheel_front_left_joint</left_joint>
      <right_joint>drive_wheel_front_right_joint</right_joint>
      <left_joint>drive_wheel_rear_left_joint</left_joint>
      <right_joint>drive_wheel_rear_right_joint</right_joint>
      <wheel_separation>0.43347499999999994</wheel_separation>
      <wheel_separation>0.43347499999999994</wheel_separation>
      <wheel_diameter>0.2032</wheel_diameter>
      <wheel_diameter>0.2032</wheel_diameter>
      <!-- limits -->
      <max_wheel_torque>10</max_wheel_torque>
      <max_wheel_acceleration>1.0</max_wheel_acceleration>
      <torque>40</torque>
      <ros>
        <namespace>/</namespace>
        <remapping>cmd_vel:=wheel_cmd</remapping>
      </ros>
      <publish_odom>true</publish_odom>
      <publish_odom_tf>true</publish_odom_tf>
      <publish_wheel_tf>false</publish_wheel_tf>
      <robot_base_frame>base_link</robot_base_frame>
    </plugin>
  </gazebo>
  <link name="base_footprint"/>
  <joint name="base_joint" type="fixed">
    <parent link="base_link"/>
    <child link="base_footprint"/>
    <origin rpy="0 0 0" xyz="0.0 0.0 -0.20793"/>
  </joint>
  <link name="camera_link">
    <parent link="base_to_camera_joint"/>
  </link>
  <link name="drive_wheel_rear_left_link">
    <visual>
      <origin rpy="1.5707963267948966 0 0" xyz="0 0 0"/>
      <geometry>
        <cylinder length="0.10795" radius="0.1016"/>
      </geometry>
      <material name="Gray">
        <color rgba="0.5 0.5 0.5 1.0"/>
      </material>
    </visual>
    <collision>
      <origin rpy="1.5707963267948966 0 0" xyz="0 0 0"/>
      <geometry>
        <cylinder length="0.10795" radius="0.1016"/>
      </geometry>
    </collision>
    <inertial>
      <mass value="1"/>
      <inertia ixx="0.00354044791667" ixy="0" ixz="0" iyy="0.0062805625" iyz="0" izz="0.0062805625"/>
    </inertial>
    <axis>
      <xyz> 0 1 0 </xyz>
    </axis>
  </link>
  <joint name="drive_wheel_rear_left_joint" type="continuous">
    <parent link="base_link"/>
    <child link="drive_wheel_rear_left_link"/>
    <origin rpy="0 0 0" xyz="-0.26397000000000004 0.258475 -0.10633000000000001"/>
    <axis xyz="0 1 0"/>
  </joint>
  <gazebo reference="drive_wheel_rear_left_link">
    <kp>1000000.0</kp>
    <kd>100.0</kd>
    <mu>0.8</mu>
    <mu2>0.8</mu2>
    <slip1>0.5</slip1>
    <slip2>0</slip2>
    <minDepth>0.01</minDepth>
    <maxContacts>3</maxContacts>
    <fdir1>1 0 0</fdir1>
  </gazebo>
  <link name="drive_wheel_rear_right_link">
    <visual>
      <origin rpy="1.5707963267948966 0 0" xyz="0 0 0"/>
      <geometry>
        <cylinder length="0.10795" radius="0.1016"/>
      </geometry>
      <material name="Gray">
        <color rgba="0.5 0.5 0.5 1.0"/>
      </material>
    </visual>
    <collision>
      <origin rpy="1.5707963267948966 0 0" xyz="0 0 0"/>
      <geometry>
        <cylinder length="0.10795" radius="0.1016"/>
      </geometry>
    </collision>
    <inertial>
      <mass value="1"/>
      <inertia ixx="0.00354044791667" ixy="0" ixz="0" iyy="0.0062805625" iyz="0" izz="0.0062805625"/>
    </inertial>
    <axis>
      <xyz> 0 1 0 </xyz>
    </axis>
  </link>
  <joint name="drive_wheel_rear_right_joint" type="continuous">
    <parent link="base_link"/>
    <child link="drive_wheel_rear_right_link"/>
    <origin rpy="0 0 0" xyz="-0.26397000000000004 -0.258475 -0.10633000000000001"/>
    <axis xyz="0 1 0"/>
  </joint>
  <gazebo reference="drive_wheel_rear_right_link">
    <kp>1000000.0</kp>
    <kd>100.0</kd>
    <mu>0.8</mu>
    <mu2>0.8</mu2>
    <slip1>0.5</slip1>
    <slip2>0</slip2>
    <minDepth>0.01</minDepth>
    <maxContacts>3</maxContacts>
    <fdir1>1 0 0</fdir1>
  </gazebo>
  <link name="drive_wheel_front_left_link">
    <visual>
      <origin rpy="1.5707963267948966 0 0" xyz="0 0 0"/>
      <geometry>
        <cylinder length="0.10795" radius="0.1016"/>
      </geometry>
      <material name="Gray">
        <color rgba="0.5 0.5 0.5 1.0"/>
      </material>
    </visual>
    <collision>
      <origin rpy="1.5707963267948966 0 0" xyz="0 0 0"/>
      <geometry>
        <cylinder length="0.10795" radius="0.1016"/>
      </geometry>
    </collision>
    <inertial>
      <mass value="1"/>
      <inertia ixx="0.00354044791667" ixy="0" ixz="0" iyy="0.0062805625" iyz="0" izz="0.0062805625"/>
    </inertial>
    <axis>
      <xyz> 0 1 0 </xyz>
    </axis>
  </link>
  <joint name="drive_wheel_front_left_joint" type="continuous">
    <parent link="base_link"/>
    <child link="drive_wheel_front_left_link"/>
    <origin rpy="0 0 0" xyz="0.26397000000000004 0.258475 -0.10633000000000001"/>
    <axis xyz="0 1 0"/>
  </joint>
  <gazebo reference="drive_wheel_front_left_link">
    <kp>1000000.0</kp>
    <kd>100.0</kd>
    <mu>0.8</mu>
    <mu2>0.8</mu2>
    <slip1>0.5</slip1>
    <slip2>0</slip2>
    <minDepth>0.01</minDepth>
    <maxContacts>3</maxContacts>
    <fdir1>1 0 0</fdir1>
  </gazebo>
  <link name="drive_wheel_front_right_link">
    <visual>
      <origin rpy="1.5707963267948966 0 0" xyz="0 0 0"/>
      <geometry>
        <cylinder length="0.10795" radius="0.1016"/>
      </geometry>
      <material name="Gray">
        <color rgba="0.5 0.5 0.5 1.0"/>
      </material>
    </visual>
    <collision>
      <origin rpy="1.5707963267948966 0 0" xyz="0 0 0"/>
      <geometry>
        <cylinder length="0.10795" radius="0.1016"/>
      </geometry>
    </collision>
    <inertial>
      <mass value="1"/>
      <inertia ixx="0.00354044791667" ixy="0" ixz="0" iyy="0.0062805625" iyz="0" izz="0.0062805625"/>
    </inertial>
    <axis>
      <xyz> 0 1 0 </xyz>
    </axis>
  </link>
  <joint name="drive_wheel_front_right_joint" type="continuous">
    <parent link="base_link"/>
    <child link="drive_wheel_front_right_link"/>
    <origin rpy="0 0 0" xyz="0.26397000000000004 -0.258475 -0.10633000000000001"/>
    <axis xyz="0 1 0"/>
  </joint>
  <gazebo reference="drive_wheel_front_right_link">
    <kp>1000000.0</kp>
    <kd>100.0</kd>
    <mu>0.8</mu>
    <mu2>0.8</mu2>
    <slip1>0.5</slip1>
    <slip2>0</slip2>
    <minDepth>0.01</minDepth>
    <maxContacts>3</maxContacts>
    <fdir1>1 0 0</fdir1>
  </gazebo>
  <joint name="base_to_camera_joint" type="fixed">
    <parent link="base_link"/>
    <child link="camera_link"/>
    <origin xyz="0.321769 0.0 0.022078000000000014"/>
  </joint>
</robot>
