<sdf version='1.7'>
  <world name='default'>
    <light name='sun' type='directional'>
      <cast_shadows>1</cast_shadows>
      <pose>0 0 10 0 -0 0</pose>
      <diffuse>0.8 0.8 0.8 1</diffuse>
      <specular>0.2 0.2 0.2 1</specular>
      <attenuation>
        <range>1000</range>
        <constant>0.9</constant>
        <linear>0.01</linear>
        <quadratic>0.001</quadratic>
      </attenuation>
      <direction>-0.5 0.1 -0.9</direction>
      <spot>
        <inner_angle>0</inner_angle>
        <outer_angle>0</outer_angle>
        <falloff>0</falloff>
      </spot>
    </light>
    <model name='ground_plane'>
      <static>1</static>
      <link name='link'>
        <collision name='collision'>
          <geometry>
            <plane>
              <normal>0 0 1</normal>
              <size>100 100</size>
            </plane>
          </geometry>
          <surface>
            <friction>
              <ode>
                <mu>100</mu>
                <mu2>50</mu2>
              </ode>
              <torsional>
                <ode/>
              </torsional>
            </friction>
            <contact>
              <ode/>
            </contact>
            <bounce/>
          </surface>
          <max_contacts>10</max_contacts>
        </collision>
        <visual name='visual'>
          <cast_shadows>0</cast_shadows>
          <geometry>
            <plane>
              <normal>0 0 1</normal>
              <size>100 100</size>
            </plane>
          </geometry>
          <material>
            <script>
              <uri>file://media/materials/scripts/gazebo.material</uri>
              <name>Gazebo/Grey</name>
            </script>
          </material>
        </visual>
        <self_collide>0</self_collide>
        <enable_wind>0</enable_wind>
        <kinematic>0</kinematic>
      </link>
    </model>
    <gravity>0 0 -9.8</gravity>
    <magnetic_field>6e-06 2.3e-05 -4.2e-05</magnetic_field>
    <atmosphere type='adiabatic'/>
    <physics type='ode'>
      <max_step_size>0.001</max_step_size>
      <real_time_factor>1</real_time_factor>
      <real_time_update_rate>1000</real_time_update_rate>
      <ode>
        <solver>
            <friction_model>cone_model</friction_model>
        </solver>
      </ode>
    </physics>
    <scene>
      <ambient>0.4 0.4 0.4 1</ambient>
      <background>0.7 0.7 0.7 1</background>
      <shadows>1</shadows>
    </scene>
    <wind/>
    <spherical_coordinates>
      <surface_model>EARTH_WGS84</surface_model>
      <latitude_deg>0</latitude_deg>
      <longitude_deg>0</longitude_deg>
      <elevation>0</elevation>
      <heading_deg>0</heading_deg>
    </spherical_coordinates>
    <model name='coke_can'>
      <link name='link'>
        <inertial>
          <pose>0 0 0.06 0 -0 0</pose>
          <mass>0.39</mass>
          <inertia>
            <ixx>0.00055575</ixx>
            <ixy>0</ixy>
            <ixz>0</ixz>
            <iyy>0.00055575</iyy>
            <iyz>0</iyz>
            <izz>0.0001755</izz>
          </inertia>
        </inertial>
        <collision name='collision'>
          <pose>0.003937 0.004724 -0.18 0 -0 0</pose>
          <geometry>
            <mesh>
              <uri>model://coke_can/meshes/coke_can.dae</uri>
            </mesh>
          </geometry>
          <surface>
            <friction>
              <ode>
                <mu>1</mu>
                <mu2>1</mu2>
              </ode>
              <torsional>
                <ode/>
              </torsional>
            </friction>
            <contact>
              <ode>
                <kp>1e+07</kp>
                <kd>1</kd>
                <min_depth>0.001</min_depth>
                <max_vel>0.1</max_vel>
              </ode>
            </contact>
            <bounce/>
          </surface>
          <max_contacts>10</max_contacts>
        </collision>
        <visual name='visual'>
          <pose>0.003937 0.004724 -0.18 0 -0 0</pose>
          <geometry>
            <mesh>
              <uri>model://coke_can/meshes/coke_can.dae</uri>
            </mesh>
          </geometry>
        </visual>
        <self_collide>0</self_collide>
        <enable_wind>0</enable_wind>
        <kinematic>0</kinematic>
      </link>
      <pose>0.551648 -0.924087 0 0 -0 0</pose>
    </model>
    <model name='coke_can_0'>
      <link name='link'>
        <inertial>
          <pose>0 0 0.06 0 -0 0</pose>
          <mass>0.39</mass>
          <inertia>
            <ixx>0.00055575</ixx>
            <ixy>0</ixy>
            <ixz>0</ixz>
            <iyy>0.00055575</iyy>
            <iyz>0</iyz>
            <izz>0.0001755</izz>
          </inertia>
        </inertial>
        <collision name='collision'>
          <pose>0.003937 0.004724 -0.18 0 -0 0</pose>
          <geometry>
            <mesh>
              <uri>model://coke_can/meshes/coke_can.dae</uri>
            </mesh>
          </geometry>
          <surface>
            <friction>
              <ode>
                <mu>1</mu>
                <mu2>1</mu2>
              </ode>
              <torsional>
                <ode/>
              </torsional>
            </friction>
            <contact>
              <ode>
                <kp>1e+07</kp>
                <kd>1</kd>
                <min_depth>0.001</min_depth>
                <max_vel>0.1</max_vel>
              </ode>
            </contact>
            <bounce/>
          </surface>
          <max_contacts>10</max_contacts>
        </collision>
        <visual name='visual'>
          <pose>0.003937 0.004724 -0.18 0 -0 0</pose>
          <geometry>
            <mesh>
              <uri>model://coke_can/meshes/coke_can.dae</uri>
            </mesh>
          </geometry>
        </visual>
        <self_collide>0</self_collide>
        <enable_wind>0</enable_wind>
        <kinematic>0</kinematic>
      </link>
      <pose>-3.78876 5.1065 0 0 -0 0</pose>
    </model>
    <model name='arm_part'>
      <link name='link'>
        <inertial>
          <pose>0 -0.12223 0.101835 0 -0 0</pose>
          <mass>0.5</mass>
          <inertia>
            <ixx>0.00950655</ixx>
            <ixy>0</ixy>
            <ixz>0</ixz>
            <iyy>0.00543452</iyy>
            <iyz>0</iyz>
            <izz>0.0114843</izz>
          </inertia>
        </inertial>
        <collision name='collision'>
          <pose>0 -0.12223 0.101835 0 -0 0</pose>
          <geometry>
            <box>
              <size>0.29824 0.43206 0.20367</size>
            </box>
          </geometry>
          <max_contacts>10</max_contacts>
          <surface>
            <contact>
              <ode/>
            </contact>
            <bounce/>
            <friction>
              <torsional>
                <ode/>
              </torsional>
              <ode/>
            </friction>
          </surface>
        </collision>
        <visual name='visual'>
          <geometry>
            <mesh>
              <uri>model://arm_part/meshes/arm.dae</uri>
            </mesh>
          </geometry>
          <material>
            <script>
              <uri>model://arm_part/materials/scripts</uri>
              <uri>model://arm_part/materials/textures</uri>
              <name>ArmPart/Diffuse</name>
            </script>
          </material>
        </visual>
        <self_collide>0</self_collide>
        <enable_wind>0</enable_wind>
        <kinematic>0</kinematic>
      </link>
      <pose>2.61043 3.62963 0 0 -0 0</pose>
    </model>
    <model name='coke_can_1'>
      <link name='link'>
        <inertial>
          <pose>0 0 0.06 0 -0 0</pose>
          <mass>0.39</mass>
          <inertia>
            <ixx>0.00055575</ixx>
            <ixy>0</ixy>
            <ixz>0</ixz>
            <iyy>0.00055575</iyy>
            <iyz>0</iyz>
            <izz>0.0001755</izz>
          </inertia>
        </inertial>
        <collision name='collision'>
          <pose>0.003937 0.004724 -0.18 0 -0 0</pose>
          <geometry>
            <mesh>
              <uri>model://coke_can/meshes/coke_can.dae</uri>
            </mesh>
          </geometry>
          <surface>
            <friction>
              <ode>
                <mu>1</mu>
                <mu2>1</mu2>
              </ode>
              <torsional>
                <ode/>
              </torsional>
            </friction>
            <contact>
              <ode>
                <kp>1e+07</kp>
                <kd>1</kd>
                <min_depth>0.001</min_depth>
                <max_vel>0.1</max_vel>
              </ode>
            </contact>
            <bounce/>
          </surface>
          <max_contacts>10</max_contacts>
        </collision>
        <visual name='visual'>
          <pose>0.003937 0.004724 -0.18 0 -0 0</pose>
          <geometry>
            <mesh>
              <uri>model://coke_can/meshes/coke_can.dae</uri>
            </mesh>
          </geometry>
        </visual>
        <self_collide>0</self_collide>
        <enable_wind>0</enable_wind>
        <kinematic>0</kinematic>
      </link>
      <pose>2.64732 -2.29958 0 0 -0 0</pose>
    </model>
    <model name='suv'>
      <static>1</static>
      <link name='link'>
        <collision name='collision'>
          <pose>0 0 0 0 0 -1.5708</pose>
          <geometry>
            <mesh>
              <scale>0.06 0.06 0.06</scale>
              <uri>model://suv/meshes/suv.obj</uri>
            </mesh>
          </geometry>
          <max_contacts>10</max_contacts>
          <surface>
            <contact>
              <ode/>
            </contact>
            <bounce/>
            <friction>
              <torsional>
                <ode/>
              </torsional>
              <ode/>
            </friction>
          </surface>
        </collision>
        <visual name='visual'>
          <pose>0 0 0 0 0 -1.5708</pose>
          <geometry>
            <mesh>
              <scale>0.06 0.06 0.06</scale>
              <uri>model://suv/meshes/suv.obj</uri>
            </mesh>
          </geometry>
        </visual>
        <self_collide>0</self_collide>
        <enable_wind>0</enable_wind>
        <kinematic>0</kinematic>
      </link>
      <pose>-5.41254 2.17041 0 0 -0 0</pose>
    </model>
    <model name='coke_can_2'>
      <link name='link'>
        <inertial>
          <pose>0 0 0.06 0 -0 0</pose>
          <mass>0.39</mass>
          <inertia>
            <ixx>0.00055575</ixx>
            <ixy>0</ixy>
            <ixz>0</ixz>
            <iyy>0.00055575</iyy>
            <iyz>0</iyz>
            <izz>0.0001755</izz>
          </inertia>
        </inertial>
        <collision name='collision'>
          <pose>0.003937 0.004724 -0.18 0 -0 0</pose>
          <geometry>
            <mesh>
              <uri>model://coke_can/meshes/coke_can.dae</uri>
            </mesh>
          </geometry>
          <surface>
            <friction>
              <ode>
                <mu>1</mu>
                <mu2>1</mu2>
              </ode>
              <torsional>
                <ode/>
              </torsional>
            </friction>
            <contact>
              <ode>
                <kp>1e+07</kp>
                <kd>1</kd>
                <min_depth>0.001</min_depth>
                <max_vel>0.1</max_vel>
              </ode>
            </contact>
            <bounce/>
          </surface>
          <max_contacts>10</max_contacts>
        </collision>
        <visual name='visual'>
          <pose>0.003937 0.004724 -0.18 0 -0 0</pose>
          <geometry>
            <mesh>
              <uri>model://coke_can/meshes/coke_can.dae</uri>
            </mesh>
          </geometry>
        </visual>
        <self_collide>0</self_collide>
        <enable_wind>0</enable_wind>
        <kinematic>0</kinematic>
      </link>
      <pose>1.5652 -6.94419 0 0 -0 0</pose>
    </model>
    <model name='coke_can_3'>
      <link name='link'>
        <inertial>
          <pose>0 0 0.06 0 -0 0</pose>
          <mass>0.39</mass>
          <inertia>
            <ixx>0.00055575</ixx>
            <ixy>0</ixy>
            <ixz>0</ixz>
            <iyy>0.00055575</iyy>
            <iyz>0</iyz>
            <izz>0.0001755</izz>
          </inertia>
        </inertial>
        <collision name='collision'>
          <pose>0.003937 0.004724 -0.18 0 -0 0</pose>
          <geometry>
            <mesh>
              <uri>model://coke_can/meshes/coke_can.dae</uri>
            </mesh>
          </geometry>
          <surface>
            <friction>
              <ode>
                <mu>1</mu>
                <mu2>1</mu2>
              </ode>
              <torsional>
                <ode/>
              </torsional>
            </friction>
            <contact>
              <ode>
                <kp>1e+07</kp>
                <kd>1</kd>
                <min_depth>0.001</min_depth>
                <max_vel>0.1</max_vel>
              </ode>
            </contact>
            <bounce/>
          </surface>
          <max_contacts>10</max_contacts>
        </collision>
        <visual name='visual'>
          <pose>0.003937 0.004724 -0.18 0 -0 0</pose>
          <geometry>
            <mesh>
              <uri>model://coke_can/meshes/coke_can.dae</uri>
            </mesh>
          </geometry>
        </visual>
        <self_collide>0</self_collide>
        <enable_wind>0</enable_wind>
        <kinematic>0</kinematic>
      </link>
      <pose>-6.40545 -4.59128 0 0 -0 0</pose>
    </model>
    <model name='coke_can_4'>
      <link name='link'>
        <inertial>
          <pose>0 0 0.06 0 -0 0</pose>
          <mass>0.39</mass>
          <inertia>
            <ixx>0.00055575</ixx>
            <ixy>0</ixy>
            <ixz>0</ixz>
            <iyy>0.00055575</iyy>
            <iyz>0</iyz>
            <izz>0.0001755</izz>
          </inertia>
        </inertial>
        <collision name='collision'>
          <pose>0.003937 0.004724 -0.18 0 -0 0</pose>
          <geometry>
            <mesh>
              <uri>model://coke_can/meshes/coke_can.dae</uri>
            </mesh>
          </geometry>
          <surface>
            <friction>
              <ode>
                <mu>1</mu>
                <mu2>1</mu2>
              </ode>
              <torsional>
                <ode/>
              </torsional>
            </friction>
            <contact>
              <ode>
                <kp>1e+07</kp>
                <kd>1</kd>
                <min_depth>0.001</min_depth>
                <max_vel>0.1</max_vel>
              </ode>
            </contact>
            <bounce/>
          </surface>
          <max_contacts>10</max_contacts>
        </collision>
        <visual name='visual'>
          <pose>0.003937 0.004724 -0.18 0 -0 0</pose>
          <geometry>
            <mesh>
              <uri>model://coke_can/meshes/coke_can.dae</uri>
            </mesh>
          </geometry>
        </visual>
        <self_collide>0</self_collide>
        <enable_wind>0</enable_wind>
        <kinematic>0</kinematic>
      </link>
      <pose>7.02826 -3.2524 0 0 -0 0</pose>
    </model>
    <model name='coke_can_5'>
      <link name='link'>
        <inertial>
          <pose>0 0 0.06 0 -0 0</pose>
          <mass>0.39</mass>
          <inertia>
            <ixx>0.00055575</ixx>
            <ixy>0</ixy>
            <ixz>0</ixz>
            <iyy>0.00055575</iyy>
            <iyz>0</iyz>
            <izz>0.0001755</izz>
          </inertia>
        </inertial>
        <collision name='collision'>
          <pose>0.003937 0.004724 -0.18 0 -0 0</pose>
          <geometry>
            <mesh>
              <uri>model://coke_can/meshes/coke_can.dae</uri>
            </mesh>
          </geometry>
          <surface>
            <friction>
              <ode>
                <mu>1</mu>
                <mu2>1</mu2>
              </ode>
              <torsional>
                <ode/>
              </torsional>
            </friction>
            <contact>
              <ode>
                <kp>1e+07</kp>
                <kd>1</kd>
                <min_depth>0.001</min_depth>
                <max_vel>0.1</max_vel>
              </ode>
            </contact>
            <bounce/>
          </surface>
          <max_contacts>10</max_contacts>
        </collision>
        <visual name='visual'>
          <pose>0.003937 0.004724 -0.18 0 -0 0</pose>
          <geometry>
            <mesh>
              <uri>model://coke_can/meshes/coke_can.dae</uri>
            </mesh>
          </geometry>
        </visual>
        <self_collide>0</self_collide>
        <enable_wind>0</enable_wind>
        <kinematic>0</kinematic>
      </link>
      <pose>7.23003 3.29614 0 0 -0 0</pose>
    </model>
    <model name='MR-Buggy3'>
      <pose>7.25788 -4.22603 0.04 0 -0 0</pose>
      <self_collide>0</self_collide>
      <static>0</static>
      <link name='MR-Buggy3/Base'>
        <inertial>
          <pose>0 0 0 0 -0 0</pose>
          <mass>3</mass>
          <inertia>
            <ixx>0.0054</ixx>
            <ixy>0</ixy>
            <ixz>0</ixz>
            <iyy>0.0252</iyy>
            <iyz>0</iyz>
            <izz>0.0252</izz>
          </inertia>
        </inertial>
        <visual name='MR-Buggy3/BaseVisual'>
          <pose>0.1371 0 -0.0115 -0.018 -0 1.5707</pose>
          <geometry>
            <mesh>
              <uri>https://fuel.gazebosim.org/1.0/rudislaboratories/models/mr-buggy3/1/files/meshes/BaseReduced.dae</uri>
            </mesh>
          </geometry>
        </visual>
        <visual name='MR-Buggy3/TopVisual'>
          <pose>0.1371 0 -0.0115 -0.018 -0 1.5707</pose>
          <geometry>
            <mesh>
              <uri>https://fuel.gazebosim.org/1.0/rudislaboratories/models/mr-buggy3/1/files/meshes/TopReduced.dae</uri>
            </mesh>
          </geometry>
        </visual>
        <collision name='MR-Buggy3/BaseCollision'>
          <pose>0 0 0.06 0 -0 0</pose>
          <geometry>
            <box>
              <size>0.3 0.09 0.12</size>
            </box>
          </geometry>
          <max_contacts>10</max_contacts>
          <surface>
            <contact>
              <ode/>
            </contact>
            <bounce/>
            <friction>
              <torsional>
                <ode/>
              </torsional>
              <ode/>
            </friction>
          </surface>
        </collision>
        <sensor name='NPUSim/Camera' type='camera'>
          <pose>0.16 0 0.3 0 0.5 0</pose>
          <always_on>1</always_on>
          <update_rate>10</update_rate>
          <camera>
            <horizontal_fov>1.5</horizontal_fov>
            <image>
              <width>300</width>
              <height>300</height>
              <format>R8G8B8</format>
            </image>
            <clip>
              <near>0.1</near>
              <far>1000</far>
            </clip>
          </camera>
          <topic>NPU/image_sim</topic>
          <enable_metrics>1</enable_metrics>
        </sensor>
        <self_collide>0</self_collide>
        <enable_wind>0</enable_wind>
        <kinematic>0</kinematic>
      </link>
      <link name='MR-Buggy3/FrontRightWheel'>
        <pose relative_to='MR-Buggy3/FrontRightWheelJoint'>0 0 0 0 -0 0</pose>
        <inertial>
          <mass>0.05</mass>
          <inertia>
            <ixx>3.331e-05</ixx>
            <ixy>0</ixy>
            <ixz>0</ixz>
            <iyy>2.04e-05</iyy>
            <iyz>0</iyz>
            <izz>2.04e-05</izz>
          </inertia>
          <pose>0 0 0 0 -0 0</pose>
        </inertial>
        <gravity>1</gravity>
        <velocity_decay/>
        <visual name='MR-Buggy3/FrontRightWheelVisual'>
          <pose>0 0 0 0 -0 0</pose>
          <geometry>
            <mesh>
              <uri>https://fuel.gazebosim.org/1.0/rudislaboratories/models/mr-buggy3/1/files/meshes/Wheel.dae</uri>
            </mesh>
          </geometry>
        </visual>
        <collision name='MR-Buggy3/FrontRightWheelCollision'>
          <pose>0 0.015 0 -1.5707 0 0</pose>
          <geometry>
            <cylinder>
              <length>0.03</length>
              <radius>0.0365</radius>
            </cylinder>
          </geometry>
          <surface>
            <friction>
              <ode>
                <mu>0.5</mu>
                <mu2>1</mu2>
                <fdir1>0 0 1</fdir1>
              </ode>
              <torsional>
                <ode/>
              </torsional>
            </friction>
            <contact>
              <ode/>
            </contact>
            <bounce/>
          </surface>
          <max_contacts>10</max_contacts>
        </collision>
        <self_collide>0</self_collide>
        <enable_wind>0</enable_wind>
        <kinematic>0</kinematic>
      </link>
      <link name='MR-Buggy3/FrontRightWheelSteering'>
        <pose relative_to='MR-Buggy3/FrontRightWheelSteeringJoint'>0 0 0 0 -0 0</pose>
        <inertial>
          <mass>0.005</mass>
          <inertia>
            <ixx>1.8e-06</ixx>
            <iyy>1.8e-06</iyy>
            <izz>1.8e-06</izz>
            <ixy>0</ixy>
            <ixz>0</ixz>
            <iyz>0</iyz>
          </inertia>
          <pose>0 0 0 0 -0 0</pose>
        </inertial>
        <self_collide>0</self_collide>
        <enable_wind>0</enable_wind>
        <kinematic>0</kinematic>
      </link>
      <link name='MR-Buggy3/FrontLeftWheel'>
        <pose relative_to='MR-Buggy3/FrontLeftWheelJoint'>0 0 0 0 -0 0</pose>
        <inertial>
          <mass>0.05</mass>
          <inertia>
            <ixx>3.331e-05</ixx>
            <ixy>0</ixy>
            <ixz>0</ixz>
            <iyy>2.04e-05</iyy>
            <iyz>0</iyz>
            <izz>2.04e-05</izz>
          </inertia>
          <pose>0 0 0 0 -0 0</pose>
        </inertial>
        <gravity>1</gravity>
        <velocity_decay/>
        <visual name='MR-Buggy3/FrontLeftWheelVisual'>
          <pose>0 0 0 0 -0 3.14159</pose>
          <geometry>
            <mesh>
              <uri>https://fuel.gazebosim.org/1.0/rudislaboratories/models/mr-buggy3/1/files/meshes/Wheel.dae</uri>
            </mesh>
          </geometry>
        </visual>
        <collision name='MR-Buggy3/FrontLeftWheelCollision'>
          <pose>0 -0.015 0 -1.5707 0 0</pose>
          <geometry>
            <cylinder>
              <length>0.03</length>
              <radius>0.0365</radius>
            </cylinder>
          </geometry>
          <surface>
            <friction>
              <ode>
                <mu>0.5</mu>
                <mu2>1</mu2>
                <fdir1>0 0 1</fdir1>
              </ode>
              <torsional>
                <ode/>
              </torsional>
            </friction>
            <contact>
              <ode/>
            </contact>
            <bounce/>
          </surface>
          <max_contacts>10</max_contacts>
        </collision>
        <self_collide>0</self_collide>
        <enable_wind>0</enable_wind>
        <kinematic>0</kinematic>
      </link>
      <link name='MR-Buggy3/FrontLeftWheelSteering'>
        <pose relative_to='MR-Buggy3/FrontLeftWheelSteeringJoint'>0 0 0 0 -0 0</pose>
        <inertial>
          <mass>0.005</mass>
          <inertia>
            <ixx>1.8e-06</ixx>
            <iyy>1.8e-06</iyy>
            <izz>1.8e-06</izz>
            <ixy>0</ixy>
            <ixz>0</ixz>
            <iyz>0</iyz>
          </inertia>
          <pose>0 0 0 0 -0 0</pose>
        </inertial>
        <self_collide>0</self_collide>
        <enable_wind>0</enable_wind>
        <kinematic>0</kinematic>
      </link>
      <link name='MR-Buggy3/RearRightWheel'>
        <pose relative_to='MR-Buggy3/RearRightWheelJoint'>0 0 0 0 -0 0</pose>
        <inertial>
          <mass>0.05</mass>
          <inertia>
            <ixx>3.331e-05</ixx>
            <ixy>0</ixy>
            <ixz>0</ixz>
            <iyy>2.04e-05</iyy>
            <iyz>0</iyz>
            <izz>2.04e-05</izz>
          </inertia>
          <pose>0 0 0 0 -0 0</pose>
        </inertial>
        <gravity>1</gravity>
        <velocity_decay/>
        <visual name='MR-Buggy3/RearRightWheelVisual'>
          <pose>0 0 0 0 -0 0</pose>
          <geometry>
            <mesh>
              <uri>https://fuel.gazebosim.org/1.0/rudislaboratories/models/mr-buggy3/1/files/meshes/Wheel.dae</uri>
            </mesh>
          </geometry>
        </visual>
        <collision name='MR-Buggy3/RearRightWheelCollision'>
          <pose>0 0.015 0 -1.5707 0 0</pose>
          <geometry>
            <cylinder>
              <length>0.03</length>
              <radius>0.0365</radius>
            </cylinder>
          </geometry>
          <surface>
            <friction>
              <ode>
                <mu>0.5</mu>
                <mu2>1</mu2>
                <fdir1>0 0 1</fdir1>
              </ode>
              <torsional>
                <ode/>
              </torsional>
            </friction>
            <contact>
              <ode/>
            </contact>
            <bounce/>
          </surface>
          <max_contacts>10</max_contacts>
        </collision>
        <self_collide>0</self_collide>
        <enable_wind>0</enable_wind>
        <kinematic>0</kinematic>
      </link>
      <link name='MR-Buggy3/RearLeftWheel'>
        <pose relative_to='MR-Buggy3/RearLeftWheelJoint'>0 0 0 0 -0 0</pose>
        <inertial>
          <mass>0.05</mass>
          <inertia>
            <ixx>3.331e-05</ixx>
            <ixy>0</ixy>
            <ixz>0</ixz>
            <iyy>2.04e-05</iyy>
            <iyz>0</iyz>
            <izz>2.04e-05</izz>
          </inertia>
          <pose>0 0 0 0 -0 0</pose>
        </inertial>
        <gravity>1</gravity>
        <velocity_decay/>
        <visual name='MR-Buggy3/RearLeftWheelVisual'>
          <pose>0 0 0 0 -0 3.14159</pose>
          <geometry>
            <mesh>
              <uri>https://fuel.gazebosim.org/1.0/rudislaboratories/models/mr-buggy3/1/files/meshes/Wheel.dae</uri>
            </mesh>
          </geometry>
        </visual>
        <collision name='MR-Buggy3/RearLeftWheelCollision'>
          <pose>0 -0.015 0 -1.5707 0 0</pose>
          <geometry>
            <cylinder>
              <length>0.03</length>
              <radius>0.0365</radius>
            </cylinder>
          </geometry>
          <surface>
            <friction>
              <ode>
                <mu>0.5</mu>
                <mu2>1</mu2>
                <fdir1>0 0 1</fdir1>
              </ode>
              <torsional>
                <ode/>
              </torsional>
            </friction>
            <contact>
              <ode/>
            </contact>
            <bounce/>
          </surface>
          <max_contacts>10</max_contacts>
        </collision>
        <self_collide>0</self_collide>
        <enable_wind>0</enable_wind>
        <kinematic>0</kinematic>
      </link>
      <joint name='MR-Buggy3/FrontRightWheelSteeringJoint' type='revolute'>
        <parent>MR-Buggy3/Base</parent>
        <child>MR-Buggy3/FrontRightWheelSteering</child>
        <pose relative_to='MR-Buggy3/Base'>0.112 -0.1 0 0 -0 0</pose>
        <axis>
          <xyz>0 0 1</xyz>
          <limit>
            <lower>-0.6</lower>
            <upper>0.6</upper>
            <velocity>1</velocity>
            <effort>25</effort>
          </limit>
          <dynamics>
            <spring_reference>0</spring_reference>
            <spring_stiffness>0</spring_stiffness>
          </dynamics>
          <use_parent_model_frame>1</use_parent_model_frame>
        </axis>
      </joint>
      <joint name='MR-Buggy3/FrontRightWheelJoint' type='revolute'>
        <parent>MR-Buggy3/FrontRightWheelSteering</parent>
        <child>MR-Buggy3/FrontRightWheel</child>
        <pose relative_to='MR-Buggy3/FrontRightWheelSteeringJoint'>0 0 0 0 -0 0</pose>
        <axis>
          <xyz>0 1 0</xyz>
          <limit>
            <lower>-1.79769e+308</lower>
            <upper>1.79769e+308</upper>
          </limit>
          <dynamics>
            <spring_reference>0</spring_reference>
            <spring_stiffness>0</spring_stiffness>
          </dynamics>
          <use_parent_model_frame>1</use_parent_model_frame>
        </axis>
      </joint>
      <joint name='MR-Buggy3/FrontLeftWheelSteeringJoint' type='revolute'>
        <parent>MR-Buggy3/Base</parent>
        <child>MR-Buggy3/FrontLeftWheelSteering</child>
        <pose relative_to='MR-Buggy3/Base'>0.112 0.1 0 0 -0 0</pose>
        <axis>
          <xyz>0 0 1</xyz>
          <limit>
            <lower>-0.6</lower>
            <upper>0.6</upper>
            <velocity>1</velocity>
            <effort>25</effort>
          </limit>
          <dynamics>
            <spring_reference>0</spring_reference>
            <spring_stiffness>0</spring_stiffness>
          </dynamics>
          <use_parent_model_frame>1</use_parent_model_frame>
        </axis>
      </joint>
      <joint name='MR-Buggy3/FrontLeftWheelJoint' type='revolute'>
        <parent>MR-Buggy3/FrontLeftWheelSteering</parent>
        <child>MR-Buggy3/FrontLeftWheel</child>
        <pose relative_to='MR-Buggy3/FrontLeftWheelSteeringJoint'>0 0 0 0 -0 0</pose>
        <axis>
          <xyz>0 1 0</xyz>
          <limit>
            <lower>-1.79769e+308</lower>
            <upper>1.79769e+308</upper>
          </limit>
          <dynamics>
            <spring_reference>0</spring_reference>
            <spring_stiffness>0</spring_stiffness>
          </dynamics>
          <use_parent_model_frame>1</use_parent_model_frame>
        </axis>
      </joint>
      <joint name='MR-Buggy3/RearRightWheelJoint' type='revolute'>
        <parent>MR-Buggy3/Base</parent>
        <child>MR-Buggy3/RearRightWheel</child>
        <pose relative_to='MR-Buggy3/Base'>-0.1135 -0.1 0 0 -0 0</pose>
        <axis>
          <xyz>0 1 0</xyz>
          <limit>
            <lower>-1.79769e+308</lower>
            <upper>1.79769e+308</upper>
          </limit>
          <dynamics>
            <spring_reference>0</spring_reference>
            <spring_stiffness>0</spring_stiffness>
          </dynamics>
          <use_parent_model_frame>1</use_parent_model_frame>
        </axis>
      </joint>
      <joint name='MR-Buggy3/RearLeftWheelJoint' type='revolute'>
        <parent>MR-Buggy3/Base</parent>
        <child>MR-Buggy3/RearLeftWheel</child>
        <pose relative_to='MR-Buggy3/Base'>-0.1135 0.1 0 0 -0 0</pose>
        <axis>
          <xyz>0 1 0</xyz>
          <limit>
            <lower>-1.79769e+308</lower>
            <upper>1.79769e+308</upper>
          </limit>
          <dynamics>
            <spring_reference>0</spring_reference>
            <spring_stiffness>0</spring_stiffness>
          </dynamics>
          <use_parent_model_frame>1</use_parent_model_frame>
        </axis>
      </joint>
      <plugin name='ignition::gazebo::systems::AckermannSteering' filename='ignition-gazebo-ackermann-steering-system'>
        <left_joint>MR-Buggy3/FrontLeftWheelJoint</left_joint>
        <left_joint>MR-Buggy3/RearLeftWheelJoint</left_joint>
        <right_joint>MR-Buggy3/FrontRightWheelJoint</right_joint>
        <right_joint>MR-Buggy3/FrontRightWheelJoint</right_joint>
        <left_steering_joint>MR-Buggy3/FrontLeftWheelSteeringJoint</left_steering_joint>
        <right_steering_joint>MR-Buggy3/FrontRightWheelSteeringJoint</right_steering_joint>
        <kingpin_width>.18</kingpin_width>
        <steering_limit>0.5</steering_limit>
        <wheel_base>.2255</wheel_base>
        <wheel_separation>.2</wheel_separation>
        <wheel_radius>0.0365</wheel_radius>
        <min_velocity>-100</min_velocity>
        <max_velocity>100</max_velocity>
        <min_acceleration>-5</min_acceleration>
        <max_acceleration>5</max_acceleration>
        <topic>/cmd_vel</topic>
      </plugin>
    </model>
    <model name='realsense_d435'>
      <link name='link'>
        <inertial>
          <mass>0.0615752</mass>
          <inertia>
            <ixx>9.108e-05</ixx>
            <ixy>0</ixy>
            <ixz>0</ixz>
            <iyy>2.51e-06</iyy>
            <iyz>0</iyz>
            <izz>8.931e-05</izz>
          </inertia>
          <pose>0 0 0 0 -0 0</pose>
        </inertial>
        <collision name='collision'>
          <geometry>
            <mesh>
              <uri>https://fuel.gazebosim.org/1.0/bmchale/models/intel realsense d435/1/files/meshes/realsense.dae</uri>
            </mesh>
          </geometry>
          <max_contacts>10</max_contacts>
          <surface>
            <contact>
              <ode/>
            </contact>
            <bounce/>
            <friction>
              <torsional>
                <ode/>
              </torsional>
              <ode/>
            </friction>
          </surface>
        </collision>
        <visual name='visual'>
          <geometry>
            <mesh>
              <uri>https://fuel.gazebosim.org/1.0/bmchale/models/intel realsense d435/1/files/meshes/realsense.dae</uri>
              <submesh>
                <name>RealSense</name>
                <center>0</center>
              </submesh>
            </mesh>
          </geometry>
          <material>
            <diffuse>1 1 1 1</diffuse>
            <specular>1 1 1 1</specular>
            <pbr>
              <metal>
                <albedo_map>https://fuel.gazebosim.org/1.0/bmchale/models/intel realsense d435/1/files/materials/textures/RealSense_Albedo.png</albedo_map>
                <normal_map>https://fuel.gazebosim.org/1.0/bmchale/models/intel realsense d435/1/files/materials/textures/RealSense_Normal.png</normal_map>
                <metalness_map>https://fuel.gazebosim.org/1.0/bmchale/models/intel realsense d435/1/files/materials/textures/RealSense_Metalness.png</metalness_map>
                <roughness_map>https://fuel.gazebosim.org/1.0/bmchale/models/intel realsense d435/1/files/materials/textures/RealSense_Roughness.png</roughness_map>
              </metal>
            </pbr>
            <script>
              <uri>https://fuel.gazebosim.org/1.0/bmchale/models/intel realsense d435/1/files/materials/scripts/</uri>
              <uri>https://fuel.gazebosim.org/1.0/bmchale/models/intel realsense d435/1/files/materials/textures/</uri>
              <name>UrbanTile/RealSense_Diffuse</name>
            </script>
          </material>
        </visual>
        <sensor name='realsense_d435' type='rgbd_camera'>
          <update_rate>60</update_rate>
          <camera name='camera'>
            <horizontal_fov>1.0472</horizontal_fov>
            <lens>
              <intrinsics>
                <fx>554.255</fx>
                <fy>554.255</fy>
                <cx>320.5</cx>
                <cy>240.5</cy>
                <s>0</s>
              </intrinsics>
              <type>stereographic</type>
              <scale_to_hfov>1</scale_to_hfov>
            </lens>
            <distortion>
              <k1>0</k1>
              <k2>0</k2>
              <k3>0</k3>
              <p1>0</p1>
              <p2>0</p2>
              <center>0.5 0.5</center>
            </distortion>
            <image>
              <width>640</width>
              <height>480</height>
              <format>R8G8B8</format>
            </image>
            <clip>
              <near>0.01</near>
              <far>300</far>
            </clip>
            <depth_camera>
              <clip>
                <near>0.1</near>
                <far>10</far>
              </clip>
              <output>depths</output>
            </depth_camera>
            <noise>
              <type>gaussian</type>
              <mean>0</mean>
              <stddev>0.007</stddev>
            </noise>
          </camera>
        </sensor>
        <self_collide>0</self_collide>
        <enable_wind>0</enable_wind>
        <kinematic>0</kinematic>
      </link>
      <pose>7.66381 -6.02592 0 0 -0 0</pose>
    </model>
    <model name='gazebo'>
      <static>1</static>
      <link name='link'>
        <collision name='collision'>
          <geometry>
            <mesh>
              <scale>3 3 2.5</scale>
              <uri>model://gazebo/meshes/gazebo.dae</uri>
            </mesh>
          </geometry>
          <max_contacts>10</max_contacts>
          <surface>
            <contact>
              <ode/>
            </contact>
            <bounce/>
            <friction>
              <torsional>
                <ode/>
              </torsional>
              <ode/>
            </friction>
          </surface>
        </collision>
        <visual name='visual'>
          <geometry>
            <mesh>
              <scale>3 3 2.5</scale>
              <uri>model://gazebo/meshes/gazebo.dae</uri>
            </mesh>
          </geometry>
        </visual>
        <self_collide>0</self_collide>
        <enable_wind>0</enable_wind>
        <kinematic>0</kinematic>
      </link>
      <pose>-10.4526 -9.51587 0 0 -0 0</pose>
    </model>
    <model name='husky'>
      <pose>9.50536 -0.359821 0.5 0 -0 0</pose>
      <link name='base_link'>
        <collision name='collision'>
          <pose>0 0 0.1 0 -0 0</pose>
          <geometry>
            <box>
              <size>1.0074 0.5709 0.2675</size>
            </box>
          </geometry>
          <max_contacts>10</max_contacts>
          <surface>
            <contact>
              <ode/>
            </contact>
            <bounce/>
            <friction>
              <torsional>
                <ode/>
              </torsional>
              <ode/>
            </friction>
          </surface>
        </collision>
        <inertial>
          <mass>33.855</mass>
          <pose>-0.085613 -0.00084 0.238145 0 -0 0</pose>
          <inertia>
            <ixx>2.2343</ixx>
            <ixy>-0.023642</ixy>
            <ixz>0.275174</ixz>
            <iyy>3.42518</iyy>
            <iyz>0.00239624</iyz>
            <izz>2.1241</izz>
          </inertia>
        </inertial>
        <visual name='base'>
          <pose>0 0 0 0 -0 0</pose>
          <geometry>
            <mesh>
              <uri>model://husky/meshes/base_link.stl</uri>
            </mesh>
          </geometry>
          <material>
            <script>
              <name>Gazebo/FlatBlack</name>
              <uri>__default__</uri>
            </script>
          </material>
        </visual>
        <visual name='top_plate'>
          <pose>0 0 0 0 -0 0</pose>
          <geometry>
            <mesh>
              <uri>model://husky/meshes/top_plate.stl</uri>
            </mesh>
          </geometry>
          <material>
            <script>
              <name>Gazebo/Yellow</name>
              <uri>__default__</uri>
            </script>
          </material>
        </visual>
        <visual name='front_bumper'>
          <pose>0.47 0 0.091 0 -0 0</pose>
          <geometry>
            <mesh>
              <uri>model://husky/meshes/bumper.stl</uri>
            </mesh>
          </geometry>
          <material>
            <script>
              <name>Gazebo/FlatBlack</name>
              <uri>__default__</uri>
            </script>
          </material>
        </visual>
        <visual name='rear_bumper'>
          <pose>-0.47 0 0.091 0 -0 3.141</pose>
          <geometry>
            <mesh>
              <uri>model://husky/meshes/bumper.stl</uri>
            </mesh>
          </geometry>
          <material>
            <script>
              <name>Gazebo/FlatBlack</name>
              <uri>__default__</uri>
            </script>
          </material>
        </visual>
        <visual name='user_rail'>
          <pose>0.272 0 0.245 0 -0 0</pose>
          <geometry>
            <mesh>
              <uri>model://husky/meshes/user_rail.stl</uri>
            </mesh>
          </geometry>
          <material>
            <script>
              <name>Gazebo/Grey</name>
              <uri>__default__</uri>
            </script>
          </material>
        </visual>
        <self_collide>0</self_collide>
        <enable_wind>0</enable_wind>
        <kinematic>0</kinematic>
      </link>
      <link name='back_left_wheel'>
        <pose>-0.256 0.285475 0.035 0 -0 0</pose>
        <inertial>
          <mass>2.6357</mass>
          <pose>0 0 0 0 -0 0</pose>
          <inertia>
            <ixx>0.0246688</ixx>
            <ixy>0</ixy>
            <ixz>0</ixz>
            <iyy>0.0246688</iyy>
            <iyz>0</iyz>
            <izz>0.0441058</izz>
          </inertia>
        </inertial>
        <collision name='back_left_wheel_collision'>
          <pose>0 0 0 -1.5707 0 0</pose>
          <geometry>
            <cylinder>
              <radius>0.17775</radius>
              <length>0.1143</length>
            </cylinder>
          </geometry>
          <surface>
            <friction>
              <ode>
                <mu>100000</mu>
                <mu2>100000</mu2>
                <slip1>0</slip1>
                <slip2>0</slip2>
              </ode>
              <torsional>
                <ode/>
              </torsional>
            </friction>
            <contact>
              <ode/>
            </contact>
            <bounce/>
          </surface>
          <max_contacts>10</max_contacts>
        </collision>
        <visual name='back_left_wheel'>
          <pose>0 0 0 -3.14159 0 0</pose>
          <geometry>
            <mesh>
              <uri>model://husky/meshes/wheel.stl</uri>
            </mesh>
          </geometry>
          <material>
            <script>
              <name>Gazebo/Grey</name>
              <uri>__default__</uri>
            </script>
          </material>
        </visual>
        <self_collide>0</self_collide>
        <enable_wind>0</enable_wind>
        <kinematic>0</kinematic>
      </link>
      <joint name='back_left_joint' type='revolute'>
        <parent>base_link</parent>
        <child>back_left_wheel</child>
        <axis>
          <xyz expressed_in='__model__'>0 1 0</xyz>
          <limit>
            <lower>-1e+16</lower>
            <upper>1e+16</upper>
          </limit>
          <dynamics>
            <spring_reference>0</spring_reference>
            <spring_stiffness>0</spring_stiffness>
          </dynamics>
        </axis>
        <physics>
          <ode>
            <limit>
              <cfm>0</cfm>
              <erp>0.9</erp>
            </limit>
          </ode>
        </physics>
      </joint>
      <link name='back_right_wheel'>
        <pose>-0.256 -0.285475 0.035 0 -0 0</pose>
        <inertial>
          <mass>2.6357</mass>
          <pose>0 0 0 0 -0 0</pose>
          <inertia>
            <ixx>0.0246688</ixx>
            <ixy>0</ixy>
            <ixz>0</ixz>
            <iyy>0.0246688</iyy>
            <iyz>0</iyz>
            <izz>0.0441058</izz>
          </inertia>
        </inertial>
        <collision name='back_right_wheel_collision'>
          <pose>0 0 0 -1.5707 0 0</pose>
          <geometry>
            <cylinder>
              <radius>0.17775</radius>
              <length>0.1143</length>
            </cylinder>
          </geometry>
          <surface>
            <friction>
              <ode>
                <mu>100000</mu>
                <mu2>100000</mu2>
                <slip1>0</slip1>
                <slip2>0</slip2>
              </ode>
              <torsional>
                <ode/>
              </torsional>
            </friction>
            <contact>
              <ode/>
            </contact>
            <bounce/>
          </surface>
          <max_contacts>10</max_contacts>
        </collision>
        <visual name='back_right_wheel'>
          <pose>0 0 0 -3.14159 0 0</pose>
          <geometry>
            <mesh>
              <uri>model://husky/meshes/wheel.stl</uri>
            </mesh>
          </geometry>
          <material>
            <script>
              <name>Gazebo/Grey</name>
              <uri>__default__</uri>
            </script>
          </material>
        </visual>
        <self_collide>0</self_collide>
        <enable_wind>0</enable_wind>
        <kinematic>0</kinematic>
      </link>
      <joint name='back_right_joint' type='revolute'>
        <parent>base_link</parent>
        <child>back_right_wheel</child>
        <axis>
          <xyz expressed_in='__model__'>0 1 0</xyz>
          <limit>
            <lower>-1e+16</lower>
            <upper>1e+16</upper>
          </limit>
          <dynamics>
            <spring_reference>0</spring_reference>
            <spring_stiffness>0</spring_stiffness>
          </dynamics>
        </axis>
        <physics>
          <ode>
            <limit>
              <cfm>0</cfm>
              <erp>0.9</erp>
            </limit>
          </ode>
        </physics>
      </joint>
      <link name='front_left_wheel'>
        <pose>0.256 0.285475 0.035 0 -0 0</pose>
        <inertial>
          <mass>2.6357</mass>
          <pose>0 0 0 0 -0 0</pose>
          <inertia>
            <ixx>0.0246688</ixx>
            <ixy>0</ixy>
            <ixz>0</ixz>
            <iyy>0.0246688</iyy>
            <iyz>0</iyz>
            <izz>0.0441058</izz>
          </inertia>
        </inertial>
        <collision name='front_left_wheel_collision'>
          <pose>0 0 0 -1.5707 0 0</pose>
          <geometry>
            <cylinder>
              <radius>0.17775</radius>
              <length>0.1143</length>
            </cylinder>
          </geometry>
          <surface>
            <friction>
              <ode>
                <mu>100000</mu>
                <mu2>100000</mu2>
                <slip1>0</slip1>
                <slip2>0</slip2>
              </ode>
              <torsional>
                <ode/>
              </torsional>
            </friction>
            <contact>
              <ode/>
            </contact>
            <bounce/>
          </surface>
          <max_contacts>10</max_contacts>
        </collision>
        <visual name='front_left_wheel'>
          <pose>0 0 0 -3.14159 0 0</pose>
          <geometry>
            <mesh>
              <uri>model://husky/meshes/wheel.stl</uri>
            </mesh>
          </geometry>
          <material>
            <script>
              <name>Gazebo/Grey</name>
              <uri>__default__</uri>
            </script>
          </material>
        </visual>
        <self_collide>0</self_collide>
        <enable_wind>0</enable_wind>
        <kinematic>0</kinematic>
      </link>
      <joint name='front_left_joint' type='revolute'>
        <parent>base_link</parent>
        <child>front_left_wheel</child>
        <axis>
          <xyz expressed_in='__model__'>0 1 0</xyz>
          <limit>
            <lower>-1e+16</lower>
            <upper>1e+16</upper>
          </limit>
          <dynamics>
            <spring_reference>0</spring_reference>
            <spring_stiffness>0</spring_stiffness>
          </dynamics>
        </axis>
        <physics>
          <ode>
            <limit>
              <cfm>0</cfm>
              <erp>0.9</erp>
            </limit>
          </ode>
        </physics>
      </joint>
      <link name='front_right_wheel'>
        <pose>0.256 -0.285475 0.035 0 -0 0</pose>
        <inertial>
          <mass>2.6357</mass>
          <pose>0 0 0 0 -0 0</pose>
          <inertia>
            <ixx>0.0246688</ixx>
            <ixy>0</ixy>
            <ixz>0</ixz>
            <iyy>0.0246688</iyy>
            <iyz>0</iyz>
            <izz>0.0441058</izz>
          </inertia>
        </inertial>
        <collision name='front_right_wheel_collision'>
          <pose>0 0 0 -1.5707 0 0</pose>
          <geometry>
            <cylinder>
              <radius>0.17775</radius>
              <length>0.1143</length>
            </cylinder>
          </geometry>
          <surface>
            <friction>
              <ode>
                <mu>100000</mu>
                <mu2>100000</mu2>
                <slip1>0</slip1>
                <slip2>0</slip2>
              </ode>
              <torsional>
                <ode/>
              </torsional>
            </friction>
            <contact>
              <ode/>
            </contact>
            <bounce/>
          </surface>
          <max_contacts>10</max_contacts>
        </collision>
        <visual name='front_right_wheel'>
          <pose>0 0 0 -3.14159 0 0</pose>
          <geometry>
            <mesh>
              <uri>model://husky/meshes/wheel.stl</uri>
            </mesh>
          </geometry>
          <material>
            <script>
              <name>Gazebo/Grey</name>
              <uri>__default__</uri>
            </script>
          </material>
        </visual>
        <self_collide>0</self_collide>
        <enable_wind>0</enable_wind>
        <kinematic>0</kinematic>
      </link>
      <joint name='front_right_joint' type='revolute'>
        <parent>base_link</parent>
        <child>front_right_wheel</child>
        <axis>
          <xyz expressed_in='__model__'>0 1 0</xyz>
          <limit>
            <lower>-1e+16</lower>
            <upper>1e+16</upper>
          </limit>
          <dynamics>
            <spring_reference>0</spring_reference>
            <spring_stiffness>0</spring_stiffness>
          </dynamics>
        </axis>
        <physics>
          <ode>
            <limit>
              <cfm>0</cfm>
              <erp>0.9</erp>
            </limit>
          </ode>
        </physics>
      </joint>
      <plugin name='husky_diff_controller' filename='libhusky_gazebo_plugins.so'>
        <alwaysOn>1</alwaysOn>
        <updateRate>100.0</updateRate>
        <backLeftJoint>back_left_joint</backLeftJoint>
        <backRightJoint>back_right_joint</backRightJoint>
        <frontLeftJoint>front_left_joint</frontLeftJoint>
        <frontRightJoint>front_right_joint</frontRightJoint>
        <wheelSeparation>0.5709</wheelSeparation>
        <wheelDiameter>0.3555</wheelDiameter>
        <torque>35</torque>
      </plugin>
    </model>
    <model name='Lamp Post'>
      <static>1</static>
      <link name='link'>
        <collision name='collision'>
          <geometry>
            <mesh>
              <uri>model://lamp_post/meshes/lamp_post.dae</uri>
              <scale>3 3 3</scale>
            </mesh>
          </geometry>
          <max_contacts>10</max_contacts>
          <surface>
            <contact>
              <ode/>
            </contact>
            <bounce/>
            <friction>
              <torsional>
                <ode/>
              </torsional>
              <ode/>
            </friction>
          </surface>
        </collision>
        <visual name='visual'>
          <geometry>
            <mesh>
              <uri>model://lamp_post/meshes/lamp_post.dae</uri>
              <scale>3 3 3</scale>
            </mesh>
          </geometry>
        </visual>
        <self_collide>0</self_collide>
        <enable_wind>0</enable_wind>
        <kinematic>0</kinematic>
      </link>
      <pose>9.47081 -8.63997 0 0 -0 0</pose>
    </model>
    <model name='Lamp Post_0'>
      <static>1</static>
      <link name='link'>
        <collision name='collision'>
          <geometry>
            <mesh>
              <uri>model://lamp_post/meshes/lamp_post.dae</uri>
              <scale>3 3 3</scale>
            </mesh>
          </geometry>
          <max_contacts>10</max_contacts>
          <surface>
            <contact>
              <ode/>
            </contact>
            <bounce/>
            <friction>
              <torsional>
                <ode/>
              </torsional>
              <ode/>
            </friction>
          </surface>
        </collision>
        <visual name='visual'>
          <geometry>
            <mesh>
              <uri>model://lamp_post/meshes/lamp_post.dae</uri>
              <scale>3 3 3</scale>
            </mesh>
          </geometry>
        </visual>
        <self_collide>0</self_collide>
        <enable_wind>0</enable_wind>
        <kinematic>0</kinematic>
      </link>
      <pose>2.42401 -7.85589 0 0 -0 0</pose>
    </model>
    <model name='Lamp Post_1'>
      <static>1</static>
      <link name='link'>
        <collision name='collision'>
          <geometry>
            <mesh>
              <uri>model://lamp_post/meshes/lamp_post.dae</uri>
              <scale>3 3 3</scale>
            </mesh>
          </geometry>
          <max_contacts>10</max_contacts>
          <surface>
            <contact>
              <ode/>
            </contact>
            <bounce/>
            <friction>
              <torsional>
                <ode/>
              </torsional>
              <ode/>
            </friction>
          </surface>
        </collision>
        <visual name='visual'>
          <geometry>
            <mesh>
              <uri>model://lamp_post/meshes/lamp_post.dae</uri>
              <scale>3 3 3</scale>
            </mesh>
          </geometry>
        </visual>
        <self_collide>0</self_collide>
        <enable_wind>0</enable_wind>
        <kinematic>0</kinematic>
      </link>
      <pose>-3.92357 -7.75113 0 0 -0 0</pose>
    </model>
    <model name='person_standing'>
      <link name='link'>
        <inertial>
          <pose>0 -0.1 0.95 0 -0 0</pose>
          <mass>80</mass>
          <inertia>
            <ixx>24.88</ixx>
            <ixy>0</ixy>
            <ixz>0</ixz>
            <iyy>25.73</iyy>
            <iyz>0</iyz>
            <izz>2.48</izz>
          </inertia>
        </inertial>
        <collision name='bottom'>
          <pose>0 -0.1 0.01 0 -0 0</pose>
          <geometry>
            <box>
              <size>0.5 0.35 0.02</size>
            </box>
          </geometry>
          <max_contacts>10</max_contacts>
          <surface>
            <contact>
              <ode/>
            </contact>
            <bounce/>
            <friction>
              <torsional>
                <ode/>
              </torsional>
              <ode/>
            </friction>
          </surface>
        </collision>
        <collision name='person'>
          <pose>0 0 0.02 0.04 -0 0</pose>
          <geometry>
            <mesh>
              <uri>model://person_standing/meshes/standing.dae</uri>
            </mesh>
          </geometry>
          <max_contacts>10</max_contacts>
          <surface>
            <contact>
              <ode/>
            </contact>
            <bounce/>
            <friction>
              <torsional>
                <ode/>
              </torsional>
              <ode/>
            </friction>
          </surface>
        </collision>
        <visual name='visual'>
          <pose>0 0 0.02 0.04 -0 0</pose>
          <geometry>
            <mesh>
              <uri>model://person_standing/meshes/standing.dae</uri>
            </mesh>
          </geometry>
        </visual>
        <self_collide>0</self_collide>
        <enable_wind>0</enable_wind>
        <kinematic>0</kinematic>
      </link>
      <pose>9.45558 -3.90581 0 0 -0 0</pose>
    </model>
    <model name='DeliveryBot'>
      <link name='body'>
        <pose>0 0 0 0 0 -1.57</pose>
        <inertial>
          <pose>0 0 0.201 0 -0 0</pose>
          <mass>70</mass>
          <inertia>
            <ixx>5.1526</ixx>
            <iyy>2.4944</iyy>
            <izz>6.2829</izz>
            <ixy>0</ixy>
            <ixz>0</ixz>
            <iyz>0</iyz>
          </inertia>
        </inertial>
        <visual name='body'>
          <geometry>
            <mesh>
              <uri>https://fuel.gazebosim.org/1.0/openrobotics/models/deliverybot/1/files/meshes/body.obj</uri>
            </mesh>
          </geometry>
        </visual>
        <collision name='body'>
          <geometry>
            <mesh>
              <uri>https://fuel.gazebosim.org/1.0/openrobotics/models/deliverybot/1/files/meshes/body.obj</uri>
            </mesh>
          </geometry>
          <max_contacts>10</max_contacts>
          <surface>
            <contact>
              <ode/>
            </contact>
            <bounce/>
            <friction>
              <torsional>
                <ode/>
              </torsional>
              <ode/>
            </friction>
          </surface>
        </collision>
        <visual name='WheelLeftFront'>
          <pose>-0.22 -0.262 0.061 0 -0 0</pose>
          <geometry>
            <mesh>
              <uri>https://fuel.gazebosim.org/1.0/openrobotics/models/deliverybot/1/files/meshes/WheelMain.obj</uri>
            </mesh>
          </geometry>
        </visual>
        <collision name='front_caster_left'>
          <pose>-0.25 -0.27 0.05 0 -0 0</pose>
          <geometry>
            <sphere>
              <radius>0.05</radius>
            </sphere>
          </geometry>
          <surface>
            <friction>
              <torsional>
                <coefficient>0</coefficient>
                <ode/>
              </torsional>
              <ode>
                <mu>0</mu>
                <mu2>0</mu2>
              </ode>
              <bullet>
                <friction>0</friction>
                <friction2>0</friction2>
                <rolling_friction>0</rolling_friction>
              </bullet>
            </friction>
            <contact>
              <ode/>
            </contact>
            <bounce/>
          </surface>
          <max_contacts>10</max_contacts>
        </collision>
        <visual name='WheelLeftBack'>
          <pose>-0.22 0.334 0.061 0 -0 0</pose>
          <geometry>
            <mesh>
              <uri>https://fuel.gazebosim.org/1.0/openrobotics/models/deliverybot/1/files/meshes/WheelMain.obj</uri>
            </mesh>
          </geometry>
        </visual>
        <collision name='back_caster_left'>
          <pose>-0.25 0.34 0.05 0 -0 0</pose>
          <geometry>
            <sphere>
              <radius>0.05</radius>
            </sphere>
          </geometry>
          <surface>
            <friction>
              <torsional>
                <coefficient>0</coefficient>
                <ode/>
              </torsional>
              <ode>
                <mu>0</mu>
                <mu2>0</mu2>
              </ode>
              <bullet>
                <friction>0</friction>
                <friction2>0</friction2>
                <rolling_friction>0</rolling_friction>
              </bullet>
            </friction>
            <contact>
              <ode/>
            </contact>
            <bounce/>
          </surface>
          <max_contacts>10</max_contacts>
        </collision>
        <visual name='WheelRightFront'>
          <pose>0.217 -0.262 0.061 0 -0 0</pose>
          <geometry>
            <mesh>
              <uri>https://fuel.gazebosim.org/1.0/openrobotics/models/deliverybot/1/files/meshes/WheelMain.obj</uri>
            </mesh>
          </geometry>
        </visual>
        <collision name='front_caster_right'>
          <pose>0.25 -0.27 0.05 0 -0 0</pose>
          <geometry>
            <sphere>
              <radius>0.05</radius>
            </sphere>
          </geometry>
          <surface>
            <friction>
              <torsional>
                <coefficient>0</coefficient>
                <ode/>
              </torsional>
              <ode>
                <mu>0</mu>
                <mu2>0</mu2>
              </ode>
              <bullet>
                <friction>0</friction>
                <friction2>0</friction2>
                <rolling_friction>0</rolling_friction>
              </bullet>
            </friction>
            <contact>
              <ode/>
            </contact>
            <bounce/>
          </surface>
          <max_contacts>10</max_contacts>
        </collision>
        <visual name='WheelRightBack'>
          <pose>0.217 0.334 0.061 0 -0 0</pose>
          <geometry>
            <mesh>
              <uri>https://fuel.gazebosim.org/1.0/openrobotics/models/deliverybot/1/files/meshes/WheelMain.obj</uri>
            </mesh>
          </geometry>
        </visual>
        <collision name='back_caster_right'>
          <pose>0.25 0.34 0.05 0 -0 0</pose>
          <geometry>
            <sphere>
              <radius>0.05</radius>
            </sphere>
          </geometry>
          <surface>
            <friction>
              <torsional>
                <coefficient>0</coefficient>
                <ode/>
              </torsional>
              <ode>
                <mu>0</mu>
                <mu2>0</mu2>
              </ode>
              <bullet>
                <friction>0</friction>
                <friction2>0</friction2>
                <rolling_friction>0</rolling_friction>
              </bullet>
            </friction>
            <contact>
              <ode/>
            </contact>
            <bounce/>
          </surface>
          <max_contacts>10</max_contacts>
        </collision>
        <self_collide>0</self_collide>
        <enable_wind>0</enable_wind>
        <kinematic>0</kinematic>
      </link>
      <link name='suspension_tire_left'>
        <pose>0 0.26 0.1 0 -0 0</pose>
        <inertial>
          <mass>1</mass>
          <inertia>
            <ixx>1</ixx>
            <iyy>1</iyy>
            <izz>1</izz>
            <ixy>0</ixy>
            <ixz>0</ixz>
            <iyz>0</iyz>
          </inertia>
          <pose>0 0 0 0 -0 0</pose>
        </inertial>
        <self_collide>0</self_collide>
        <enable_wind>0</enable_wind>
        <kinematic>0</kinematic>
      </link>
      <joint name='joint_suspension_tire_left' type='prismatic'>
        <parent>body</parent>
        <child>suspension_tire_left</child>
        <axis>
          <xyz>0 0 1</xyz>
          <dynamics>
            <damping>500</damping>
            <spring_reference>-0.09</spring_reference>
            <spring_stiffness>2000</spring_stiffness>
          </dynamics>
          <limit>
            <lower>-1e+16</lower>
            <upper>1e+16</upper>
          </limit>
        </axis>
        <physics>
          <ode>
            <implicit_spring_damper>1</implicit_spring_damper>
            <limit>
              <cfm>0</cfm>
              <erp>0.2</erp>
            </limit>
          </ode>
        </physics>
      </joint>
      <link name='tire_left'>
        <pose>0 0.26 0.1 0 -0 0</pose>
        <inertial>
          <pose>0 0 0 0 -0 0</pose>
          <mass>5</mass>
          <inertia>
            <ixx>0.757897</ixx>
            <iyy>1.30298</iyy>
            <izz>0.757897</izz>
            <ixy>0</ixy>
            <ixz>0</ixz>
            <iyz>0</iyz>
          </inertia>
        </inertial>
        <visual name='WheelSideLeft'>
          <pose>0 0 0 0 0 -1.57</pose>
          <geometry>
            <mesh>
              <uri>https://fuel.gazebosim.org/1.0/openrobotics/models/deliverybot/1/files/meshes/WheelSide.obj</uri>
            </mesh>
          </geometry>
        </visual>
        <collision name='tire_left'>
          <geometry>
            <sphere>
              <radius>0.06137</radius>
            </sphere>
          </geometry>
          <surface>
            <contact>
              <ode>
                <kp>1e+07</kp>
                <kd>1</kd>
              </ode>
            </contact>
            <bounce/>
            <friction>
              <torsional>
                <ode/>
              </torsional>
              <ode/>
            </friction>
          </surface>
          <max_contacts>10</max_contacts>
        </collision>
        <self_collide>0</self_collide>
        <enable_wind>0</enable_wind>
        <kinematic>0</kinematic>
      </link>
      <joint name='joint_tire_left' type='revolute'>
        <parent>suspension_tire_left</parent>
        <child>tire_left</child>
        <axis>
          <xyz>0 1 0</xyz>
          <limit>
            <lower>-1e+16</lower>
            <upper>1e+16</upper>
          </limit>
          <dynamics>
            <spring_reference>0</spring_reference>
            <spring_stiffness>0</spring_stiffness>
          </dynamics>
        </axis>
      </joint>
      <link name='suspension_tire_right'>
        <pose>0 -0.26 0.1 0 -0 0</pose>
        <inertial>
          <mass>1</mass>
          <inertia>
            <ixx>1</ixx>
            <iyy>1</iyy>
            <izz>1</izz>
            <ixy>0</ixy>
            <ixz>0</ixz>
            <iyz>0</iyz>
          </inertia>
          <pose>0 0 0 0 -0 0</pose>
        </inertial>
        <self_collide>0</self_collide>
        <enable_wind>0</enable_wind>
        <kinematic>0</kinematic>
      </link>
      <joint name='joint_suspension_tire_right' type='prismatic'>
        <parent>body</parent>
        <child>suspension_tire_right</child>
        <axis>
          <xyz>0 0 1</xyz>
          <dynamics>
            <damping>500</damping>
            <spring_reference>-0.09</spring_reference>
            <spring_stiffness>2000</spring_stiffness>
          </dynamics>
          <limit>
            <lower>-1e+16</lower>
            <upper>1e+16</upper>
          </limit>
        </axis>
        <physics>
          <ode>
            <implicit_spring_damper>1</implicit_spring_damper>
            <limit>
              <cfm>0</cfm>
              <erp>0.2</erp>
            </limit>
          </ode>
        </physics>
      </joint>
      <link name='tire_right'>
        <pose>0 -0.26 0.1 0 -0 0</pose>
        <inertial>
          <pose>0 0 0 0 -0 0</pose>
          <mass>5</mass>
          <inertia>
            <ixx>0.757897</ixx>
            <iyy>1.30298</iyy>
            <izz>0.757897</izz>
            <ixy>0</ixy>
            <ixz>0</ixz>
            <iyz>0</iyz>
          </inertia>
        </inertial>
        <visual name='WheelSideRight'>
          <pose>0 0 0 0 0 -1.57</pose>
          <geometry>
            <mesh>
              <uri>https://fuel.gazebosim.org/1.0/openrobotics/models/deliverybot/1/files/meshes/WheelSide.obj</uri>
            </mesh>
          </geometry>
        </visual>
        <collision name='tire_right'>
          <geometry>
            <sphere>
              <radius>0.06137</radius>
            </sphere>
          </geometry>
          <surface>
            <contact>
              <ode>
                <kp>1e+07</kp>
                <kd>1</kd>
              </ode>
            </contact>
            <bounce/>
            <friction>
              <torsional>
                <ode/>
              </torsional>
              <ode/>
            </friction>
          </surface>
          <max_contacts>10</max_contacts>
        </collision>
        <self_collide>0</self_collide>
        <enable_wind>0</enable_wind>
        <kinematic>0</kinematic>
      </link>
      <joint name='joint_tire_right' type='revolute'>
        <parent>suspension_tire_right</parent>
        <child>tire_right</child>
        <axis>
          <xyz>0 1 0</xyz>
          <limit>
            <lower>-1e+16</lower>
            <upper>1e+16</upper>
          </limit>
          <dynamics>
            <spring_reference>0</spring_reference>
            <spring_stiffness>0</spring_stiffness>
          </dynamics>
        </axis>
      </joint>
      <pose>8.974 2.21081 0 0 -0 0</pose>
    </model>
    <model name='grey_wall'>
      <static>1</static>
      <link name='link'>
        <pose>0 0 1.4 0 -0 0</pose>
        <collision name='collision'>
          <geometry>
            <box>
              <size>7.5 0.2 2.8</size>
            </box>
          </geometry>
          <max_contacts>10</max_contacts>
          <surface>
            <contact>
              <ode/>
            </contact>
            <bounce/>
            <friction>
              <torsional>
                <ode/>
              </torsional>
              <ode/>
            </friction>
          </surface>
        </collision>
        <visual name='visual'>
          <cast_shadows>0</cast_shadows>
          <geometry>
            <box>
              <size>7.5 0.2 2.8</size>
            </box>
          </geometry>
          <material>
            <script>
              <uri>model://grey_wall/materials/scripts</uri>
              <uri>model://grey_wall/materials/textures</uri>
              <name>vrc/grey_wall</name>
            </script>
          </material>
        </visual>
        <self_collide>0</self_collide>
        <enable_wind>0</enable_wind>
        <kinematic>0</kinematic>
      </link>
      <pose>-1.09206 20.0592 0 0 -0 0</pose>
    </model>
    <model name='grey_wall_0'>
      <static>1</static>
      <link name='link'>
        <pose>0 0 1.4 0 -0 0</pose>
        <collision name='collision'>
          <geometry>
            <box>
              <size>7.5 0.2 2.8</size>
            </box>
          </geometry>
          <max_contacts>10</max_contacts>
          <surface>
            <contact>
              <ode/>
            </contact>
            <bounce/>
            <friction>
              <torsional>
                <ode/>
              </torsional>
              <ode/>
            </friction>
          </surface>
        </collision>
        <visual name='visual'>
          <cast_shadows>0</cast_shadows>
          <geometry>
            <box>
              <size>7.5 0.2 2.8</size>
            </box>
          </geometry>
          <material>
            <script>
              <uri>model://grey_wall/materials/scripts</uri>
              <uri>model://grey_wall/materials/textures</uri>
              <name>vrc/grey_wall</name>
            </script>
          </material>
        </visual>
        <self_collide>0</self_collide>
        <enable_wind>0</enable_wind>
        <kinematic>0</kinematic>
      </link>
      <pose>6.30258 20.0607 0 0 -0 0</pose>
    </model>
    <model name='grey_wall_1'>
      <static>1</static>
      <link name='link'>
        <pose>0 0 1.4 0 -0 0</pose>
        <collision name='collision'>
          <geometry>
            <box>
              <size>7.5 0.2 2.8</size>
            </box>
          </geometry>
          <max_contacts>10</max_contacts>
          <surface>
            <contact>
              <ode/>
            </contact>
            <bounce/>
            <friction>
              <torsional>
                <ode/>
              </torsional>
              <ode/>
            </friction>
          </surface>
        </collision>
        <visual name='visual'>
          <cast_shadows>0</cast_shadows>
          <geometry>
            <box>
              <size>7.5 0.2 2.8</size>
            </box>
          </geometry>
          <material>
            <script>
              <uri>model://grey_wall/materials/scripts</uri>
              <uri>model://grey_wall/materials/textures</uri>
              <name>vrc/grey_wall</name>
            </script>
          </material>
        </visual>
        <self_collide>0</self_collide>
        <enable_wind>0</enable_wind>
        <kinematic>0</kinematic>
      </link>
      <pose>13.7474 20.0506 0 0 -0 0</pose>
    </model>
    <model name='grey_wall_2'>
      <static>1</static>
      <link name='link'>
        <pose>0 0 1.4 0 -0 0</pose>
        <collision name='collision'>
          <geometry>
            <box>
              <size>7.5 0.2 2.8</size>
            </box>
          </geometry>
          <max_contacts>10</max_contacts>
          <surface>
            <contact>
              <ode/>
            </contact>
            <bounce/>
            <friction>
              <torsional>
                <ode/>
              </torsional>
              <ode/>
            </friction>
          </surface>
        </collision>
        <visual name='visual'>
          <cast_shadows>0</cast_shadows>
          <geometry>
            <box>
              <size>7.5 0.2 2.8</size>
            </box>
          </geometry>
          <material>
            <script>
              <uri>model://grey_wall/materials/scripts</uri>
              <uri>model://grey_wall/materials/textures</uri>
              <name>vrc/grey_wall</name>
            </script>
          </material>
        </visual>
        <self_collide>0</self_collide>
        <enable_wind>0</enable_wind>
        <kinematic>0</kinematic>
      </link>
      <pose>20.9448 14.1556 0 0 -0 0</pose>
    </model>
    <model name='grey_wall_3'>
      <static>1</static>
      <link name='link'>
        <pose>0 0 1.4 0 -0 0</pose>
        <collision name='collision'>
          <geometry>
            <box>
              <size>7.5 0.2 2.8</size>
            </box>
          </geometry>
          <max_contacts>10</max_contacts>
          <surface>
            <contact>
              <ode/>
            </contact>
            <bounce/>
            <friction>
              <torsional>
                <ode/>
              </torsional>
              <ode/>
            </friction>
          </surface>
        </collision>
        <visual name='visual'>
          <cast_shadows>0</cast_shadows>
          <geometry>
            <box>
              <size>7.5 0.2 2.8</size>
            </box>
          </geometry>
          <material>
            <script>
              <uri>model://grey_wall/materials/scripts</uri>
              <uri>model://grey_wall/materials/textures</uri>
              <name>vrc/grey_wall</name>
            </script>
          </material>
        </visual>
        <self_collide>0</self_collide>
        <enable_wind>0</enable_wind>
        <kinematic>0</kinematic>
      </link>
      <pose>14.7172 9.23036 0 0 -0 0</pose>
    </model>
    <model name='grey_wall_4'>
      <static>1</static>
      <link name='link'>
        <pose>0 0 1.4 0 -0 0</pose>
        <collision name='collision'>
          <geometry>
            <box>
              <size>7.5 0.2 2.8</size>
            </box>
          </geometry>
          <max_contacts>10</max_contacts>
          <surface>
            <contact>
              <ode/>
            </contact>
            <bounce/>
            <friction>
              <torsional>
                <ode/>
              </torsional>
              <ode/>
            </friction>
          </surface>
        </collision>
        <visual name='visual'>
          <cast_shadows>0</cast_shadows>
          <geometry>
            <box>
              <size>7.5 0.2 2.8</size>
            </box>
          </geometry>
          <material>
            <script>
              <uri>model://grey_wall/materials/scripts</uri>
              <uri>model://grey_wall/materials/textures</uri>
              <name>vrc/grey_wall</name>
            </script>
          </material>
        </visual>
        <self_collide>0</self_collide>
        <enable_wind>0</enable_wind>
        <kinematic>0</kinematic>
      </link>
      <pose>14.7656 5.46197 0 0 -0 0</pose>
    </model>
    <model name='grey_wall_5'>
      <static>1</static>
      <link name='link'>
        <pose>0 0 1.4 0 -0 0</pose>
        <collision name='collision'>
          <geometry>
            <box>
              <size>7.5 0.2 2.8</size>
            </box>
          </geometry>
          <max_contacts>10</max_contacts>
          <surface>
            <contact>
              <ode/>
            </contact>
            <bounce/>
            <friction>
              <torsional>
                <ode/>
              </torsional>
              <ode/>
            </friction>
          </surface>
        </collision>
        <visual name='visual'>
          <cast_shadows>0</cast_shadows>
          <geometry>
            <box>
              <size>7.5 0.2 2.8</size>
            </box>
          </geometry>
          <material>
            <script>
              <uri>model://grey_wall/materials/scripts</uri>
              <uri>model://grey_wall/materials/textures</uri>
              <name>vrc/grey_wall</name>
            </script>
          </material>
        </visual>
        <self_collide>0</self_collide>
        <enable_wind>0</enable_wind>
        <kinematic>0</kinematic>
      </link>
      <pose>13.2633 11.207 0 0 -0 0</pose>
    </model>
    <model name='grey_wall_6'>
      <static>1</static>
      <link name='link'>
        <pose>0 0 1.4 0 -0 0</pose>
        <collision name='collision'>
          <geometry>
            <box>
              <size>7.5 0.2 2.8</size>
            </box>
          </geometry>
          <max_contacts>10</max_contacts>
          <surface>
            <contact>
              <ode/>
            </contact>
            <bounce/>
            <friction>
              <torsional>
                <ode/>
              </torsional>
              <ode/>
            </friction>
          </surface>
        </collision>
        <visual name='visual'>
          <cast_shadows>0</cast_shadows>
          <geometry>
            <box>
              <size>7.5 0.2 2.8</size>
            </box>
          </geometry>
          <material>
            <script>
              <uri>model://grey_wall/materials/scripts</uri>
              <uri>model://grey_wall/materials/textures</uri>
              <name>vrc/grey_wall</name>
            </script>
          </material>
        </visual>
        <self_collide>0</self_collide>
        <enable_wind>0</enable_wind>
        <kinematic>0</kinematic>
      </link>
      <pose>9.58711 15.9777 0 0 -0 0</pose>
    </model>
    <model name='grey_wall_7'>
      <static>1</static>
      <link name='link'>
        <pose>0 0 1.4 0 -0 0</pose>
        <collision name='collision'>
          <geometry>
            <box>
              <size>7.5 0.2 2.8</size>
            </box>
          </geometry>
          <max_contacts>10</max_contacts>
          <surface>
            <contact>
              <ode/>
            </contact>
            <bounce/>
            <friction>
              <torsional>
                <ode/>
              </torsional>
              <ode/>
            </friction>
          </surface>
        </collision>
        <visual name='visual'>
          <cast_shadows>0</cast_shadows>
          <geometry>
            <box>
              <size>7.5 0.2 2.8</size>
            </box>
          </geometry>
          <material>
            <script>
              <uri>model://grey_wall/materials/scripts</uri>
              <uri>model://grey_wall/materials/textures</uri>
              <name>vrc/grey_wall</name>
            </script>
          </material>
        </visual>
        <self_collide>0</self_collide>
        <enable_wind>0</enable_wind>
        <kinematic>0</kinematic>
      </link>
      <pose>1.72564 -25.9269 0 0 -0 0</pose>
    </model>
    <model name='grey_wall_8'>
      <static>1</static>
      <link name='link'>
        <pose>0 0 1.4 0 -0 0</pose>
        <collision name='collision'>
          <geometry>
            <box>
              <size>7.5 0.2 2.8</size>
            </box>
          </geometry>
          <max_contacts>10</max_contacts>
          <surface>
            <contact>
              <ode/>
            </contact>
            <bounce/>
            <friction>
              <torsional>
                <ode/>
              </torsional>
              <ode/>
            </friction>
          </surface>
        </collision>
        <visual name='visual'>
          <cast_shadows>0</cast_shadows>
          <geometry>
            <box>
              <size>7.5 0.2 2.8</size>
            </box>
          </geometry>
          <material>
            <script>
              <uri>model://grey_wall/materials/scripts</uri>
              <uri>model://grey_wall/materials/textures</uri>
              <name>vrc/grey_wall</name>
            </script>
          </material>
        </visual>
        <self_collide>0</self_collide>
        <enable_wind>0</enable_wind>
        <kinematic>0</kinematic>
      </link>
      <pose>0.875054 -22.5441 0 0 -0 0</pose>
    </model>
    <model name='grey_wall_9'>
      <static>1</static>
      <link name='link'>
        <pose>0 0 1.4 0 -0 0</pose>
        <collision name='collision'>
          <geometry>
            <box>
              <size>7.5 0.2 2.8</size>
            </box>
          </geometry>
          <max_contacts>10</max_contacts>
          <surface>
            <contact>
              <ode/>
            </contact>
            <bounce/>
            <friction>
              <torsional>
                <ode/>
              </torsional>
              <ode/>
            </friction>
          </surface>
        </collision>
        <visual name='visual'>
          <cast_shadows>0</cast_shadows>
          <geometry>
            <box>
              <size>7.5 0.2 2.8</size>
            </box>
          </geometry>
          <material>
            <script>
              <uri>model://grey_wall/materials/scripts</uri>
              <uri>model://grey_wall/materials/textures</uri>
              <name>vrc/grey_wall</name>
            </script>
          </material>
        </visual>
        <self_collide>0</self_collide>
        <enable_wind>0</enable_wind>
        <kinematic>0</kinematic>
      </link>
      <pose>1.23338 -18.5523 0 0 -0 0</pose>
    </model>
    <model name='grey_wall_10'>
      <static>1</static>
      <link name='link'>
        <pose>0 0 1.4 0 -0 0</pose>
        <collision name='collision'>
          <geometry>
            <box>
              <size>7.5 0.2 2.8</size>
            </box>
          </geometry>
          <max_contacts>10</max_contacts>
          <surface>
            <contact>
              <ode/>
            </contact>
            <bounce/>
            <friction>
              <torsional>
                <ode/>
              </torsional>
              <ode/>
            </friction>
          </surface>
        </collision>
        <visual name='visual'>
          <cast_shadows>0</cast_shadows>
          <geometry>
            <box>
              <size>7.5 0.2 2.8</size>
            </box>
          </geometry>
          <material>
            <script>
              <uri>model://grey_wall/materials/scripts</uri>
              <uri>model://grey_wall/materials/textures</uri>
              <name>vrc/grey_wall</name>
            </script>
          </material>
        </visual>
        <self_collide>0</self_collide>
        <enable_wind>0</enable_wind>
        <kinematic>0</kinematic>
      </link>
      <pose>0.873365 -16.6961 0 0 -0 0</pose>
    </model>
    <model name='grey_wall_11'>
      <static>1</static>
      <link name='link'>
        <pose>0 0 1.4 0 -0 0</pose>
        <collision name='collision'>
          <geometry>
            <box>
              <size>7.5 0.2 2.8</size>
            </box>
          </geometry>
          <max_contacts>10</max_contacts>
          <surface>
            <contact>
              <ode/>
            </contact>
            <bounce/>
            <friction>
              <torsional>
                <ode/>
              </torsional>
              <ode/>
            </friction>
          </surface>
        </collision>
        <visual name='visual'>
          <cast_shadows>0</cast_shadows>
          <geometry>
            <box>
              <size>7.5 0.2 2.8</size>
            </box>
          </geometry>
          <material>
            <script>
              <uri>model://grey_wall/materials/scripts</uri>
              <uri>model://grey_wall/materials/textures</uri>
              <name>vrc/grey_wall</name>
            </script>
          </material>
        </visual>
        <self_collide>0</self_collide>
        <enable_wind>0</enable_wind>
        <kinematic>0</kinematic>
      </link>
      <pose>-27.5964 -8.98661 0 0 -0 0</pose>
    </model>
    <model name='grey_wall_12'>
      <static>1</static>
      <link name='link'>
        <pose>0 0 1.4 0 -0 0</pose>
        <collision name='collision'>
          <geometry>
            <box>
              <size>7.5 0.2 2.8</size>
            </box>
          </geometry>
          <max_contacts>10</max_contacts>
          <surface>
            <contact>
              <ode/>
            </contact>
            <bounce/>
            <friction>
              <torsional>
                <ode/>
              </torsional>
              <ode/>
            </friction>
          </surface>
        </collision>
        <visual name='visual'>
          <cast_shadows>0</cast_shadows>
          <geometry>
            <box>
              <size>7.5 0.2 2.8</size>
            </box>
          </geometry>
          <material>
            <script>
              <uri>model://grey_wall/materials/scripts</uri>
              <uri>model://grey_wall/materials/textures</uri>
              <name>vrc/grey_wall</name>
            </script>
          </material>
        </visual>
        <self_collide>0</self_collide>
        <enable_wind>0</enable_wind>
        <kinematic>0</kinematic>
      </link>
      <pose>-36.2561 -0.733519 0 0 -0 0</pose>
    </model>
    <model name='grey_wall_13'>
      <static>1</static>
      <link name='link'>
        <pose>0 0 1.4 0 -0 0</pose>
        <collision name='collision'>
          <geometry>
            <box>
              <size>7.5 0.2 2.8</size>
            </box>
          </geometry>
          <max_contacts>10</max_contacts>
          <surface>
            <contact>
              <ode/>
            </contact>
            <bounce/>
            <friction>
              <torsional>
                <ode/>
              </torsional>
              <ode/>
            </friction>
          </surface>
        </collision>
        <visual name='visual'>
          <cast_shadows>0</cast_shadows>
          <geometry>
            <box>
              <size>7.5 0.2 2.8</size>
            </box>
          </geometry>
          <material>
            <script>
              <uri>model://grey_wall/materials/scripts</uri>
              <uri>model://grey_wall/materials/textures</uri>
              <name>vrc/grey_wall</name>
            </script>
          </material>
        </visual>
        <self_collide>0</self_collide>
        <enable_wind>0</enable_wind>
        <kinematic>0</kinematic>
      </link>
      <pose>-36.8855 8.09539 0 0 -0 0</pose>
    </model>
    <model name='gazebo_0'>
      <static>1</static>
      <link name='link'>
        <collision name='collision'>
          <geometry>
            <mesh>
              <scale>3 3 2.5</scale>
              <uri>model://gazebo/meshes/gazebo.dae</uri>
            </mesh>
          </geometry>
          <max_contacts>10</max_contacts>
          <surface>
            <contact>
              <ode/>
            </contact>
            <bounce/>
            <friction>
              <torsional>
                <ode/>
              </torsional>
              <ode/>
            </friction>
          </surface>
        </collision>
        <visual name='visual'>
          <geometry>
            <mesh>
              <scale>3 3 2.5</scale>
              <uri>model://gazebo/meshes/gazebo.dae</uri>
            </mesh>
          </geometry>
        </visual>
        <self_collide>0</self_collide>
        <enable_wind>0</enable_wind>
        <kinematic>0</kinematic>
      </link>
      <pose>-21.663 7.72593 0 0 -0 0</pose>
    </model>
    <model name='grey_wall_14'>
      <static>1</static>
      <link name='link'>
        <pose>0 0 1.4 0 -0 0</pose>
        <collision name='collision'>
          <geometry>
            <box>
              <size>7.5 0.2 2.8</size>
            </box>
          </geometry>
          <max_contacts>10</max_contacts>
          <surface>
            <contact>
              <ode/>
            </contact>
            <bounce/>
            <friction>
              <torsional>
                <ode/>
              </torsional>
              <ode/>
            </friction>
          </surface>
        </collision>
        <visual name='visual'>
          <cast_shadows>0</cast_shadows>
          <geometry>
            <box>
              <size>7.5 0.2 2.8</size>
            </box>
          </geometry>
          <material>
            <script>
              <uri>model://grey_wall/materials/scripts</uri>
              <uri>model://grey_wall/materials/textures</uri>
              <name>vrc/grey_wall</name>
            </script>
          </material>
        </visual>
        <self_collide>0</self_collide>
        <enable_wind>0</enable_wind>
        <kinematic>0</kinematic>
      </link>
      <pose>-8.73441 20.0599 0 0 -0 0</pose>
    </model>
    <model name='grey_wall_15'>
      <static>1</static>
      <link name='link'>
        <pose>0 0 1.4 0 -0 0</pose>
        <collision name='collision'>
          <geometry>
            <box>
              <size>7.5 0.2 2.8</size>
            </box>
          </geometry>
          <max_contacts>10</max_contacts>
          <surface>
            <contact>
              <ode/>
            </contact>
            <bounce/>
            <friction>
              <torsional>
                <ode/>
              </torsional>
              <ode/>
            </friction>
          </surface>
        </collision>
        <visual name='visual'>
          <cast_shadows>0</cast_shadows>
          <geometry>
            <box>
              <size>7.5 0.2 2.8</size>
            </box>
          </geometry>
          <material>
            <script>
              <uri>model://grey_wall/materials/scripts</uri>
              <uri>model://grey_wall/materials/textures</uri>
              <name>vrc/grey_wall</name>
            </script>
          </material>
        </visual>
        <self_collide>0</self_collide>
        <enable_wind>0</enable_wind>
        <kinematic>0</kinematic>
      </link>
      <pose>-14.2098 15.3371 0 0 -0 0</pose>
    </model>
    <model name='grey_wall_16'>
      <static>1</static>
      <link name='link'>
        <pose>0 0 1.4 0 -0 0</pose>
        <collision name='collision'>
          <geometry>
            <box>
              <size>7.5 0.2 2.8</size>
            </box>
          </geometry>
          <max_contacts>10</max_contacts>
          <surface>
            <contact>
              <ode/>
            </contact>
            <bounce/>
            <friction>
              <torsional>
                <ode/>
              </torsional>
              <ode/>
            </friction>
          </surface>
        </collision>
        <visual name='visual'>
          <cast_shadows>0</cast_shadows>
          <geometry>
            <box>
              <size>7.5 0.2 2.8</size>
            </box>
          </geometry>
          <material>
            <script>
              <uri>model://grey_wall/materials/scripts</uri>
              <uri>model://grey_wall/materials/textures</uri>
              <name>vrc/grey_wall</name>
            </script>
          </material>
        </visual>
        <self_collide>0</self_collide>
        <enable_wind>0</enable_wind>
        <kinematic>0</kinematic>
      </link>
      <pose>-14.7804 7.4027 0 0 -0 0</pose>
    </model>
    <state world_name='default'>
      <sim_time>755 760000000</sim_time>
      <real_time>807 39657202</real_time>
      <wall_time>1671809840 316263413</wall_time>
      <iterations>755760</iterations>
      <model name='DeliveryBot'>
        <pose>8.97402 2.21082 -1e-06 -4e-06 0 -4e-06</pose>
        <scale>1 1 1</scale>
        <link name='body'>
          <pose>8.97402 2.21082 -1e-06 0 -4e-06 -1.57</pose>
          <velocity>1e-06 -0.000794 -2.9e-05 -0.00813 -6e-06 0</velocity>
          <acceleration>-0.000963 1.68018 -4.9e-05 -2.17089 -0.020018 -2.7e-05</acceleration>
          <wrench>-0.06744 117.613 -0.003424 0 -0 0</wrench>
        </link>
        <link name='suspension_tire_left'>
          <pose>8.97402 2.47082 0.06135 -4e-06 0 -4e-06</pose>
          <velocity>0 0.000231 -0.005751 -0.008044 -6e-06 0</velocity>
          <acceleration>0.000346 0.461169 -0.094016 2.76272 -0.012954 2.2e-05</acceleration>
          <wrench>0.000346 0.461169 -0.094016 0 -0 0</wrench>
        </link>
        <link name='suspension_tire_right'>
          <pose>8.97402 1.95082 0.06135 -4e-06 0 -4e-06</pose>
          <velocity>1e-06 -0.000463 -0.00566 -0.008107 -6e-06 0</velocity>
          <acceleration>0.000994 -0.926763 0.088254 2.63666 -0.012994 -0.000101</acceleration>
          <wrench>0.000994 -0.926763 0.088254 0 -0 0</wrench>
        </link>
        <link name='tire_left'>
          <pose>8.97402 2.47082 0.06135 -4e-06 -1.1e-05 -4e-06</pose>
          <velocity>0 0.000478 -0.005751 -0.007881 1e-06 0</velocity>
          <acceleration>0.000104 0.956575 -0.093136 3.08684 0.001632 2.2e-05</acceleration>
          <wrench>0.000518 4.78287 -0.465679 0 -0 0</wrench>
        </link>
        <link name='tire_right'>
          <pose>8.97402 1.95082 0.06135 -4e-06 -5.7e-05 -4e-06</pose>
          <velocity>0 0.000481 -0.005657 -0.007935 0 0</velocity>
          <acceleration>0.000105 0.962612 0.0942 2.979 0.001658 -0.000105</acceleration>
          <wrench>0.000526 4.81306 0.470998 0 -0 0</wrench>
        </link>
      </model>
      <model name='Lamp Post'>
        <pose>9.47081 -8.63997 0 0 -0 0</pose>
        <scale>1 1 1</scale>
        <link name='link'>
          <pose>9.47081 -8.63997 0 0 -0 0</pose>
          <velocity>0 0 0 0 -0 0</velocity>
          <acceleration>0 0 0 0 -0 0</acceleration>
          <wrench>0 0 0 0 -0 0</wrench>
        </link>
      </model>
      <model name='Lamp Post_0'>
        <pose>2.42401 -7.85589 0 0 -0 0</pose>
        <scale>1 1 1</scale>
        <link name='link'>
          <pose>2.42401 -7.85589 0 0 -0 0</pose>
          <velocity>0 0 0 0 -0 0</velocity>
          <acceleration>0 0 0 0 -0 0</acceleration>
          <wrench>0 0 0 0 -0 0</wrench>
        </link>
      </model>
      <model name='Lamp Post_1'>
        <pose>-3.92357 -7.75113 0 0 -0 0</pose>
        <scale>1 1 1</scale>
        <link name='link'>
          <pose>-3.92357 -7.75113 0 0 -0 0</pose>
          <velocity>0 0 0 0 -0 0</velocity>
          <acceleration>0 0 0 0 -0 0</acceleration>
          <wrench>0 0 0 0 -0 0</wrench>
        </link>
      </model>
      <model name='MR-Buggy3'>
        <pose>16.7486 1.19874 0.036434 0.000187 0.000418 0.472361</pose>
        <scale>1 1 1</scale>
        <link name='MR-Buggy3/Base'>
          <pose>16.7486 1.19874 0.036434 0.000187 0.000418 0.472361</pose>
          <velocity>0.021816 0.012464 -0.007139 0.167644 0.072394 -0.007659</velocity>
          <acceleration>-0.073892 0.111496 0.354615 0.640779 0.131049 -1.8082</acceleration>
          <wrench>-0.221676 0.334489 1.06384 0 -0 0</wrench>
        </link>
        <link name='MR-Buggy3/FrontLeftWheel'>
          <pose>16.8028 1.33874 0.036502 -3.14061 0.340085 -2.76891</pose>
          <velocity>0.023334 0.011007 0.010553 -0.301331 0.639587 -0.000231</velocity>
          <acceleration>1.8789 -3.25217 48.9537 2.42461 -1.18207 2.32663</acceleration>
          <wrench>0.093945 -0.162608 2.44769 0 -0 0</wrench>
        </link>
        <link name='MR-Buggy3/FrontLeftWheelSteering'>
          <pose>16.8028 1.33874 0.036526 -0.001021 0.000438 0.372302</pose>
          <velocity>0.023514 0.010654 0.010169 -0.122869 -0.042036 -0.002287</velocity>
          <acceleration>2.00885 -3.45117 53.7336 1.41082 -1.05654 -2.78338</acceleration>
          <wrench>0.010044 -0.017256 0.268668 0 -0 0</wrench>
        </link>
        <link name='MR-Buggy3/FrontRightWheel'>
          <pose>16.8938 1.16066 0.036446 3.14007 -1.12579 -2.71116</pose>
          <velocity>0.021984 0.010198 -0.043935 -0.229944 0.641199 0.013121</velocity>
          <acceleration>-0.2189 -0.843449 -54.9366 -0.835911 -1.10074 1.34306</acceleration>
          <wrench>-0.010945 -0.042172 -2.74683 0 -0 0</wrench>
        </link>
        <link name='MR-Buggy3/FrontRightWheelSteering'>
          <pose>16.8938 1.16066 0.036465 0.000648 0.000425 0.429032</pose>
          <velocity>0.021911 0.010284 -0.049011 0.05354 0.020288 0.019421</velocity>
          <acceleration>-0.264767 -0.843454 -60.0304 1.8768 -0.268129 1.75661</acceleration>
          <wrench>-0.001324 -0.004217 -0.300152 0 -0 0</wrench>
        </link>
        <link name='MR-Buggy3/RearLeftWheel'>
          <pose>16.602 1.23614 0.036501 -3.14133 -0.663922 -2.66947</pose>
          <velocity>0.022062 0.013353 0.008718 -0.356026 0.586611 -0.045533</velocity>
          <acceleration>0.53377 -0.307244 35.5296 1.82463 -0.354196 2.33609</acceleration>
          <wrench>0.026689 -0.015362 1.77648 0 -0 0</wrench>
        </link>
        <link name='MR-Buggy3/RearRightWheel'>
          <pose>16.693 1.05805 0.036466 3.14126 -0.418597 -2.66907</pose>
          <velocity>0.02094 0.012517 -0.026997 -0.175335 0.673417 -0.013482</velocity>
          <acceleration>-0.747677 0.436184 -28.0033 -0.784026 0.53956 -1.83141</acceleration>
          <wrench>-0.037384 0.021809 -1.40017 0 -0 0</wrench>
        </link>
      </model>
      <model name='arm_part'>
        <pose>2.61043 3.62963 -0 0 -0 0</pose>
        <scale>1 1 1</scale>
        <link name='link'>
          <pose>2.61043 3.62963 -0 0 -0 0</pose>
          <velocity>0 0 0 0 -0 0</velocity>
          <acceleration>-8e-06 -5e-06 0 4.8e-05 -8.2e-05 0</acceleration>
          <wrench>-4e-06 -2e-06 0 0 -0 0</wrench>
        </link>
      </model>
      <model name='coke_can'>
        <pose>0.551613 -0.924164 -0.003472 -0.036724 0.008273 -0.000693</pose>
        <scale>1 1 1</scale>
        <link name='link'>
          <pose>0.551613 -0.924164 -0.003472 -0.036724 0.008273 -0.000693</pose>
          <velocity>0 0 0 0 -0 0</velocity>
          <acceleration>0.345505 -0.447223 -0.079262 1.61792 -0.160963 0.628236</acceleration>
          <wrench>0.134747 -0.174417 -0.030912 0 -0 0</wrench>
        </link>
      </model>
      <model name='coke_can_0'>
        <pose>-3.78879 5.10642 -0.003472 -0.036724 0.008273 -0.000693</pose>
        <scale>1 1 1</scale>
        <link name='link'>
          <pose>-3.78879 5.10642 -0.003472 -0.036724 0.008273 -0.000693</pose>
          <velocity>0 0 0 0 -0 0</velocity>
          <acceleration>0.345505 -0.447223 -0.079262 1.61792 -0.160966 0.628236</acceleration>
          <wrench>0.134747 -0.174417 -0.030912 0 -0 0</wrench>
        </link>
      </model>
      <model name='coke_can_1'>
        <pose>2.64729 -2.29966 -0.003472 -0.036721 0.00827 -0.000693</pose>
        <scale>1 1 1</scale>
        <link name='link'>
          <pose>2.64729 -2.29966 -0.003472 -0.036721 0.00827 -0.000693</pose>
          <velocity>0 0 0 0 -0 0</velocity>
          <acceleration>-0.012784 0.202288 -0.016397 2.71793 -0.230566 -0.088135</acceleration>
          <wrench>-0.004986 0.078892 -0.006395 0 -0 0</wrench>
        </link>
      </model>
      <model name='coke_can_2'>
        <pose>1.56516 -6.94427 -0.003472 -0.036727 0.008266 -0.000694</pose>
        <scale>1 1 1</scale>
        <link name='link'>
          <pose>1.56516 -6.94427 -0.003472 -0.036727 0.008266 -0.000694</pose>
          <velocity>0 0 0 0 -0 0</velocity>
          <acceleration>0.093482 -0.09365 -0.001193 -1.4878 1.48503 -2.97604</acceleration>
          <wrench>0.036458 -0.036524 -0.000465 0 -0 0</wrench>
        </link>
      </model>
      <model name='coke_can_3'>
        <pose>-6.40548 -4.59136 -0.003472 -0.036723 0.008267 -0.000695</pose>
        <scale>1 1 1</scale>
        <link name='link'>
          <pose>-6.40548 -4.59136 -0.003472 -0.036723 0.008267 -0.000695</pose>
          <velocity>0 0 0 0 -0 0</velocity>
          <acceleration>-0.000602 0.041591 -0.005982 -0.738048 -0.012702 -0.020681</acceleration>
          <wrench>-0.000235 0.01622 -0.002333 0 -0 0</wrench>
        </link>
      </model>
      <model name='coke_can_4'>
        <pose>7.02822 -3.25248 -0.003472 -0.036728 0.008266 -0.000697</pose>
        <scale>1 1 1</scale>
        <link name='link'>
          <pose>7.02822 -3.25248 -0.003472 -0.036728 0.008266 -0.000697</pose>
          <velocity>0 0 0 0 -0 0</velocity>
          <acceleration>0.006576 -0.006634 0.000674 0.117342 0.116576 0.011603</acceleration>
          <wrench>0.002565 -0.002587 0.000263 0 -0 0</wrench>
        </link>
      </model>
      <model name='coke_can_5'>
        <pose>7.22999 3.29606 -0.003472 -0.036723 0.008274 -0.000697</pose>
        <scale>1 1 1</scale>
        <link name='link'>
          <pose>7.22999 3.29606 -0.003472 -0.036723 0.008274 -0.000697</pose>
          <velocity>0 0 0 0 -0 0</velocity>
          <acceleration>0.345229 -0.44648 -0.079074 1.6048 -0.16586 0.627614</acceleration>
          <wrench>0.134639 -0.174127 -0.030839 0 -0 0</wrench>
        </link>
      </model>
      <model name='gazebo'>
        <pose>-10.3933 -7.04736 0 0 -0 0</pose>
        <scale>1 1 1</scale>
        <link name='link'>
          <pose>-10.3933 -7.04736 0 0 -0 0</pose>
          <velocity>0 0 0 0 -0 0</velocity>
          <acceleration>0 0 0 0 -0 0</acceleration>
          <wrench>0 0 0 0 -0 0</wrench>
        </link>
      </model>
      <model name='gazebo_0'>
        <pose>-21.663 7.72593 0 0 -0 0</pose>
        <scale>1 1 1</scale>
        <link name='link'>
          <pose>-21.663 7.72593 0 0 -0 0</pose>
          <velocity>0 0 0 0 -0 0</velocity>
          <acceleration>0 0 0 0 -0 0</acceleration>
          <wrench>0 0 0 0 -0 0</wrench>
        </link>
      </model>
      <model name='grey_wall'>
        <pose>-1.09206 20.0592 0 0 -0 0</pose>
        <scale>1 1 1</scale>
        <link name='link'>
          <pose>-1.09206 20.0592 1.4 0 -0 0</pose>
          <velocity>0 0 0 0 -0 0</velocity>
          <acceleration>0 0 0 0 -0 0</acceleration>
          <wrench>0 0 0 0 -0 0</wrench>
        </link>
      </model>
      <model name='grey_wall_0'>
        <pose>6.30258 20.0607 0 0 -0 0</pose>
        <scale>1 1 1</scale>
        <link name='link'>
          <pose>6.30258 20.0607 1.4 0 -0 0</pose>
          <velocity>0 0 0 0 -0 0</velocity>
          <acceleration>0 0 0 0 -0 0</acceleration>
          <wrench>0 0 0 0 -0 0</wrench>
        </link>
      </model>
      <model name='grey_wall_1'>
        <pose>13.7474 20.0506 0 0 -0 0</pose>
        <scale>1 1 1</scale>
        <link name='link'>
          <pose>13.7474 20.0506 1.4 0 -0 0</pose>
          <velocity>0 0 0 0 -0 0</velocity>
          <acceleration>0 0 0 0 -0 0</acceleration>
          <wrench>0 0 0 0 -0 0</wrench>
        </link>
      </model>
      <model name='grey_wall_10'>
        <pose>9.56874 -12.4779 0 0 -0 0</pose>
        <scale>1 1 1</scale>
        <link name='link'>
          <pose>9.56874 -12.4779 1.4 0 -0 0</pose>
          <velocity>0 0 0 0 -0 0</velocity>
          <acceleration>0 0 0 0 -0 0</acceleration>
          <wrench>0 0 0 0 -0 0</wrench>
        </link>
      </model>
      <model name='grey_wall_11'>
        <pose>-18.1814 -12.7582 0 0 0 -0.734407</pose>
        <scale>1 1 1</scale>
        <link name='link'>
          <pose>-18.1814 -12.7582 1.4 0 0 -0.734407</pose>
          <velocity>0 0 0 0 -0 0</velocity>
          <acceleration>0 0 0 0 -0 0</acceleration>
          <wrench>0 0 0 0 -0 0</wrench>
        </link>
      </model>
      <model name='grey_wall_12'>
        <pose>-21.4523 -6.59853 0 0 0 -1.4598</pose>
        <scale>1 1 1</scale>
        <link name='link'>
          <pose>-21.4523 -6.59853 1.4 0 0 -1.4598</pose>
          <velocity>0 0 0 0 -0 0</velocity>
          <acceleration>0 0 0 0 -0 0</acceleration>
          <wrench>0 0 0 0 -0 0</wrench>
        </link>
      </model>
      <model name='grey_wall_13'>
        <pose>-21.5356 0.523983 0 0 -0 1.28015</pose>
        <scale>1 1 1</scale>
        <link name='link'>
          <pose>-21.5356 0.523983 1.4 0 -0 1.28015</pose>
          <velocity>0 0 0 0 -0 0</velocity>
          <acceleration>0 0 0 0 -0 0</acceleration>
          <wrench>0 0 0 0 -0 0</wrench>
        </link>
      </model>
      <model name='grey_wall_14'>
        <pose>-7.78655 17.6097 0 0 -0 0.680868</pose>
        <scale>1 1 1</scale>
        <link name='link'>
          <pose>-7.78655 17.6097 1.4 0 -0 0.680868</pose>
          <velocity>0 0 0 0 -0 0</velocity>
          <acceleration>0 0 0 0 -0 0</acceleration>
          <wrench>0 0 0 0 -0 0</wrench>
        </link>
      </model>
      <model name='grey_wall_15'>
        <pose>-13.369 12.9834 0 0 -0 0.68949</pose>
        <scale>1 1 1</scale>
        <link name='link'>
          <pose>-13.369 12.9834 1.4 0 -0 0.68949</pose>
          <velocity>0 0 0 0 -0 0</velocity>
          <acceleration>0 0 0 0 -0 0</acceleration>
          <wrench>0 0 0 0 -0 0</wrench>
        </link>
      </model>
      <model name='grey_wall_16'>
        <pose>-19.8044 11.8509 0 0 0 -0.354647</pose>
        <scale>1 1 1</scale>
        <link name='link'>
          <pose>-19.8044 11.8509 1.4 0 0 -0.354647</pose>
          <velocity>0 0 0 0 -0 0</velocity>
          <acceleration>0 0 0 0 -0 0</acceleration>
          <wrench>0 0 0 0 -0 0</wrench>
        </link>
      </model>
      <model name='grey_wall_2'>
        <pose>19.1693 16.7061 0 0 0 -1.10288</pose>
        <scale>1 1 1</scale>
        <link name='link'>
          <pose>19.1693 16.7061 1.4 0 0 -1.10288</pose>
          <velocity>0 0 0 0 -0 0</velocity>
          <acceleration>0 0 0 0 -0 0</acceleration>
          <wrench>0 0 0 0 -0 0</wrench>
        </link>
      </model>
      <model name='grey_wall_3'>
        <pose>19.9937 -4.9034 0 0 0 -1.6726</pose>
        <scale>1 1 1</scale>
        <link name='link'>
          <pose>19.9937 -4.9034 1.4 0 0 -1.6726</pose>
          <velocity>0 0 0 0 -0 0</velocity>
          <acceleration>0 0 0 0 -0 0</acceleration>
          <wrench>0 0 0 0 -0 0</wrench>
        </link>
      </model>
      <model name='grey_wall_4'>
        <pose>20.3234 2.2979 0 0 0 -1.57405</pose>
        <scale>1 1 1</scale>
        <link name='link'>
          <pose>20.3234 2.2979 1.4 0 0 -1.57405</pose>
          <velocity>0 0 0 0 -0 0</velocity>
          <acceleration>0 0 0 0 -0 0</acceleration>
          <wrench>0 0 0 0 -0 0</wrench>
        </link>
      </model>
      <model name='grey_wall_5'>
        <pose>16.4974 -10.5105 0 0 -0 0.552868</pose>
        <scale>1 1 1</scale>
        <link name='link'>
          <pose>16.4974 -10.5105 1.4 0 -0 0.552868</pose>
          <velocity>0 0 0 0 -0 0</velocity>
          <acceleration>0 0 0 0 -0 0</acceleration>
          <wrench>0 0 0 0 -0 0</wrench>
        </link>
      </model>
      <model name='grey_wall_6'>
        <pose>20.5654 9.6079 0 0 0 -1.64863</pose>
        <scale>1 1 1</scale>
        <link name='link'>
          <pose>20.5654 9.6079 1.4 0 0 -1.64863</pose>
          <velocity>0 0 0 0 -0 0</velocity>
          <acceleration>0 0 0 0 -0 0</acceleration>
          <wrench>0 0 0 0 -0 0</wrench>
        </link>
      </model>
      <model name='grey_wall_7'>
        <pose>-11.9015 -15.1974 0 0 -0 0</pose>
        <scale>1 1 1</scale>
        <link name='link'>
          <pose>-11.9015 -15.1974 1.4 0 -0 0</pose>
          <velocity>0 0 0 0 -0 0</velocity>
          <acceleration>0 0 0 0 -0 0</acceleration>
          <wrench>0 0 0 0 -0 0</wrench>
        </link>
      </model>
      <model name='grey_wall_8'>
        <pose>-4.83261 -15.2532 0 0 -0 0</pose>
        <scale>1 1 1</scale>
        <link name='link'>
          <pose>-4.83261 -15.2532 1.4 0 -0 0</pose>
          <velocity>0 0 0 0 -0 0</velocity>
          <acceleration>0 0 0 0 -0 0</acceleration>
          <wrench>0 0 0 0 -0 0</wrench>
        </link>
      </model>
      <model name='grey_wall_9'>
        <pose>2.4148 -13.8309 0 0 -0 0.366253</pose>
        <scale>1 1 1</scale>
        <link name='link'>
          <pose>2.4148 -13.8309 1.4 0 -0 0.366253</pose>
          <velocity>0 0 0 0 -0 0</velocity>
          <acceleration>0 0 0 0 -0 0</acceleration>
          <wrench>0 0 0 0 -0 0</wrench>
        </link>
      </model>
      <model name='ground_plane'>
        <pose>0 0 0 0 -0 0</pose>
        <scale>1 1 1</scale>
        <link name='link'>
          <pose>0 0 0 0 -0 0</pose>
          <velocity>0 0 0 0 -0 0</velocity>
          <acceleration>0 0 0 0 -0 0</acceleration>
          <wrench>0 0 0 0 -0 0</wrench>
        </link>
      </model>
      <model name='husky'>
        <pose>8.11427 0.039506 0.142754 2e-06 1e-06 -0.187497</pose>
        <scale>1 1 1</scale>
        <link name='back_left_wheel'>
          <pose>7.91597 0.367697 0.177755 3.14158 -0.200778 2.9541</pose>
          <velocity>-0.002474 9.8e-05 0.003174 -0.000777 -0.014546 0.002025</velocity>
          <acceleration>3.32887 0.042874 6.37985 1.7485 -1.48943 -0.38184</acceleration>
          <wrench>8.7739 0.113002 16.8154 0 -0 0</wrench>
        </link>
        <link name='back_right_wheel'>
          <pose>7.80954 -0.193246 0.177755 3.14158 -0.216909 2.9541</pose>
          <velocity>-0.001238 -0.000184 0.003473 0.000852 -0.007547 0.001903</velocity>
          <acceleration>3.58781 -0.110594 6.98258 2.56899 -0.676692 -0.722685</acceleration>
          <wrench>9.45639 -0.291493 18.404 0 -0 0</wrench>
        </link>
        <link name='base_link'>
          <pose>8.11427 0.039506 0.142754 2e-06 1e-06 -0.187497</pose>
          <velocity>-0.001366 0.000295 0.006355 -0.002401 -0.011611 0.002189</velocity>
          <acceleration>-1.26687 0.697299 10.6863 0.83372 1.14956 2.69683</acceleration>
          <wrench>-42.89 23.6071 361.784 0 -0 0</wrench>
        </link>
        <link name='front_left_wheel'>
          <pose>8.419 0.272259 0.177755 -6e-06 0.222843 -0.187497</pose>
          <velocity>-0.002318 0.000941 0.009442 -0.005092 -0.012293 0.002434</velocity>
          <acceleration>3.26751 -0.251534 18.8254 -0.747233 0.45128 1.26182</acceleration>
          <wrench>8.61218 -0.662968 49.618 0 -0 0</wrench>
        </link>
        <link name='front_right_wheel'>
          <pose>8.31257 -0.288684 0.177753 -6e-06 -0.943164 -0.187493</pose>
          <velocity>-0.001071 0.000626 0.009326 -0.003353 -0.005536 0.001597</velocity>
          <acceleration>3.54934 -0.417231 18.619 1.23636 0.849674 -1.25811</acceleration>
          <wrench>9.35499 -1.0997 49.0742 0 -0 0</wrench>
        </link>
      </model>
      <model name='person_standing'>
        <pose>9.45596 -3.9058 -0 1e-06 -1e-06 -0.003801</pose>
        <scale>1 1 1</scale>
        <link name='link'>
          <pose>9.45596 -3.9058 -0 1e-06 -1e-06 -0.003801</pose>
          <velocity>0 0 0 0 -0 0</velocity>
          <acceleration>-1.6185 -1.12936 -1.49079 -1.94081 -1.44604 3.09668</acceleration>
          <wrench>-129.48 -90.3486 -119.263 0 -0 0</wrench>
        </link>
      </model>
      <model name='realsense_d435'>
        <pose>7.67033 -6.01891 -1.1e-05 -1.5708 -0.00035 0.034968</pose>
        <scale>1 1 1</scale>
        <link name='link'>
          <pose>7.67033 -6.01891 -1.1e-05 -1.5708 -0.00035 0.034968</pose>
          <velocity>-1e-06 0 -0.002032 0.013828 -0.369969 -1.5e-05</velocity>
          <acceleration>-0.001294 0.000258 9.8 2.79697 0.220641 -0.881964</acceleration>
          <wrench>-8e-05 1.6e-05 0.603437 0 -0 0</wrench>
        </link>
      </model>
      <model name='suv'>
        <pose>-15.2624 -1.80078 0 0 -0 0</pose>
        <scale>1 1 1</scale>
        <link name='link'>
          <pose>-15.2624 -1.80078 0 0 -0 0</pose>
          <velocity>0 0 0 0 -0 0</velocity>
          <acceleration>0 0 0 0 -0 0</acceleration>
          <wrench>0 0 0 0 -0 0</wrench>
        </link>
      </model>
      <light name='sun'>
        <pose>0 0 10 0 -0 0</pose>
      </light>
    </state>
    <gui fullscreen='0'>
      <camera name='user_camera'>
        <pose>20.2263 26.6557 18.5859 0 0.529796 -2.49016</pose>
        <view_controller>orbit</view_controller>
        <projection_type>perspective</projection_type>
      </camera>
    </gui>
  </world>
</sdf>
